2017-03-21 14:25:53,406 orm.py[line:152] ERROR failed to update field:<built-in function id>, rows:0
2017-03-21 14:28:20,371 orm.py[line:153] ERROR failed to update field:<built-in function id>, rows:0
2017-03-21 14:35:52,317 orm.py[line:153] ERROR failed to update field:<built-in function id>, rows:0
2017-03-21 14:36:33,081 orm.py[line:153] ERROR failed to update field:<built-in function id>, rows:0
2017-03-21 14:36:38,714 orm.py[line:153] ERROR failed to update field:<built-in function id>, rows:0
2017-03-21 14:36:41,841 orm.py[line:153] ERROR failed to update field:<built-in function id>, rows:0
2017-03-21 14:36:47,489 orm.py[line:153] ERROR failed to update field:<built-in function id>, rows:0
2017-03-21 14:58:50,781 orm.py[line:152] ERROR failed to update field:<built-in function id>, rows:0
2017-03-21 17:26:03,762 web_server.py[line:88] ERROR Error handling request
Traceback (most recent call last):
  File "/home/gyz/python3.5.2/lib/python3.5/site-packages/aiohttp/web_server.py", line 62, in handle_request
    resp = yield from self._handler(request)
  File "/home/gyz/python3.5.2/lib/python3.5/site-packages/aiohttp/web.py", line 270, in _handle
    resp = yield from handler(request)
  File "app.py", line 35, in logger
    return (yield from handler(request))
  File "app.py", line 73, in response
    resp = web.Response(body=app['__templating__'].get_template(template).render(**r).encode('utf-8'))
  File "/home/gyz/python3.5.2/lib/python3.5/site-packages/jinja2/environment.py", line 830, in get_template
    return self._load_template(name, self.make_globals(globals))
  File "/home/gyz/python3.5.2/lib/python3.5/site-packages/jinja2/environment.py", line 804, in _load_template
    template = self.loader.load(self, name, globals)
  File "/home/gyz/python3.5.2/lib/python3.5/site-packages/jinja2/loaders.py", line 113, in load
    source, filename, uptodate = self.get_source(environment, name)
  File "/home/gyz/python3.5.2/lib/python3.5/site-packages/jinja2/loaders.py", line 175, in get_source
    contents = f.read().decode(self.encoding)
UnicodeDecodeError: 'utf-8' codec can't decode byte 0xea in position 64: invalid continuation byte
2017-03-21 17:26:04,069 web_server.py[line:88] ERROR Error handling request
Traceback (most recent call last):
  File "/home/gyz/python3.5.2/lib/python3.5/site-packages/aiohttp/web_server.py", line 62, in handle_request
    resp = yield from self._handler(request)
  File "/home/gyz/python3.5.2/lib/python3.5/site-packages/aiohttp/web.py", line 270, in _handle
    resp = yield from handler(request)
  File "app.py", line 35, in logger
    return (yield from handler(request))
  File "app.py", line 73, in response
    resp = web.Response(body=app['__templating__'].get_template(template).render(**r).encode('utf-8'))
  File "/home/gyz/python3.5.2/lib/python3.5/site-packages/jinja2/environment.py", line 830, in get_template
    return self._load_template(name, self.make_globals(globals))
  File "/home/gyz/python3.5.2/lib/python3.5/site-packages/jinja2/environment.py", line 804, in _load_template
    template = self.loader.load(self, name, globals)
  File "/home/gyz/python3.5.2/lib/python3.5/site-packages/jinja2/loaders.py", line 113, in load
    source, filename, uptodate = self.get_source(environment, name)
  File "/home/gyz/python3.5.2/lib/python3.5/site-packages/jinja2/loaders.py", line 175, in get_source
    contents = f.read().decode(self.encoding)
UnicodeDecodeError: 'utf-8' codec can't decode byte 0xea in position 64: invalid continuation byte
2017-03-21 17:26:07,858 web_server.py[line:88] ERROR Error handling request
Traceback (most recent call last):
  File "/home/gyz/python3.5.2/lib/python3.5/site-packages/aiohttp/web_server.py", line 62, in handle_request
    resp = yield from self._handler(request)
  File "/home/gyz/python3.5.2/lib/python3.5/site-packages/aiohttp/web.py", line 270, in _handle
    resp = yield from handler(request)
  File "app.py", line 35, in logger
    return (yield from handler(request))
  File "app.py", line 73, in response
    resp = web.Response(body=app['__templating__'].get_template(template).render(**r).encode('utf-8'))
  File "/home/gyz/python3.5.2/lib/python3.5/site-packages/jinja2/environment.py", line 830, in get_template
    return self._load_template(name, self.make_globals(globals))
  File "/home/gyz/python3.5.2/lib/python3.5/site-packages/jinja2/environment.py", line 804, in _load_template
    template = self.loader.load(self, name, globals)
  File "/home/gyz/python3.5.2/lib/python3.5/site-packages/jinja2/loaders.py", line 113, in load
    source, filename, uptodate = self.get_source(environment, name)
  File "/home/gyz/python3.5.2/lib/python3.5/site-packages/jinja2/loaders.py", line 175, in get_source
    contents = f.read().decode(self.encoding)
UnicodeDecodeError: 'utf-8' codec can't decode byte 0xea in position 64: invalid continuation byte
2017-03-21 17:26:08,366 web_server.py[line:88] ERROR Error handling request
Traceback (most recent call last):
  File "/home/gyz/python3.5.2/lib/python3.5/site-packages/aiohttp/web_server.py", line 62, in handle_request
    resp = yield from self._handler(request)
  File "/home/gyz/python3.5.2/lib/python3.5/site-packages/aiohttp/web.py", line 270, in _handle
    resp = yield from handler(request)
  File "app.py", line 35, in logger
    return (yield from handler(request))
  File "app.py", line 73, in response
    resp = web.Response(body=app['__templating__'].get_template(template).render(**r).encode('utf-8'))
  File "/home/gyz/python3.5.2/lib/python3.5/site-packages/jinja2/environment.py", line 830, in get_template
    return self._load_template(name, self.make_globals(globals))
  File "/home/gyz/python3.5.2/lib/python3.5/site-packages/jinja2/environment.py", line 804, in _load_template
    template = self.loader.load(self, name, globals)
  File "/home/gyz/python3.5.2/lib/python3.5/site-packages/jinja2/loaders.py", line 113, in load
    source, filename, uptodate = self.get_source(environment, name)
  File "/home/gyz/python3.5.2/lib/python3.5/site-packages/jinja2/loaders.py", line 175, in get_source
    contents = f.read().decode(self.encoding)
UnicodeDecodeError: 'utf-8' codec can't decode byte 0xea in position 64: invalid continuation byte
2017-03-21 17:26:08,521 web_server.py[line:88] ERROR Error handling request
Traceback (most recent call last):
  File "/home/gyz/python3.5.2/lib/python3.5/site-packages/aiohttp/web_server.py", line 62, in handle_request
    resp = yield from self._handler(request)
  File "/home/gyz/python3.5.2/lib/python3.5/site-packages/aiohttp/web.py", line 270, in _handle
    resp = yield from handler(request)
  File "app.py", line 35, in logger
    return (yield from handler(request))
  File "app.py", line 73, in response
    resp = web.Response(body=app['__templating__'].get_template(template).render(**r).encode('utf-8'))
  File "/home/gyz/python3.5.2/lib/python3.5/site-packages/jinja2/environment.py", line 830, in get_template
    return self._load_template(name, self.make_globals(globals))
  File "/home/gyz/python3.5.2/lib/python3.5/site-packages/jinja2/environment.py", line 804, in _load_template
    template = self.loader.load(self, name, globals)
  File "/home/gyz/python3.5.2/lib/python3.5/site-packages/jinja2/loaders.py", line 113, in load
    source, filename, uptodate = self.get_source(environment, name)
  File "/home/gyz/python3.5.2/lib/python3.5/site-packages/jinja2/loaders.py", line 175, in get_source
    contents = f.read().decode(self.encoding)
UnicodeDecodeError: 'utf-8' codec can't decode byte 0xea in position 64: invalid continuation byte
2017-03-21 17:26:08,930 web_server.py[line:88] ERROR Error handling request
Traceback (most recent call last):
  File "/home/gyz/python3.5.2/lib/python3.5/site-packages/aiohttp/web_server.py", line 62, in handle_request
    resp = yield from self._handler(request)
  File "/home/gyz/python3.5.2/lib/python3.5/site-packages/aiohttp/web.py", line 270, in _handle
    resp = yield from handler(request)
  File "app.py", line 35, in logger
    return (yield from handler(request))
  File "app.py", line 73, in response
    resp = web.Response(body=app['__templating__'].get_template(template).render(**r).encode('utf-8'))
  File "/home/gyz/python3.5.2/lib/python3.5/site-packages/jinja2/environment.py", line 830, in get_template
    return self._load_template(name, self.make_globals(globals))
  File "/home/gyz/python3.5.2/lib/python3.5/site-packages/jinja2/environment.py", line 804, in _load_template
    template = self.loader.load(self, name, globals)
  File "/home/gyz/python3.5.2/lib/python3.5/site-packages/jinja2/loaders.py", line 113, in load
    source, filename, uptodate = self.get_source(environment, name)
  File "/home/gyz/python3.5.2/lib/python3.5/site-packages/jinja2/loaders.py", line 175, in get_source
    contents = f.read().decode(self.encoding)
UnicodeDecodeError: 'utf-8' codec can't decode byte 0xea in position 64: invalid continuation byte
2017-03-21 17:41:16,064 web_server.py[line:88] ERROR Error handling request
Traceback (most recent call last):
  File "/home/gyz/python3.5.2/lib/python3.5/site-packages/aiohttp/web_server.py", line 62, in handle_request
    resp = yield from self._handler(request)
  File "/home/gyz/python3.5.2/lib/python3.5/site-packages/aiohttp/web.py", line 270, in _handle
    resp = yield from handler(request)
  File "app.py", line 35, in logger
    return (yield from handler(request))
  File "app.py", line 73, in response
    resp = web.Response(body=app['__templating__'].get_template(template).render(**r).encode('utf-8'))
  File "/home/gyz/python3.5.2/lib/python3.5/site-packages/jinja2/environment.py", line 830, in get_template
    return self._load_template(name, self.make_globals(globals))
  File "/home/gyz/python3.5.2/lib/python3.5/site-packages/jinja2/environment.py", line 804, in _load_template
    template = self.loader.load(self, name, globals)
  File "/home/gyz/python3.5.2/lib/python3.5/site-packages/jinja2/loaders.py", line 125, in load
    code = environment.compile(source, name, filename)
  File "/home/gyz/python3.5.2/lib/python3.5/site-packages/jinja2/environment.py", line 591, in compile
    self.handle_exception(exc_info, source_hint=source_hint)
  File "/home/gyz/python3.5.2/lib/python3.5/site-packages/jinja2/environment.py", line 780, in handle_exception
    reraise(exc_type, exc_value, tb)
  File "/home/gyz/python3.5.2/lib/python3.5/site-packages/jinja2/_compat.py", line 37, in reraise
    raise value.with_traceback(tb)
  File "/home/pycode/python3-summer-blog/www/templates/test.html", line 10, in template
    {% endfor %}
  File "/home/gyz/python3.5.2/lib/python3.5/site-packages/jinja2/environment.py", line 497, in _parse
    return Parser(self, source, name, encode_filename(filename)).parse()
  File "/home/gyz/python3.5.2/lib/python3.5/site-packages/jinja2/parser.py", line 896, in parse
    result = nodes.Template(self.subparse(), lineno=1)
  File "/home/gyz/python3.5.2/lib/python3.5/site-packages/jinja2/parser.py", line 878, in subparse
    rv = self.parse_statement()
  File "/home/gyz/python3.5.2/lib/python3.5/site-packages/jinja2/parser.py", line 144, in parse_statement
    self.fail_unknown_tag(token.value, token.lineno)
  File "/home/gyz/python3.5.2/lib/python3.5/site-packages/jinja2/parser.py", line 97, in fail_unknown_tag
    return self._fail_ut_eof(name, self._end_token_stack, lineno)
  File "/home/gyz/python3.5.2/lib/python3.5/site-packages/jinja2/parser.py", line 90, in _fail_ut_eof
    self.fail(' '.join(message), lineno)
  File "/home/gyz/python3.5.2/lib/python3.5/site-packages/jinja2/parser.py", line 59, in fail
    raise exc(msg, lineno, self.name, self.filename)
jinja2.exceptions.TemplateSyntaxError: Encountered unknown tag 'endfor'.
2017-03-21 17:41:16,256 web_server.py[line:88] ERROR Error handling request
Traceback (most recent call last):
  File "/home/gyz/python3.5.2/lib/python3.5/site-packages/aiohttp/web_server.py", line 62, in handle_request
    resp = yield from self._handler(request)
  File "/home/gyz/python3.5.2/lib/python3.5/site-packages/aiohttp/web.py", line 270, in _handle
    resp = yield from handler(request)
  File "app.py", line 35, in logger
    return (yield from handler(request))
  File "app.py", line 73, in response
    resp = web.Response(body=app['__templating__'].get_template(template).render(**r).encode('utf-8'))
  File "/home/gyz/python3.5.2/lib/python3.5/site-packages/jinja2/environment.py", line 830, in get_template
    return self._load_template(name, self.make_globals(globals))
  File "/home/gyz/python3.5.2/lib/python3.5/site-packages/jinja2/environment.py", line 804, in _load_template
    template = self.loader.load(self, name, globals)
  File "/home/gyz/python3.5.2/lib/python3.5/site-packages/jinja2/loaders.py", line 125, in load
    code = environment.compile(source, name, filename)
  File "/home/gyz/python3.5.2/lib/python3.5/site-packages/jinja2/environment.py", line 591, in compile
    self.handle_exception(exc_info, source_hint=source_hint)
  File "/home/gyz/python3.5.2/lib/python3.5/site-packages/jinja2/environment.py", line 780, in handle_exception
    reraise(exc_type, exc_value, tb)
  File "/home/gyz/python3.5.2/lib/python3.5/site-packages/jinja2/_compat.py", line 37, in reraise
    raise value.with_traceback(tb)
  File "/home/pycode/python3-summer-blog/www/templates/test.html", line 10, in template
    {% endfor %}
  File "/home/gyz/python3.5.2/lib/python3.5/site-packages/jinja2/environment.py", line 497, in _parse
    return Parser(self, source, name, encode_filename(filename)).parse()
  File "/home/gyz/python3.5.2/lib/python3.5/site-packages/jinja2/parser.py", line 896, in parse
    result = nodes.Template(self.subparse(), lineno=1)
  File "/home/gyz/python3.5.2/lib/python3.5/site-packages/jinja2/parser.py", line 878, in subparse
    rv = self.parse_statement()
  File "/home/gyz/python3.5.2/lib/python3.5/site-packages/jinja2/parser.py", line 144, in parse_statement
    self.fail_unknown_tag(token.value, token.lineno)
  File "/home/gyz/python3.5.2/lib/python3.5/site-packages/jinja2/parser.py", line 97, in fail_unknown_tag
    return self._fail_ut_eof(name, self._end_token_stack, lineno)
  File "/home/gyz/python3.5.2/lib/python3.5/site-packages/jinja2/parser.py", line 90, in _fail_ut_eof
    self.fail(' '.join(message), lineno)
  File "/home/gyz/python3.5.2/lib/python3.5/site-packages/jinja2/parser.py", line 59, in fail
    raise exc(msg, lineno, self.name, self.filename)
jinja2.exceptions.TemplateSyntaxError: Encountered unknown tag 'endfor'.
2017-03-21 17:41:16,694 web_server.py[line:88] ERROR Error handling request
Traceback (most recent call last):
  File "/home/gyz/python3.5.2/lib/python3.5/site-packages/aiohttp/web_server.py", line 62, in handle_request
    resp = yield from self._handler(request)
  File "/home/gyz/python3.5.2/lib/python3.5/site-packages/aiohttp/web.py", line 270, in _handle
    resp = yield from handler(request)
  File "app.py", line 35, in logger
    return (yield from handler(request))
  File "app.py", line 73, in response
    resp = web.Response(body=app['__templating__'].get_template(template).render(**r).encode('utf-8'))
  File "/home/gyz/python3.5.2/lib/python3.5/site-packages/jinja2/environment.py", line 830, in get_template
    return self._load_template(name, self.make_globals(globals))
  File "/home/gyz/python3.5.2/lib/python3.5/site-packages/jinja2/environment.py", line 804, in _load_template
    template = self.loader.load(self, name, globals)
  File "/home/gyz/python3.5.2/lib/python3.5/site-packages/jinja2/loaders.py", line 125, in load
    code = environment.compile(source, name, filename)
  File "/home/gyz/python3.5.2/lib/python3.5/site-packages/jinja2/environment.py", line 591, in compile
    self.handle_exception(exc_info, source_hint=source_hint)
  File "/home/gyz/python3.5.2/lib/python3.5/site-packages/jinja2/environment.py", line 780, in handle_exception
    reraise(exc_type, exc_value, tb)
  File "/home/gyz/python3.5.2/lib/python3.5/site-packages/jinja2/_compat.py", line 37, in reraise
    raise value.with_traceback(tb)
  File "/home/pycode/python3-summer-blog/www/templates/test.html", line 10, in template
    {% endfor %}
  File "/home/gyz/python3.5.2/lib/python3.5/site-packages/jinja2/environment.py", line 497, in _parse
    return Parser(self, source, name, encode_filename(filename)).parse()
  File "/home/gyz/python3.5.2/lib/python3.5/site-packages/jinja2/parser.py", line 896, in parse
    result = nodes.Template(self.subparse(), lineno=1)
  File "/home/gyz/python3.5.2/lib/python3.5/site-packages/jinja2/parser.py", line 878, in subparse
    rv = self.parse_statement()
  File "/home/gyz/python3.5.2/lib/python3.5/site-packages/jinja2/parser.py", line 144, in parse_statement
    self.fail_unknown_tag(token.value, token.lineno)
  File "/home/gyz/python3.5.2/lib/python3.5/site-packages/jinja2/parser.py", line 97, in fail_unknown_tag
    return self._fail_ut_eof(name, self._end_token_stack, lineno)
  File "/home/gyz/python3.5.2/lib/python3.5/site-packages/jinja2/parser.py", line 90, in _fail_ut_eof
    self.fail(' '.join(message), lineno)
  File "/home/gyz/python3.5.2/lib/python3.5/site-packages/jinja2/parser.py", line 59, in fail
    raise exc(msg, lineno, self.name, self.filename)
jinja2.exceptions.TemplateSyntaxError: Encountered unknown tag 'endfor'.
2017-03-21 17:41:18,649 web_server.py[line:88] ERROR Error handling request
Traceback (most recent call last):
  File "/home/gyz/python3.5.2/lib/python3.5/site-packages/aiohttp/web_server.py", line 62, in handle_request
    resp = yield from self._handler(request)
  File "/home/gyz/python3.5.2/lib/python3.5/site-packages/aiohttp/web.py", line 270, in _handle
    resp = yield from handler(request)
  File "app.py", line 35, in logger
    return (yield from handler(request))
  File "app.py", line 73, in response
    resp = web.Response(body=app['__templating__'].get_template(template).render(**r).encode('utf-8'))
  File "/home/gyz/python3.5.2/lib/python3.5/site-packages/jinja2/environment.py", line 830, in get_template
    return self._load_template(name, self.make_globals(globals))
  File "/home/gyz/python3.5.2/lib/python3.5/site-packages/jinja2/environment.py", line 804, in _load_template
    template = self.loader.load(self, name, globals)
  File "/home/gyz/python3.5.2/lib/python3.5/site-packages/jinja2/loaders.py", line 125, in load
    code = environment.compile(source, name, filename)
  File "/home/gyz/python3.5.2/lib/python3.5/site-packages/jinja2/environment.py", line 591, in compile
    self.handle_exception(exc_info, source_hint=source_hint)
  File "/home/gyz/python3.5.2/lib/python3.5/site-packages/jinja2/environment.py", line 780, in handle_exception
    reraise(exc_type, exc_value, tb)
  File "/home/gyz/python3.5.2/lib/python3.5/site-packages/jinja2/_compat.py", line 37, in reraise
    raise value.with_traceback(tb)
  File "/home/pycode/python3-summer-blog/www/templates/test.html", line 10, in template
    {% endfor %}
  File "/home/gyz/python3.5.2/lib/python3.5/site-packages/jinja2/environment.py", line 497, in _parse
    return Parser(self, source, name, encode_filename(filename)).parse()
  File "/home/gyz/python3.5.2/lib/python3.5/site-packages/jinja2/parser.py", line 896, in parse
    result = nodes.Template(self.subparse(), lineno=1)
  File "/home/gyz/python3.5.2/lib/python3.5/site-packages/jinja2/parser.py", line 878, in subparse
    rv = self.parse_statement()
  File "/home/gyz/python3.5.2/lib/python3.5/site-packages/jinja2/parser.py", line 144, in parse_statement
    self.fail_unknown_tag(token.value, token.lineno)
  File "/home/gyz/python3.5.2/lib/python3.5/site-packages/jinja2/parser.py", line 97, in fail_unknown_tag
    return self._fail_ut_eof(name, self._end_token_stack, lineno)
  File "/home/gyz/python3.5.2/lib/python3.5/site-packages/jinja2/parser.py", line 90, in _fail_ut_eof
    self.fail(' '.join(message), lineno)
  File "/home/gyz/python3.5.2/lib/python3.5/site-packages/jinja2/parser.py", line 59, in fail
    raise exc(msg, lineno, self.name, self.filename)
jinja2.exceptions.TemplateSyntaxError: Encountered unknown tag 'endfor'.
2017-03-21 17:41:18,833 web_server.py[line:88] ERROR Error handling request
Traceback (most recent call last):
  File "/home/gyz/python3.5.2/lib/python3.5/site-packages/aiohttp/web_server.py", line 62, in handle_request
    resp = yield from self._handler(request)
  File "/home/gyz/python3.5.2/lib/python3.5/site-packages/aiohttp/web.py", line 270, in _handle
    resp = yield from handler(request)
  File "app.py", line 35, in logger
    return (yield from handler(request))
  File "app.py", line 73, in response
    resp = web.Response(body=app['__templating__'].get_template(template).render(**r).encode('utf-8'))
  File "/home/gyz/python3.5.2/lib/python3.5/site-packages/jinja2/environment.py", line 830, in get_template
    return self._load_template(name, self.make_globals(globals))
  File "/home/gyz/python3.5.2/lib/python3.5/site-packages/jinja2/environment.py", line 804, in _load_template
    template = self.loader.load(self, name, globals)
  File "/home/gyz/python3.5.2/lib/python3.5/site-packages/jinja2/loaders.py", line 125, in load
    code = environment.compile(source, name, filename)
  File "/home/gyz/python3.5.2/lib/python3.5/site-packages/jinja2/environment.py", line 591, in compile
    self.handle_exception(exc_info, source_hint=source_hint)
  File "/home/gyz/python3.5.2/lib/python3.5/site-packages/jinja2/environment.py", line 780, in handle_exception
    reraise(exc_type, exc_value, tb)
  File "/home/gyz/python3.5.2/lib/python3.5/site-packages/jinja2/_compat.py", line 37, in reraise
    raise value.with_traceback(tb)
  File "/home/pycode/python3-summer-blog/www/templates/test.html", line 10, in template
    {% endfor %}
  File "/home/gyz/python3.5.2/lib/python3.5/site-packages/jinja2/environment.py", line 497, in _parse
    return Parser(self, source, name, encode_filename(filename)).parse()
  File "/home/gyz/python3.5.2/lib/python3.5/site-packages/jinja2/parser.py", line 896, in parse
    result = nodes.Template(self.subparse(), lineno=1)
  File "/home/gyz/python3.5.2/lib/python3.5/site-packages/jinja2/parser.py", line 878, in subparse
    rv = self.parse_statement()
  File "/home/gyz/python3.5.2/lib/python3.5/site-packages/jinja2/parser.py", line 144, in parse_statement
    self.fail_unknown_tag(token.value, token.lineno)
  File "/home/gyz/python3.5.2/lib/python3.5/site-packages/jinja2/parser.py", line 97, in fail_unknown_tag
    return self._fail_ut_eof(name, self._end_token_stack, lineno)
  File "/home/gyz/python3.5.2/lib/python3.5/site-packages/jinja2/parser.py", line 90, in _fail_ut_eof
    self.fail(' '.join(message), lineno)
  File "/home/gyz/python3.5.2/lib/python3.5/site-packages/jinja2/parser.py", line 59, in fail
    raise exc(msg, lineno, self.name, self.filename)
jinja2.exceptions.TemplateSyntaxError: Encountered unknown tag 'endfor'.
2017-03-21 17:41:19,011 web_server.py[line:88] ERROR Error handling request
Traceback (most recent call last):
  File "/home/gyz/python3.5.2/lib/python3.5/site-packages/aiohttp/web_server.py", line 62, in handle_request
    resp = yield from self._handler(request)
  File "/home/gyz/python3.5.2/lib/python3.5/site-packages/aiohttp/web.py", line 270, in _handle
    resp = yield from handler(request)
  File "app.py", line 35, in logger
    return (yield from handler(request))
  File "app.py", line 73, in response
    resp = web.Response(body=app['__templating__'].get_template(template).render(**r).encode('utf-8'))
  File "/home/gyz/python3.5.2/lib/python3.5/site-packages/jinja2/environment.py", line 830, in get_template
    return self._load_template(name, self.make_globals(globals))
  File "/home/gyz/python3.5.2/lib/python3.5/site-packages/jinja2/environment.py", line 804, in _load_template
    template = self.loader.load(self, name, globals)
  File "/home/gyz/python3.5.2/lib/python3.5/site-packages/jinja2/loaders.py", line 125, in load
    code = environment.compile(source, name, filename)
  File "/home/gyz/python3.5.2/lib/python3.5/site-packages/jinja2/environment.py", line 591, in compile
    self.handle_exception(exc_info, source_hint=source_hint)
  File "/home/gyz/python3.5.2/lib/python3.5/site-packages/jinja2/environment.py", line 780, in handle_exception
    reraise(exc_type, exc_value, tb)
  File "/home/gyz/python3.5.2/lib/python3.5/site-packages/jinja2/_compat.py", line 37, in reraise
    raise value.with_traceback(tb)
  File "/home/pycode/python3-summer-blog/www/templates/test.html", line 10, in template
    {% endfor %}
  File "/home/gyz/python3.5.2/lib/python3.5/site-packages/jinja2/environment.py", line 497, in _parse
    return Parser(self, source, name, encode_filename(filename)).parse()
  File "/home/gyz/python3.5.2/lib/python3.5/site-packages/jinja2/parser.py", line 896, in parse
    result = nodes.Template(self.subparse(), lineno=1)
  File "/home/gyz/python3.5.2/lib/python3.5/site-packages/jinja2/parser.py", line 878, in subparse
    rv = self.parse_statement()
  File "/home/gyz/python3.5.2/lib/python3.5/site-packages/jinja2/parser.py", line 144, in parse_statement
    self.fail_unknown_tag(token.value, token.lineno)
  File "/home/gyz/python3.5.2/lib/python3.5/site-packages/jinja2/parser.py", line 97, in fail_unknown_tag
    return self._fail_ut_eof(name, self._end_token_stack, lineno)
  File "/home/gyz/python3.5.2/lib/python3.5/site-packages/jinja2/parser.py", line 90, in _fail_ut_eof
    self.fail(' '.join(message), lineno)
  File "/home/gyz/python3.5.2/lib/python3.5/site-packages/jinja2/parser.py", line 59, in fail
    raise exc(msg, lineno, self.name, self.filename)
jinja2.exceptions.TemplateSyntaxError: Encountered unknown tag 'endfor'.
2017-03-21 17:55:43,593 web_server.py[line:88] ERROR Error handling request
Traceback (most recent call last):
  File "/home/gyz/python3.5.2/lib/python3.5/site-packages/aiohttp/web_server.py", line 62, in handle_request
    resp = yield from self._handler(request)
  File "/home/gyz/python3.5.2/lib/python3.5/site-packages/aiohttp/web.py", line 270, in _handle
    resp = yield from handler(request)
  File "app.py", line 35, in logger
    return (yield from handler(request))
  File "app.py", line 53, in response
    r = await handler(request)
  File "/home/gyz/python3.5.2/lib/python3.5/site-packages/aiohttp/web_urldispatcher.py", line 116, in handler_wrapper
    result = yield from result
  File "/home/pycode/python3-summer-blog/www/coroweb.py", line 126, in __call__
    r = await self._func(**kw)
  File "/home/gyz/python3.5.2/lib/python3.5/asyncio/coroutines.py", line 219, in coro
    res = yield from await_meth()
  File "/home/pycode/python3-summer-blog/www/handlers.py", line 14, in index
    users = await User.findAll()
TypeError: findAll() missing 1 required positional argument: 'cls'
2017-03-21 17:55:43,797 web_server.py[line:88] ERROR Error handling request
Traceback (most recent call last):
  File "/home/gyz/python3.5.2/lib/python3.5/site-packages/aiohttp/web_server.py", line 62, in handle_request
    resp = yield from self._handler(request)
  File "/home/gyz/python3.5.2/lib/python3.5/site-packages/aiohttp/web.py", line 270, in _handle
    resp = yield from handler(request)
  File "app.py", line 35, in logger
    return (yield from handler(request))
  File "app.py", line 53, in response
    r = await handler(request)
  File "/home/gyz/python3.5.2/lib/python3.5/site-packages/aiohttp/web_urldispatcher.py", line 116, in handler_wrapper
    result = yield from result
  File "/home/pycode/python3-summer-blog/www/coroweb.py", line 126, in __call__
    r = await self._func(**kw)
  File "/home/gyz/python3.5.2/lib/python3.5/asyncio/coroutines.py", line 219, in coro
    res = yield from await_meth()
  File "/home/pycode/python3-summer-blog/www/handlers.py", line 14, in index
    users = await User.findAll()
TypeError: findAll() missing 1 required positional argument: 'cls'
2017-03-21 17:55:45,535 web_server.py[line:88] ERROR Error handling request
Traceback (most recent call last):
  File "/home/gyz/python3.5.2/lib/python3.5/site-packages/aiohttp/web_server.py", line 62, in handle_request
    resp = yield from self._handler(request)
  File "/home/gyz/python3.5.2/lib/python3.5/site-packages/aiohttp/web.py", line 270, in _handle
    resp = yield from handler(request)
  File "app.py", line 35, in logger
    return (yield from handler(request))
  File "app.py", line 53, in response
    r = await handler(request)
  File "/home/gyz/python3.5.2/lib/python3.5/site-packages/aiohttp/web_urldispatcher.py", line 116, in handler_wrapper
    result = yield from result
  File "/home/pycode/python3-summer-blog/www/coroweb.py", line 126, in __call__
    r = await self._func(**kw)
  File "/home/gyz/python3.5.2/lib/python3.5/asyncio/coroutines.py", line 219, in coro
    res = yield from await_meth()
  File "/home/pycode/python3-summer-blog/www/handlers.py", line 14, in index
    users = await User.findAll()
TypeError: findAll() missing 1 required positional argument: 'cls'
2017-03-21 18:00:29,562 web_server.py[line:88] ERROR Error handling request
Traceback (most recent call last):
  File "/home/gyz/python3.5.2/lib/python3.5/site-packages/aiohttp/web_server.py", line 62, in handle_request
    resp = yield from self._handler(request)
  File "/home/gyz/python3.5.2/lib/python3.5/site-packages/aiohttp/web.py", line 270, in _handle
    resp = yield from handler(request)
  File "app.py", line 35, in logger
    return (yield from handler(request))
  File "app.py", line 53, in response
    r = await handler(request)
  File "/home/gyz/python3.5.2/lib/python3.5/site-packages/aiohttp/web_urldispatcher.py", line 116, in handler_wrapper
    result = yield from result
  File "/home/pycode/python3-summer-blog/www/coroweb.py", line 126, in __call__
    r = await self._func(**kw)
  File "/home/gyz/python3.5.2/lib/python3.5/asyncio/coroutines.py", line 219, in coro
    res = yield from await_meth()
  File "/home/pycode/python3-summer-blog/www/handlers.py", line 15, in index
    logging.debug(users.name)
AttributeError: 'list' object has no attribute 'name'
2017-03-21 18:00:29,724 web_server.py[line:88] ERROR Error handling request
Traceback (most recent call last):
  File "/home/gyz/python3.5.2/lib/python3.5/site-packages/aiohttp/web_server.py", line 62, in handle_request
    resp = yield from self._handler(request)
  File "/home/gyz/python3.5.2/lib/python3.5/site-packages/aiohttp/web.py", line 270, in _handle
    resp = yield from handler(request)
  File "app.py", line 35, in logger
    return (yield from handler(request))
  File "app.py", line 53, in response
    r = await handler(request)
  File "/home/gyz/python3.5.2/lib/python3.5/site-packages/aiohttp/web_urldispatcher.py", line 116, in handler_wrapper
    result = yield from result
  File "/home/pycode/python3-summer-blog/www/coroweb.py", line 126, in __call__
    r = await self._func(**kw)
  File "/home/gyz/python3.5.2/lib/python3.5/asyncio/coroutines.py", line 219, in coro
    res = yield from await_meth()
  File "/home/pycode/python3-summer-blog/www/handlers.py", line 15, in index
    logging.debug(users.name)
AttributeError: 'list' object has no attribute 'name'
2017-03-21 18:00:30,195 web_server.py[line:88] ERROR Error handling request
Traceback (most recent call last):
  File "/home/gyz/python3.5.2/lib/python3.5/site-packages/aiohttp/web_server.py", line 62, in handle_request
    resp = yield from self._handler(request)
  File "/home/gyz/python3.5.2/lib/python3.5/site-packages/aiohttp/web.py", line 270, in _handle
    resp = yield from handler(request)
  File "app.py", line 35, in logger
    return (yield from handler(request))
  File "app.py", line 53, in response
    r = await handler(request)
  File "/home/gyz/python3.5.2/lib/python3.5/site-packages/aiohttp/web_urldispatcher.py", line 116, in handler_wrapper
    result = yield from result
  File "/home/pycode/python3-summer-blog/www/coroweb.py", line 126, in __call__
    r = await self._func(**kw)
  File "/home/gyz/python3.5.2/lib/python3.5/asyncio/coroutines.py", line 219, in coro
    res = yield from await_meth()
  File "/home/pycode/python3-summer-blog/www/handlers.py", line 15, in index
    logging.debug(users.name)
AttributeError: 'list' object has no attribute 'name'
2017-03-21 18:00:31,335 web_server.py[line:88] ERROR Error handling request
Traceback (most recent call last):
  File "/home/gyz/python3.5.2/lib/python3.5/site-packages/aiohttp/web_server.py", line 62, in handle_request
    resp = yield from self._handler(request)
  File "/home/gyz/python3.5.2/lib/python3.5/site-packages/aiohttp/web.py", line 270, in _handle
    resp = yield from handler(request)
  File "app.py", line 35, in logger
    return (yield from handler(request))
  File "app.py", line 53, in response
    r = await handler(request)
  File "/home/gyz/python3.5.2/lib/python3.5/site-packages/aiohttp/web_urldispatcher.py", line 116, in handler_wrapper
    result = yield from result
  File "/home/pycode/python3-summer-blog/www/coroweb.py", line 126, in __call__
    r = await self._func(**kw)
  File "/home/gyz/python3.5.2/lib/python3.5/asyncio/coroutines.py", line 219, in coro
    res = yield from await_meth()
  File "/home/pycode/python3-summer-blog/www/handlers.py", line 15, in index
    logging.debug(users.name)
AttributeError: 'list' object has no attribute 'name'
2017-03-21 18:00:31,488 web_server.py[line:88] ERROR Error handling request
Traceback (most recent call last):
  File "/home/gyz/python3.5.2/lib/python3.5/site-packages/aiohttp/web_server.py", line 62, in handle_request
    resp = yield from self._handler(request)
  File "/home/gyz/python3.5.2/lib/python3.5/site-packages/aiohttp/web.py", line 270, in _handle
    resp = yield from handler(request)
  File "app.py", line 35, in logger
    return (yield from handler(request))
  File "app.py", line 53, in response
    r = await handler(request)
  File "/home/gyz/python3.5.2/lib/python3.5/site-packages/aiohttp/web_urldispatcher.py", line 116, in handler_wrapper
    result = yield from result
  File "/home/pycode/python3-summer-blog/www/coroweb.py", line 126, in __call__
    r = await self._func(**kw)
  File "/home/gyz/python3.5.2/lib/python3.5/asyncio/coroutines.py", line 219, in coro
    res = yield from await_meth()
  File "/home/pycode/python3-summer-blog/www/handlers.py", line 15, in index
    logging.debug(users.name)
AttributeError: 'list' object has no attribute 'name'
2017-03-21 18:00:31,692 web_server.py[line:88] ERROR Error handling request
Traceback (most recent call last):
  File "/home/gyz/python3.5.2/lib/python3.5/site-packages/aiohttp/web_server.py", line 62, in handle_request
    resp = yield from self._handler(request)
  File "/home/gyz/python3.5.2/lib/python3.5/site-packages/aiohttp/web.py", line 270, in _handle
    resp = yield from handler(request)
  File "app.py", line 35, in logger
    return (yield from handler(request))
  File "app.py", line 53, in response
    r = await handler(request)
  File "/home/gyz/python3.5.2/lib/python3.5/site-packages/aiohttp/web_urldispatcher.py", line 116, in handler_wrapper
    result = yield from result
  File "/home/pycode/python3-summer-blog/www/coroweb.py", line 126, in __call__
    r = await self._func(**kw)
  File "/home/gyz/python3.5.2/lib/python3.5/asyncio/coroutines.py", line 219, in coro
    res = yield from await_meth()
  File "/home/pycode/python3-summer-blog/www/handlers.py", line 15, in index
    logging.debug(users.name)
AttributeError: 'list' object has no attribute 'name'
2017-03-22 11:25:21,938 web_server.py[line:88] ERROR Error handling request
Traceback (most recent call last):
  File "/home/gyz/python3.5.2/lib/python3.5/site-packages/aiohttp/web_server.py", line 62, in handle_request
    resp = yield from self._handler(request)
  File "/home/gyz/python3.5.2/lib/python3.5/site-packages/aiohttp/web.py", line 270, in _handle
    resp = yield from handler(request)
  File "app.py", line 35, in logger
    return (yield from handler(request))
  File "app.py", line 73, in response
    resp = web.Response(body=app['__templating__'].get_template(template).render(**r).encode('utf-8'))
  File "/home/gyz/python3.5.2/lib/python3.5/site-packages/jinja2/environment.py", line 830, in get_template
    return self._load_template(name, self.make_globals(globals))
  File "/home/gyz/python3.5.2/lib/python3.5/site-packages/jinja2/environment.py", line 804, in _load_template
    template = self.loader.load(self, name, globals)
  File "/home/gyz/python3.5.2/lib/python3.5/site-packages/jinja2/loaders.py", line 113, in load
    source, filename, uptodate = self.get_source(environment, name)
  File "/home/gyz/python3.5.2/lib/python3.5/site-packages/jinja2/loaders.py", line 175, in get_source
    contents = f.read().decode(self.encoding)
UnicodeDecodeError: 'utf-8' codec can't decode byte 0xc8 in position 50: invalid continuation byte
2017-03-22 11:25:22,107 web_server.py[line:88] ERROR Error handling request
Traceback (most recent call last):
  File "/home/gyz/python3.5.2/lib/python3.5/site-packages/aiohttp/web_server.py", line 62, in handle_request
    resp = yield from self._handler(request)
  File "/home/gyz/python3.5.2/lib/python3.5/site-packages/aiohttp/web.py", line 270, in _handle
    resp = yield from handler(request)
  File "app.py", line 35, in logger
    return (yield from handler(request))
  File "app.py", line 73, in response
    resp = web.Response(body=app['__templating__'].get_template(template).render(**r).encode('utf-8'))
  File "/home/gyz/python3.5.2/lib/python3.5/site-packages/jinja2/environment.py", line 830, in get_template
    return self._load_template(name, self.make_globals(globals))
  File "/home/gyz/python3.5.2/lib/python3.5/site-packages/jinja2/environment.py", line 804, in _load_template
    template = self.loader.load(self, name, globals)
  File "/home/gyz/python3.5.2/lib/python3.5/site-packages/jinja2/loaders.py", line 113, in load
    source, filename, uptodate = self.get_source(environment, name)
  File "/home/gyz/python3.5.2/lib/python3.5/site-packages/jinja2/loaders.py", line 175, in get_source
    contents = f.read().decode(self.encoding)
UnicodeDecodeError: 'utf-8' codec can't decode byte 0xc8 in position 50: invalid continuation byte
2017-03-22 11:25:22,536 web_server.py[line:88] ERROR Error handling request
Traceback (most recent call last):
  File "/home/gyz/python3.5.2/lib/python3.5/site-packages/aiohttp/web_server.py", line 62, in handle_request
    resp = yield from self._handler(request)
  File "/home/gyz/python3.5.2/lib/python3.5/site-packages/aiohttp/web.py", line 270, in _handle
    resp = yield from handler(request)
  File "app.py", line 35, in logger
    return (yield from handler(request))
  File "app.py", line 73, in response
    resp = web.Response(body=app['__templating__'].get_template(template).render(**r).encode('utf-8'))
  File "/home/gyz/python3.5.2/lib/python3.5/site-packages/jinja2/environment.py", line 830, in get_template
    return self._load_template(name, self.make_globals(globals))
  File "/home/gyz/python3.5.2/lib/python3.5/site-packages/jinja2/environment.py", line 804, in _load_template
    template = self.loader.load(self, name, globals)
  File "/home/gyz/python3.5.2/lib/python3.5/site-packages/jinja2/loaders.py", line 113, in load
    source, filename, uptodate = self.get_source(environment, name)
  File "/home/gyz/python3.5.2/lib/python3.5/site-packages/jinja2/loaders.py", line 175, in get_source
    contents = f.read().decode(self.encoding)
UnicodeDecodeError: 'utf-8' codec can't decode byte 0xc8 in position 50: invalid continuation byte
2017-03-22 11:42:01,731 web_server.py[line:88] ERROR Error handling request
Traceback (most recent call last):
  File "/home/gyz/python3.5.2/lib/python3.5/site-packages/aiohttp/web_server.py", line 62, in handle_request
    resp = yield from self._handler(request)
  File "/home/gyz/python3.5.2/lib/python3.5/site-packages/aiohttp/web.py", line 270, in _handle
    resp = yield from handler(request)
  File "app.py", line 35, in logger
    return (yield from handler(request))
  File "app.py", line 73, in response
    resp = web.Response(body=app['__templating__'].get_template(template).render(**r).encode('utf-8'))
  File "/home/gyz/python3.5.2/lib/python3.5/site-packages/jinja2/environment.py", line 830, in get_template
    return self._load_template(name, self.make_globals(globals))
  File "/home/gyz/python3.5.2/lib/python3.5/site-packages/jinja2/environment.py", line 804, in _load_template
    template = self.loader.load(self, name, globals)
  File "/home/gyz/python3.5.2/lib/python3.5/site-packages/jinja2/loaders.py", line 125, in load
    code = environment.compile(source, name, filename)
  File "/home/gyz/python3.5.2/lib/python3.5/site-packages/jinja2/environment.py", line 591, in compile
    self.handle_exception(exc_info, source_hint=source_hint)
  File "/home/gyz/python3.5.2/lib/python3.5/site-packages/jinja2/environment.py", line 780, in handle_exception
    reraise(exc_type, exc_value, tb)
  File "/home/gyz/python3.5.2/lib/python3.5/site-packages/jinja2/_compat.py", line 37, in reraise
    raise value.with_traceback(tb)
  File "/home/pycode/python3-summer-blog/www/templates/blogs.html", line 18, in template
    <p class="uk-article-meta">发表于{{ blog.created_at|datetime }}</p>
  File "/home/gyz/python3.5.2/lib/python3.5/site-packages/jinja2/environment.py", line 543, in _generate
    optimized=self.optimized)
  File "/home/gyz/python3.5.2/lib/python3.5/site-packages/jinja2/compiler.py", line 82, in generate
    generator.visit(node)
  File "/home/gyz/python3.5.2/lib/python3.5/site-packages/jinja2/visitor.py", line 38, in visit
    return f(node, *args, **kwargs)
  File "/home/gyz/python3.5.2/lib/python3.5/site-packages/jinja2/compiler.py", line 772, in visit_Template
    self.blockvisit(block.body, block_frame)
  File "/home/gyz/python3.5.2/lib/python3.5/site-packages/jinja2/compiler.py", line 372, in blockvisit
    self.visit(node, frame)
  File "/home/gyz/python3.5.2/lib/python3.5/site-packages/jinja2/visitor.py", line 38, in visit
    return f(node, *args, **kwargs)
  File "/home/gyz/python3.5.2/lib/python3.5/site-packages/jinja2/compiler.py", line 1092, in visit_For
    self.blockvisit(node.body, loop_frame)
  File "/home/gyz/python3.5.2/lib/python3.5/site-packages/jinja2/compiler.py", line 372, in blockvisit
    self.visit(node, frame)
  File "/home/gyz/python3.5.2/lib/python3.5/site-packages/jinja2/visitor.py", line 38, in visit
    return f(node, *args, **kwargs)
  File "/home/gyz/python3.5.2/lib/python3.5/site-packages/jinja2/compiler.py", line 1321, in visit_Output
    self.visit(argument, frame)
  File "/home/gyz/python3.5.2/lib/python3.5/site-packages/jinja2/visitor.py", line 38, in visit
    return f(node, *args, **kwargs)
  File "/home/gyz/python3.5.2/lib/python3.5/site-packages/jinja2/compiler.py", line 70, in new_func
    return f(self, node, frame, **kwargs)
  File "/home/gyz/python3.5.2/lib/python3.5/site-packages/jinja2/compiler.py", line 1524, in visit_Filter
    self.fail('no filter named %r' % node.name, node.lineno)
  File "/home/gyz/python3.5.2/lib/python3.5/site-packages/jinja2/compiler.py", line 309, in fail
    raise TemplateAssertionError(msg, lineno, self.name, self.filename)
jinja2.exceptions.TemplateAssertionError: no filter named 'datetime'
2017-03-22 11:42:01,940 web_server.py[line:88] ERROR Error handling request
Traceback (most recent call last):
  File "/home/gyz/python3.5.2/lib/python3.5/site-packages/aiohttp/web_server.py", line 62, in handle_request
    resp = yield from self._handler(request)
  File "/home/gyz/python3.5.2/lib/python3.5/site-packages/aiohttp/web.py", line 270, in _handle
    resp = yield from handler(request)
  File "app.py", line 35, in logger
    return (yield from handler(request))
  File "app.py", line 73, in response
    resp = web.Response(body=app['__templating__'].get_template(template).render(**r).encode('utf-8'))
  File "/home/gyz/python3.5.2/lib/python3.5/site-packages/jinja2/environment.py", line 830, in get_template
    return self._load_template(name, self.make_globals(globals))
  File "/home/gyz/python3.5.2/lib/python3.5/site-packages/jinja2/environment.py", line 804, in _load_template
    template = self.loader.load(self, name, globals)
  File "/home/gyz/python3.5.2/lib/python3.5/site-packages/jinja2/loaders.py", line 125, in load
    code = environment.compile(source, name, filename)
  File "/home/gyz/python3.5.2/lib/python3.5/site-packages/jinja2/environment.py", line 591, in compile
    self.handle_exception(exc_info, source_hint=source_hint)
  File "/home/gyz/python3.5.2/lib/python3.5/site-packages/jinja2/environment.py", line 780, in handle_exception
    reraise(exc_type, exc_value, tb)
  File "/home/gyz/python3.5.2/lib/python3.5/site-packages/jinja2/_compat.py", line 37, in reraise
    raise value.with_traceback(tb)
  File "/home/pycode/python3-summer-blog/www/templates/blogs.html", line 18, in template
    <p class="uk-article-meta">发表于{{ blog.created_at|datetime }}</p>
  File "/home/gyz/python3.5.2/lib/python3.5/site-packages/jinja2/environment.py", line 543, in _generate
    optimized=self.optimized)
  File "/home/gyz/python3.5.2/lib/python3.5/site-packages/jinja2/compiler.py", line 82, in generate
    generator.visit(node)
  File "/home/gyz/python3.5.2/lib/python3.5/site-packages/jinja2/visitor.py", line 38, in visit
    return f(node, *args, **kwargs)
  File "/home/gyz/python3.5.2/lib/python3.5/site-packages/jinja2/compiler.py", line 772, in visit_Template
    self.blockvisit(block.body, block_frame)
  File "/home/gyz/python3.5.2/lib/python3.5/site-packages/jinja2/compiler.py", line 372, in blockvisit
    self.visit(node, frame)
  File "/home/gyz/python3.5.2/lib/python3.5/site-packages/jinja2/visitor.py", line 38, in visit
    return f(node, *args, **kwargs)
  File "/home/gyz/python3.5.2/lib/python3.5/site-packages/jinja2/compiler.py", line 1092, in visit_For
    self.blockvisit(node.body, loop_frame)
  File "/home/gyz/python3.5.2/lib/python3.5/site-packages/jinja2/compiler.py", line 372, in blockvisit
    self.visit(node, frame)
  File "/home/gyz/python3.5.2/lib/python3.5/site-packages/jinja2/visitor.py", line 38, in visit
    return f(node, *args, **kwargs)
  File "/home/gyz/python3.5.2/lib/python3.5/site-packages/jinja2/compiler.py", line 1321, in visit_Output
    self.visit(argument, frame)
  File "/home/gyz/python3.5.2/lib/python3.5/site-packages/jinja2/visitor.py", line 38, in visit
    return f(node, *args, **kwargs)
  File "/home/gyz/python3.5.2/lib/python3.5/site-packages/jinja2/compiler.py", line 70, in new_func
    return f(self, node, frame, **kwargs)
  File "/home/gyz/python3.5.2/lib/python3.5/site-packages/jinja2/compiler.py", line 1524, in visit_Filter
    self.fail('no filter named %r' % node.name, node.lineno)
  File "/home/gyz/python3.5.2/lib/python3.5/site-packages/jinja2/compiler.py", line 309, in fail
    raise TemplateAssertionError(msg, lineno, self.name, self.filename)
jinja2.exceptions.TemplateAssertionError: no filter named 'datetime'
2017-03-22 11:42:02,584 web_server.py[line:88] ERROR Error handling request
Traceback (most recent call last):
  File "/home/gyz/python3.5.2/lib/python3.5/site-packages/aiohttp/web_server.py", line 62, in handle_request
    resp = yield from self._handler(request)
  File "/home/gyz/python3.5.2/lib/python3.5/site-packages/aiohttp/web.py", line 270, in _handle
    resp = yield from handler(request)
  File "app.py", line 35, in logger
    return (yield from handler(request))
  File "app.py", line 73, in response
    resp = web.Response(body=app['__templating__'].get_template(template).render(**r).encode('utf-8'))
  File "/home/gyz/python3.5.2/lib/python3.5/site-packages/jinja2/environment.py", line 830, in get_template
    return self._load_template(name, self.make_globals(globals))
  File "/home/gyz/python3.5.2/lib/python3.5/site-packages/jinja2/environment.py", line 804, in _load_template
    template = self.loader.load(self, name, globals)
  File "/home/gyz/python3.5.2/lib/python3.5/site-packages/jinja2/loaders.py", line 125, in load
    code = environment.compile(source, name, filename)
  File "/home/gyz/python3.5.2/lib/python3.5/site-packages/jinja2/environment.py", line 591, in compile
    self.handle_exception(exc_info, source_hint=source_hint)
  File "/home/gyz/python3.5.2/lib/python3.5/site-packages/jinja2/environment.py", line 780, in handle_exception
    reraise(exc_type, exc_value, tb)
  File "/home/gyz/python3.5.2/lib/python3.5/site-packages/jinja2/_compat.py", line 37, in reraise
    raise value.with_traceback(tb)
  File "/home/pycode/python3-summer-blog/www/templates/blogs.html", line 18, in template
    <p class="uk-article-meta">发表于{{ blog.created_at|datetime }}</p>
  File "/home/gyz/python3.5.2/lib/python3.5/site-packages/jinja2/environment.py", line 543, in _generate
    optimized=self.optimized)
  File "/home/gyz/python3.5.2/lib/python3.5/site-packages/jinja2/compiler.py", line 82, in generate
    generator.visit(node)
  File "/home/gyz/python3.5.2/lib/python3.5/site-packages/jinja2/visitor.py", line 38, in visit
    return f(node, *args, **kwargs)
  File "/home/gyz/python3.5.2/lib/python3.5/site-packages/jinja2/compiler.py", line 772, in visit_Template
    self.blockvisit(block.body, block_frame)
  File "/home/gyz/python3.5.2/lib/python3.5/site-packages/jinja2/compiler.py", line 372, in blockvisit
    self.visit(node, frame)
  File "/home/gyz/python3.5.2/lib/python3.5/site-packages/jinja2/visitor.py", line 38, in visit
    return f(node, *args, **kwargs)
  File "/home/gyz/python3.5.2/lib/python3.5/site-packages/jinja2/compiler.py", line 1092, in visit_For
    self.blockvisit(node.body, loop_frame)
  File "/home/gyz/python3.5.2/lib/python3.5/site-packages/jinja2/compiler.py", line 372, in blockvisit
    self.visit(node, frame)
  File "/home/gyz/python3.5.2/lib/python3.5/site-packages/jinja2/visitor.py", line 38, in visit
    return f(node, *args, **kwargs)
  File "/home/gyz/python3.5.2/lib/python3.5/site-packages/jinja2/compiler.py", line 1321, in visit_Output
    self.visit(argument, frame)
  File "/home/gyz/python3.5.2/lib/python3.5/site-packages/jinja2/visitor.py", line 38, in visit
    return f(node, *args, **kwargs)
  File "/home/gyz/python3.5.2/lib/python3.5/site-packages/jinja2/compiler.py", line 70, in new_func
    return f(self, node, frame, **kwargs)
  File "/home/gyz/python3.5.2/lib/python3.5/site-packages/jinja2/compiler.py", line 1524, in visit_Filter
    self.fail('no filter named %r' % node.name, node.lineno)
  File "/home/gyz/python3.5.2/lib/python3.5/site-packages/jinja2/compiler.py", line 309, in fail
    raise TemplateAssertionError(msg, lineno, self.name, self.filename)
jinja2.exceptions.TemplateAssertionError: no filter named 'datetime'
2017-03-22 11:42:17,078 web_server.py[line:88] ERROR Error handling request
Traceback (most recent call last):
  File "/home/gyz/python3.5.2/lib/python3.5/site-packages/aiohttp/web_server.py", line 62, in handle_request
    resp = yield from self._handler(request)
  File "/home/gyz/python3.5.2/lib/python3.5/site-packages/aiohttp/web.py", line 270, in _handle
    resp = yield from handler(request)
  File "app.py", line 35, in logger
    return (yield from handler(request))
  File "app.py", line 73, in response
    resp = web.Response(body=app['__templating__'].get_template(template).render(**r).encode('utf-8'))
  File "/home/gyz/python3.5.2/lib/python3.5/site-packages/jinja2/environment.py", line 830, in get_template
    return self._load_template(name, self.make_globals(globals))
  File "/home/gyz/python3.5.2/lib/python3.5/site-packages/jinja2/environment.py", line 804, in _load_template
    template = self.loader.load(self, name, globals)
  File "/home/gyz/python3.5.2/lib/python3.5/site-packages/jinja2/loaders.py", line 125, in load
    code = environment.compile(source, name, filename)
  File "/home/gyz/python3.5.2/lib/python3.5/site-packages/jinja2/environment.py", line 591, in compile
    self.handle_exception(exc_info, source_hint=source_hint)
  File "/home/gyz/python3.5.2/lib/python3.5/site-packages/jinja2/environment.py", line 780, in handle_exception
    reraise(exc_type, exc_value, tb)
  File "/home/gyz/python3.5.2/lib/python3.5/site-packages/jinja2/_compat.py", line 37, in reraise
    raise value.with_traceback(tb)
  File "/home/pycode/python3-summer-blog/www/templates/blogs.html", line 18, in template
    <p class="uk-article-meta">发表于{{ blog.created_at|datetime }}</p>
  File "/home/gyz/python3.5.2/lib/python3.5/site-packages/jinja2/environment.py", line 543, in _generate
    optimized=self.optimized)
  File "/home/gyz/python3.5.2/lib/python3.5/site-packages/jinja2/compiler.py", line 82, in generate
    generator.visit(node)
  File "/home/gyz/python3.5.2/lib/python3.5/site-packages/jinja2/visitor.py", line 38, in visit
    return f(node, *args, **kwargs)
  File "/home/gyz/python3.5.2/lib/python3.5/site-packages/jinja2/compiler.py", line 772, in visit_Template
    self.blockvisit(block.body, block_frame)
  File "/home/gyz/python3.5.2/lib/python3.5/site-packages/jinja2/compiler.py", line 372, in blockvisit
    self.visit(node, frame)
  File "/home/gyz/python3.5.2/lib/python3.5/site-packages/jinja2/visitor.py", line 38, in visit
    return f(node, *args, **kwargs)
  File "/home/gyz/python3.5.2/lib/python3.5/site-packages/jinja2/compiler.py", line 1092, in visit_For
    self.blockvisit(node.body, loop_frame)
  File "/home/gyz/python3.5.2/lib/python3.5/site-packages/jinja2/compiler.py", line 372, in blockvisit
    self.visit(node, frame)
  File "/home/gyz/python3.5.2/lib/python3.5/site-packages/jinja2/visitor.py", line 38, in visit
    return f(node, *args, **kwargs)
  File "/home/gyz/python3.5.2/lib/python3.5/site-packages/jinja2/compiler.py", line 1321, in visit_Output
    self.visit(argument, frame)
  File "/home/gyz/python3.5.2/lib/python3.5/site-packages/jinja2/visitor.py", line 38, in visit
    return f(node, *args, **kwargs)
  File "/home/gyz/python3.5.2/lib/python3.5/site-packages/jinja2/compiler.py", line 70, in new_func
    return f(self, node, frame, **kwargs)
  File "/home/gyz/python3.5.2/lib/python3.5/site-packages/jinja2/compiler.py", line 1524, in visit_Filter
    self.fail('no filter named %r' % node.name, node.lineno)
  File "/home/gyz/python3.5.2/lib/python3.5/site-packages/jinja2/compiler.py", line 309, in fail
    raise TemplateAssertionError(msg, lineno, self.name, self.filename)
jinja2.exceptions.TemplateAssertionError: no filter named 'datetime'
2017-03-22 11:42:17,252 web_server.py[line:88] ERROR Error handling request
Traceback (most recent call last):
  File "/home/gyz/python3.5.2/lib/python3.5/site-packages/aiohttp/web_server.py", line 62, in handle_request
    resp = yield from self._handler(request)
  File "/home/gyz/python3.5.2/lib/python3.5/site-packages/aiohttp/web.py", line 270, in _handle
    resp = yield from handler(request)
  File "app.py", line 35, in logger
    return (yield from handler(request))
  File "app.py", line 73, in response
    resp = web.Response(body=app['__templating__'].get_template(template).render(**r).encode('utf-8'))
  File "/home/gyz/python3.5.2/lib/python3.5/site-packages/jinja2/environment.py", line 830, in get_template
    return self._load_template(name, self.make_globals(globals))
  File "/home/gyz/python3.5.2/lib/python3.5/site-packages/jinja2/environment.py", line 804, in _load_template
    template = self.loader.load(self, name, globals)
  File "/home/gyz/python3.5.2/lib/python3.5/site-packages/jinja2/loaders.py", line 125, in load
    code = environment.compile(source, name, filename)
  File "/home/gyz/python3.5.2/lib/python3.5/site-packages/jinja2/environment.py", line 591, in compile
    self.handle_exception(exc_info, source_hint=source_hint)
  File "/home/gyz/python3.5.2/lib/python3.5/site-packages/jinja2/environment.py", line 780, in handle_exception
    reraise(exc_type, exc_value, tb)
  File "/home/gyz/python3.5.2/lib/python3.5/site-packages/jinja2/_compat.py", line 37, in reraise
    raise value.with_traceback(tb)
  File "/home/pycode/python3-summer-blog/www/templates/blogs.html", line 18, in template
    <p class="uk-article-meta">发表于{{ blog.created_at|datetime }}</p>
  File "/home/gyz/python3.5.2/lib/python3.5/site-packages/jinja2/environment.py", line 543, in _generate
    optimized=self.optimized)
  File "/home/gyz/python3.5.2/lib/python3.5/site-packages/jinja2/compiler.py", line 82, in generate
    generator.visit(node)
  File "/home/gyz/python3.5.2/lib/python3.5/site-packages/jinja2/visitor.py", line 38, in visit
    return f(node, *args, **kwargs)
  File "/home/gyz/python3.5.2/lib/python3.5/site-packages/jinja2/compiler.py", line 772, in visit_Template
    self.blockvisit(block.body, block_frame)
  File "/home/gyz/python3.5.2/lib/python3.5/site-packages/jinja2/compiler.py", line 372, in blockvisit
    self.visit(node, frame)
  File "/home/gyz/python3.5.2/lib/python3.5/site-packages/jinja2/visitor.py", line 38, in visit
    return f(node, *args, **kwargs)
  File "/home/gyz/python3.5.2/lib/python3.5/site-packages/jinja2/compiler.py", line 1092, in visit_For
    self.blockvisit(node.body, loop_frame)
  File "/home/gyz/python3.5.2/lib/python3.5/site-packages/jinja2/compiler.py", line 372, in blockvisit
    self.visit(node, frame)
  File "/home/gyz/python3.5.2/lib/python3.5/site-packages/jinja2/visitor.py", line 38, in visit
    return f(node, *args, **kwargs)
  File "/home/gyz/python3.5.2/lib/python3.5/site-packages/jinja2/compiler.py", line 1321, in visit_Output
    self.visit(argument, frame)
  File "/home/gyz/python3.5.2/lib/python3.5/site-packages/jinja2/visitor.py", line 38, in visit
    return f(node, *args, **kwargs)
  File "/home/gyz/python3.5.2/lib/python3.5/site-packages/jinja2/compiler.py", line 70, in new_func
    return f(self, node, frame, **kwargs)
  File "/home/gyz/python3.5.2/lib/python3.5/site-packages/jinja2/compiler.py", line 1524, in visit_Filter
    self.fail('no filter named %r' % node.name, node.lineno)
  File "/home/gyz/python3.5.2/lib/python3.5/site-packages/jinja2/compiler.py", line 309, in fail
    raise TemplateAssertionError(msg, lineno, self.name, self.filename)
jinja2.exceptions.TemplateAssertionError: no filter named 'datetime'
2017-03-22 11:42:17,508 web_server.py[line:88] ERROR Error handling request
Traceback (most recent call last):
  File "/home/gyz/python3.5.2/lib/python3.5/site-packages/aiohttp/web_server.py", line 62, in handle_request
    resp = yield from self._handler(request)
  File "/home/gyz/python3.5.2/lib/python3.5/site-packages/aiohttp/web.py", line 270, in _handle
    resp = yield from handler(request)
  File "app.py", line 35, in logger
    return (yield from handler(request))
  File "app.py", line 73, in response
    resp = web.Response(body=app['__templating__'].get_template(template).render(**r).encode('utf-8'))
  File "/home/gyz/python3.5.2/lib/python3.5/site-packages/jinja2/environment.py", line 830, in get_template
    return self._load_template(name, self.make_globals(globals))
  File "/home/gyz/python3.5.2/lib/python3.5/site-packages/jinja2/environment.py", line 804, in _load_template
    template = self.loader.load(self, name, globals)
  File "/home/gyz/python3.5.2/lib/python3.5/site-packages/jinja2/loaders.py", line 125, in load
    code = environment.compile(source, name, filename)
  File "/home/gyz/python3.5.2/lib/python3.5/site-packages/jinja2/environment.py", line 591, in compile
    self.handle_exception(exc_info, source_hint=source_hint)
  File "/home/gyz/python3.5.2/lib/python3.5/site-packages/jinja2/environment.py", line 780, in handle_exception
    reraise(exc_type, exc_value, tb)
  File "/home/gyz/python3.5.2/lib/python3.5/site-packages/jinja2/_compat.py", line 37, in reraise
    raise value.with_traceback(tb)
  File "/home/pycode/python3-summer-blog/www/templates/blogs.html", line 18, in template
    <p class="uk-article-meta">发表于{{ blog.created_at|datetime }}</p>
  File "/home/gyz/python3.5.2/lib/python3.5/site-packages/jinja2/environment.py", line 543, in _generate
    optimized=self.optimized)
  File "/home/gyz/python3.5.2/lib/python3.5/site-packages/jinja2/compiler.py", line 82, in generate
    generator.visit(node)
  File "/home/gyz/python3.5.2/lib/python3.5/site-packages/jinja2/visitor.py", line 38, in visit
    return f(node, *args, **kwargs)
  File "/home/gyz/python3.5.2/lib/python3.5/site-packages/jinja2/compiler.py", line 772, in visit_Template
    self.blockvisit(block.body, block_frame)
  File "/home/gyz/python3.5.2/lib/python3.5/site-packages/jinja2/compiler.py", line 372, in blockvisit
    self.visit(node, frame)
  File "/home/gyz/python3.5.2/lib/python3.5/site-packages/jinja2/visitor.py", line 38, in visit
    return f(node, *args, **kwargs)
  File "/home/gyz/python3.5.2/lib/python3.5/site-packages/jinja2/compiler.py", line 1092, in visit_For
    self.blockvisit(node.body, loop_frame)
  File "/home/gyz/python3.5.2/lib/python3.5/site-packages/jinja2/compiler.py", line 372, in blockvisit
    self.visit(node, frame)
  File "/home/gyz/python3.5.2/lib/python3.5/site-packages/jinja2/visitor.py", line 38, in visit
    return f(node, *args, **kwargs)
  File "/home/gyz/python3.5.2/lib/python3.5/site-packages/jinja2/compiler.py", line 1321, in visit_Output
    self.visit(argument, frame)
  File "/home/gyz/python3.5.2/lib/python3.5/site-packages/jinja2/visitor.py", line 38, in visit
    return f(node, *args, **kwargs)
  File "/home/gyz/python3.5.2/lib/python3.5/site-packages/jinja2/compiler.py", line 70, in new_func
    return f(self, node, frame, **kwargs)
  File "/home/gyz/python3.5.2/lib/python3.5/site-packages/jinja2/compiler.py", line 1524, in visit_Filter
    self.fail('no filter named %r' % node.name, node.lineno)
  File "/home/gyz/python3.5.2/lib/python3.5/site-packages/jinja2/compiler.py", line 309, in fail
    raise TemplateAssertionError(msg, lineno, self.name, self.filename)
jinja2.exceptions.TemplateAssertionError: no filter named 'datetime'
2017-03-22 11:48:09,614 web_server.py[line:88] ERROR Error handling request
Traceback (most recent call last):
  File "/home/gyz/python3.5.2/lib/python3.5/site-packages/aiohttp/web_server.py", line 62, in handle_request
    resp = yield from self._handler(request)
  File "/home/gyz/python3.5.2/lib/python3.5/site-packages/aiohttp/web.py", line 270, in _handle
    resp = yield from handler(request)
  File "app.py", line 35, in logger
    return (yield from handler(request))
  File "app.py", line 73, in response
    resp = web.Response(body=app['__templating__'].get_template(template).render(**r).encode('utf-8'))
  File "/home/gyz/python3.5.2/lib/python3.5/site-packages/jinja2/environment.py", line 1008, in render
    return self.environment.handle_exception(exc_info, True)
  File "/home/gyz/python3.5.2/lib/python3.5/site-packages/jinja2/environment.py", line 780, in handle_exception
    reraise(exc_type, exc_value, tb)
  File "/home/gyz/python3.5.2/lib/python3.5/site-packages/jinja2/_compat.py", line 37, in reraise
    raise value.with_traceback(tb)
  File "/home/pycode/python3-summer-blog/www/templates/blogs.html", line 1, in top-level template code
    {% extends '__base__.html' %}
  File "/home/pycode/python3-summer-blog/www/templates/__base__.html", line 67, in top-level template code
    {% block content %}
  File "/home/pycode/python3-summer-blog/www/templates/blogs.html", line 18, in block "content"
    <p class="uk-article-meta">发表于{{ blog.created_at|datetime }}</p>
  File "app.py", line 93, in datetime_filter
    return r'%s minutes ago' (delta//60)
TypeError: 'str' object is not callable
2017-03-22 11:48:09,768 web_server.py[line:88] ERROR Error handling request
Traceback (most recent call last):
  File "/home/gyz/python3.5.2/lib/python3.5/site-packages/aiohttp/web_server.py", line 62, in handle_request
    resp = yield from self._handler(request)
  File "/home/gyz/python3.5.2/lib/python3.5/site-packages/aiohttp/web.py", line 270, in _handle
    resp = yield from handler(request)
  File "app.py", line 35, in logger
    return (yield from handler(request))
  File "app.py", line 73, in response
    resp = web.Response(body=app['__templating__'].get_template(template).render(**r).encode('utf-8'))
  File "/home/gyz/python3.5.2/lib/python3.5/site-packages/jinja2/environment.py", line 1008, in render
    return self.environment.handle_exception(exc_info, True)
  File "/home/gyz/python3.5.2/lib/python3.5/site-packages/jinja2/environment.py", line 780, in handle_exception
    reraise(exc_type, exc_value, tb)
  File "/home/gyz/python3.5.2/lib/python3.5/site-packages/jinja2/_compat.py", line 37, in reraise
    raise value.with_traceback(tb)
  File "/home/pycode/python3-summer-blog/www/templates/blogs.html", line 1, in top-level template code
    {% extends '__base__.html' %}
  File "/home/pycode/python3-summer-blog/www/templates/__base__.html", line 67, in top-level template code
    {% block content %}
  File "/home/pycode/python3-summer-blog/www/templates/blogs.html", line 18, in block "content"
    <p class="uk-article-meta">发表于{{ blog.created_at|datetime }}</p>
  File "app.py", line 93, in datetime_filter
    return r'%s minutes ago' (delta//60)
TypeError: 'str' object is not callable
2017-03-22 11:48:10,144 web_server.py[line:88] ERROR Error handling request
Traceback (most recent call last):
  File "/home/gyz/python3.5.2/lib/python3.5/site-packages/aiohttp/web_server.py", line 62, in handle_request
    resp = yield from self._handler(request)
  File "/home/gyz/python3.5.2/lib/python3.5/site-packages/aiohttp/web.py", line 270, in _handle
    resp = yield from handler(request)
  File "app.py", line 35, in logger
    return (yield from handler(request))
  File "app.py", line 73, in response
    resp = web.Response(body=app['__templating__'].get_template(template).render(**r).encode('utf-8'))
  File "/home/gyz/python3.5.2/lib/python3.5/site-packages/jinja2/environment.py", line 1008, in render
    return self.environment.handle_exception(exc_info, True)
  File "/home/gyz/python3.5.2/lib/python3.5/site-packages/jinja2/environment.py", line 780, in handle_exception
    reraise(exc_type, exc_value, tb)
  File "/home/gyz/python3.5.2/lib/python3.5/site-packages/jinja2/_compat.py", line 37, in reraise
    raise value.with_traceback(tb)
  File "/home/pycode/python3-summer-blog/www/templates/blogs.html", line 1, in top-level template code
    {% extends '__base__.html' %}
  File "/home/pycode/python3-summer-blog/www/templates/__base__.html", line 67, in top-level template code
    {% block content %}
  File "/home/pycode/python3-summer-blog/www/templates/blogs.html", line 18, in block "content"
    <p class="uk-article-meta">发表于{{ blog.created_at|datetime }}</p>
  File "app.py", line 93, in datetime_filter
    return r'%s minutes ago' (delta//60)
TypeError: 'str' object is not callable
2017-03-22 11:49:01,857 web_server.py[line:88] ERROR Error handling request
Traceback (most recent call last):
  File "/home/gyz/python3.5.2/lib/python3.5/site-packages/aiohttp/web_server.py", line 62, in handle_request
    resp = yield from self._handler(request)
  File "/home/gyz/python3.5.2/lib/python3.5/site-packages/aiohttp/web.py", line 270, in _handle
    resp = yield from handler(request)
  File "app.py", line 35, in logger
    return (yield from handler(request))
  File "app.py", line 73, in response
    resp = web.Response(body=app['__templating__'].get_template(template).render(**r).encode('utf-8'))
  File "/home/gyz/python3.5.2/lib/python3.5/site-packages/jinja2/environment.py", line 1008, in render
    return self.environment.handle_exception(exc_info, True)
  File "/home/gyz/python3.5.2/lib/python3.5/site-packages/jinja2/environment.py", line 780, in handle_exception
    reraise(exc_type, exc_value, tb)
  File "/home/gyz/python3.5.2/lib/python3.5/site-packages/jinja2/_compat.py", line 37, in reraise
    raise value.with_traceback(tb)
  File "/home/pycode/python3-summer-blog/www/templates/blogs.html", line 1, in top-level template code
    {% extends '__base__.html' %}
  File "/home/pycode/python3-summer-blog/www/templates/__base__.html", line 67, in top-level template code
    {% block content %}
  File "/home/pycode/python3-summer-blog/www/templates/blogs.html", line 18, in block "content"
    <p class="uk-article-meta">发表于{{ blog.created_at|datetime }}</p>
  File "app.py", line 93, in datetime_filter
    return '%s minutes ago' (delta//60)
TypeError: 'str' object is not callable
2017-03-22 11:49:02,008 web_server.py[line:88] ERROR Error handling request
Traceback (most recent call last):
  File "/home/gyz/python3.5.2/lib/python3.5/site-packages/aiohttp/web_server.py", line 62, in handle_request
    resp = yield from self._handler(request)
  File "/home/gyz/python3.5.2/lib/python3.5/site-packages/aiohttp/web.py", line 270, in _handle
    resp = yield from handler(request)
  File "app.py", line 35, in logger
    return (yield from handler(request))
  File "app.py", line 73, in response
    resp = web.Response(body=app['__templating__'].get_template(template).render(**r).encode('utf-8'))
  File "/home/gyz/python3.5.2/lib/python3.5/site-packages/jinja2/environment.py", line 1008, in render
    return self.environment.handle_exception(exc_info, True)
  File "/home/gyz/python3.5.2/lib/python3.5/site-packages/jinja2/environment.py", line 780, in handle_exception
    reraise(exc_type, exc_value, tb)
  File "/home/gyz/python3.5.2/lib/python3.5/site-packages/jinja2/_compat.py", line 37, in reraise
    raise value.with_traceback(tb)
  File "/home/pycode/python3-summer-blog/www/templates/blogs.html", line 1, in top-level template code
    {% extends '__base__.html' %}
  File "/home/pycode/python3-summer-blog/www/templates/__base__.html", line 67, in top-level template code
    {% block content %}
  File "/home/pycode/python3-summer-blog/www/templates/blogs.html", line 18, in block "content"
    <p class="uk-article-meta">发表于{{ blog.created_at|datetime }}</p>
  File "app.py", line 93, in datetime_filter
    return '%s minutes ago' (delta//60)
TypeError: 'str' object is not callable
2017-03-22 11:49:02,316 web_server.py[line:88] ERROR Error handling request
Traceback (most recent call last):
  File "/home/gyz/python3.5.2/lib/python3.5/site-packages/aiohttp/web_server.py", line 62, in handle_request
    resp = yield from self._handler(request)
  File "/home/gyz/python3.5.2/lib/python3.5/site-packages/aiohttp/web.py", line 270, in _handle
    resp = yield from handler(request)
  File "app.py", line 35, in logger
    return (yield from handler(request))
  File "app.py", line 73, in response
    resp = web.Response(body=app['__templating__'].get_template(template).render(**r).encode('utf-8'))
  File "/home/gyz/python3.5.2/lib/python3.5/site-packages/jinja2/environment.py", line 1008, in render
    return self.environment.handle_exception(exc_info, True)
  File "/home/gyz/python3.5.2/lib/python3.5/site-packages/jinja2/environment.py", line 780, in handle_exception
    reraise(exc_type, exc_value, tb)
  File "/home/gyz/python3.5.2/lib/python3.5/site-packages/jinja2/_compat.py", line 37, in reraise
    raise value.with_traceback(tb)
  File "/home/pycode/python3-summer-blog/www/templates/blogs.html", line 1, in top-level template code
    {% extends '__base__.html' %}
  File "/home/pycode/python3-summer-blog/www/templates/__base__.html", line 67, in top-level template code
    {% block content %}
  File "/home/pycode/python3-summer-blog/www/templates/blogs.html", line 18, in block "content"
    <p class="uk-article-meta">发表于{{ blog.created_at|datetime }}</p>
  File "app.py", line 93, in datetime_filter
    return '%s minutes ago' (delta//60)
TypeError: 'str' object is not callable
2017-03-22 11:50:26,888 web_server.py[line:88] ERROR Error handling request
Traceback (most recent call last):
  File "/home/gyz/python3.5.2/lib/python3.5/site-packages/aiohttp/web_server.py", line 62, in handle_request
    resp = yield from self._handler(request)
  File "/home/gyz/python3.5.2/lib/python3.5/site-packages/aiohttp/web.py", line 270, in _handle
    resp = yield from handler(request)
  File "app.py", line 35, in logger
    return (yield from handler(request))
  File "app.py", line 73, in response
    resp = web.Response(body=app['__templating__'].get_template(template).render(**r).encode('utf-8'))
  File "/home/gyz/python3.5.2/lib/python3.5/site-packages/jinja2/environment.py", line 1008, in render
    return self.environment.handle_exception(exc_info, True)
  File "/home/gyz/python3.5.2/lib/python3.5/site-packages/jinja2/environment.py", line 780, in handle_exception
    reraise(exc_type, exc_value, tb)
  File "/home/gyz/python3.5.2/lib/python3.5/site-packages/jinja2/_compat.py", line 37, in reraise
    raise value.with_traceback(tb)
  File "/home/pycode/python3-summer-blog/www/templates/blogs.html", line 1, in top-level template code
    {% extends '__base__.html' %}
  File "/home/pycode/python3-summer-blog/www/templates/__base__.html", line 67, in top-level template code
    {% block content %}
  File "/home/pycode/python3-summer-blog/www/templates/blogs.html", line 18, in block "content"
    <p class="uk-article-meta">发表于{{ blog.created_at|datetime }}</p>
  File "app.py", line 93, in datetime_filter
    return u'%s minutes ago' (delta//60)
TypeError: 'str' object is not callable
2017-03-22 11:50:27,046 web_server.py[line:88] ERROR Error handling request
Traceback (most recent call last):
  File "/home/gyz/python3.5.2/lib/python3.5/site-packages/aiohttp/web_server.py", line 62, in handle_request
    resp = yield from self._handler(request)
  File "/home/gyz/python3.5.2/lib/python3.5/site-packages/aiohttp/web.py", line 270, in _handle
    resp = yield from handler(request)
  File "app.py", line 35, in logger
    return (yield from handler(request))
  File "app.py", line 73, in response
    resp = web.Response(body=app['__templating__'].get_template(template).render(**r).encode('utf-8'))
  File "/home/gyz/python3.5.2/lib/python3.5/site-packages/jinja2/environment.py", line 1008, in render
    return self.environment.handle_exception(exc_info, True)
  File "/home/gyz/python3.5.2/lib/python3.5/site-packages/jinja2/environment.py", line 780, in handle_exception
    reraise(exc_type, exc_value, tb)
  File "/home/gyz/python3.5.2/lib/python3.5/site-packages/jinja2/_compat.py", line 37, in reraise
    raise value.with_traceback(tb)
  File "/home/pycode/python3-summer-blog/www/templates/blogs.html", line 1, in top-level template code
    {% extends '__base__.html' %}
  File "/home/pycode/python3-summer-blog/www/templates/__base__.html", line 67, in top-level template code
    {% block content %}
  File "/home/pycode/python3-summer-blog/www/templates/blogs.html", line 18, in block "content"
    <p class="uk-article-meta">发表于{{ blog.created_at|datetime }}</p>
  File "app.py", line 93, in datetime_filter
    return u'%s minutes ago' (delta//60)
TypeError: 'str' object is not callable
2017-03-22 11:50:27,530 web_server.py[line:88] ERROR Error handling request
Traceback (most recent call last):
  File "/home/gyz/python3.5.2/lib/python3.5/site-packages/aiohttp/web_server.py", line 62, in handle_request
    resp = yield from self._handler(request)
  File "/home/gyz/python3.5.2/lib/python3.5/site-packages/aiohttp/web.py", line 270, in _handle
    resp = yield from handler(request)
  File "app.py", line 35, in logger
    return (yield from handler(request))
  File "app.py", line 73, in response
    resp = web.Response(body=app['__templating__'].get_template(template).render(**r).encode('utf-8'))
  File "/home/gyz/python3.5.2/lib/python3.5/site-packages/jinja2/environment.py", line 1008, in render
    return self.environment.handle_exception(exc_info, True)
  File "/home/gyz/python3.5.2/lib/python3.5/site-packages/jinja2/environment.py", line 780, in handle_exception
    reraise(exc_type, exc_value, tb)
  File "/home/gyz/python3.5.2/lib/python3.5/site-packages/jinja2/_compat.py", line 37, in reraise
    raise value.with_traceback(tb)
  File "/home/pycode/python3-summer-blog/www/templates/blogs.html", line 1, in top-level template code
    {% extends '__base__.html' %}
  File "/home/pycode/python3-summer-blog/www/templates/__base__.html", line 67, in top-level template code
    {% block content %}
  File "/home/pycode/python3-summer-blog/www/templates/blogs.html", line 18, in block "content"
    <p class="uk-article-meta">发表于{{ blog.created_at|datetime }}</p>
  File "app.py", line 93, in datetime_filter
    return u'%s minutes ago' (delta//60)
TypeError: 'str' object is not callable
2017-03-22 13:21:43,314 web_server.py[line:88] ERROR Error handling request
Traceback (most recent call last):
  File "/home/gyz/python3.5.2/lib/python3.5/site-packages/aiohttp/web_server.py", line 62, in handle_request
    resp = yield from self._handler(request)
  File "/home/gyz/python3.5.2/lib/python3.5/site-packages/aiohttp/web.py", line 270, in _handle
    resp = yield from handler(request)
  File "app.py", line 35, in logger
    return (yield from handler(request))
  File "app.py", line 73, in response
    resp = web.Response(body=app['__templating__'].get_template(template).render(**r).encode('utf-8'))
  File "/home/gyz/python3.5.2/lib/python3.5/site-packages/jinja2/environment.py", line 1008, in render
    return self.environment.handle_exception(exc_info, True)
  File "/home/gyz/python3.5.2/lib/python3.5/site-packages/jinja2/environment.py", line 780, in handle_exception
    reraise(exc_type, exc_value, tb)
  File "/home/gyz/python3.5.2/lib/python3.5/site-packages/jinja2/_compat.py", line 37, in reraise
    raise value.with_traceback(tb)
  File "/home/pycode/python3-summer-blog/www/templates/blogs.html", line 1, in top-level template code
    {% extends '__base__.html' %}
  File "/home/pycode/python3-summer-blog/www/templates/__base__.html", line 67, in top-level template code
    {% block content %}
  File "/home/pycode/python3-summer-blog/www/templates/blogs.html", line 18, in block "content"
    <p class="uk-article-meta">发表于{{ blog.created_at|datetime }}</p>
  File "app.py", line 93, in datetime_filter
    return '%s minutes ago' (delta//60)
TypeError: 'str' object is not callable
2017-03-22 13:21:43,500 web_server.py[line:88] ERROR Error handling request
Traceback (most recent call last):
  File "/home/gyz/python3.5.2/lib/python3.5/site-packages/aiohttp/web_server.py", line 62, in handle_request
    resp = yield from self._handler(request)
  File "/home/gyz/python3.5.2/lib/python3.5/site-packages/aiohttp/web.py", line 270, in _handle
    resp = yield from handler(request)
  File "app.py", line 35, in logger
    return (yield from handler(request))
  File "app.py", line 73, in response
    resp = web.Response(body=app['__templating__'].get_template(template).render(**r).encode('utf-8'))
  File "/home/gyz/python3.5.2/lib/python3.5/site-packages/jinja2/environment.py", line 1008, in render
    return self.environment.handle_exception(exc_info, True)
  File "/home/gyz/python3.5.2/lib/python3.5/site-packages/jinja2/environment.py", line 780, in handle_exception
    reraise(exc_type, exc_value, tb)
  File "/home/gyz/python3.5.2/lib/python3.5/site-packages/jinja2/_compat.py", line 37, in reraise
    raise value.with_traceback(tb)
  File "/home/pycode/python3-summer-blog/www/templates/blogs.html", line 1, in top-level template code
    {% extends '__base__.html' %}
  File "/home/pycode/python3-summer-blog/www/templates/__base__.html", line 67, in top-level template code
    {% block content %}
  File "/home/pycode/python3-summer-blog/www/templates/blogs.html", line 18, in block "content"
    <p class="uk-article-meta">发表于{{ blog.created_at|datetime }}</p>
  File "app.py", line 93, in datetime_filter
    return '%s minutes ago' (delta//60)
TypeError: 'str' object is not callable
2017-03-22 13:21:45,269 web_server.py[line:88] ERROR Error handling request
Traceback (most recent call last):
  File "/home/gyz/python3.5.2/lib/python3.5/site-packages/aiohttp/web_server.py", line 62, in handle_request
    resp = yield from self._handler(request)
  File "/home/gyz/python3.5.2/lib/python3.5/site-packages/aiohttp/web.py", line 270, in _handle
    resp = yield from handler(request)
  File "app.py", line 35, in logger
    return (yield from handler(request))
  File "app.py", line 73, in response
    resp = web.Response(body=app['__templating__'].get_template(template).render(**r).encode('utf-8'))
  File "/home/gyz/python3.5.2/lib/python3.5/site-packages/jinja2/environment.py", line 1008, in render
    return self.environment.handle_exception(exc_info, True)
  File "/home/gyz/python3.5.2/lib/python3.5/site-packages/jinja2/environment.py", line 780, in handle_exception
    reraise(exc_type, exc_value, tb)
  File "/home/gyz/python3.5.2/lib/python3.5/site-packages/jinja2/_compat.py", line 37, in reraise
    raise value.with_traceback(tb)
  File "/home/pycode/python3-summer-blog/www/templates/blogs.html", line 1, in top-level template code
    {% extends '__base__.html' %}
  File "/home/pycode/python3-summer-blog/www/templates/__base__.html", line 67, in top-level template code
    {% block content %}
  File "/home/pycode/python3-summer-blog/www/templates/blogs.html", line 18, in block "content"
    <p class="uk-article-meta">发表于{{ blog.created_at|datetime }}</p>
  File "app.py", line 93, in datetime_filter
    return '%s minutes ago' (delta//60)
TypeError: 'str' object is not callable
2017-03-22 13:29:11,809 web_server.py[line:88] ERROR Error handling request
Traceback (most recent call last):
  File "/home/gyz/python3.5.2/lib/python3.5/site-packages/aiohttp/web_server.py", line 62, in handle_request
    resp = yield from self._handler(request)
  File "/home/gyz/python3.5.2/lib/python3.5/site-packages/aiohttp/web.py", line 270, in _handle
    resp = yield from handler(request)
  File "app.py", line 35, in logger
    return (yield from handler(request))
  File "app.py", line 73, in response
    resp = web.Response(body=app['__templating__'].get_template(template).render(**r).encode('utf-8'))
  File "/home/gyz/python3.5.2/lib/python3.5/site-packages/jinja2/environment.py", line 1008, in render
    return self.environment.handle_exception(exc_info, True)
  File "/home/gyz/python3.5.2/lib/python3.5/site-packages/jinja2/environment.py", line 780, in handle_exception
    reraise(exc_type, exc_value, tb)
  File "/home/gyz/python3.5.2/lib/python3.5/site-packages/jinja2/_compat.py", line 37, in reraise
    raise value.with_traceback(tb)
  File "/home/pycode/python3-summer-blog/www/templates/blogs.html", line 1, in top-level template code
    {% extends '__base__.html' %}
  File "/home/pycode/python3-summer-blog/www/templates/__base__.html", line 67, in top-level template code
    {% block content %}
  File "/home/pycode/python3-summer-blog/www/templates/blogs.html", line 18, in block "content"
    <p class="uk-article-meta">发表于{{ blog.created_at|datetime }}</p>
  File "app.py", line 93, in datetime_filter
    return str('%s minutes ago' (delta//60))
TypeError: 'str' object is not callable
2017-03-22 13:29:11,996 web_server.py[line:88] ERROR Error handling request
Traceback (most recent call last):
  File "/home/gyz/python3.5.2/lib/python3.5/site-packages/aiohttp/web_server.py", line 62, in handle_request
    resp = yield from self._handler(request)
  File "/home/gyz/python3.5.2/lib/python3.5/site-packages/aiohttp/web.py", line 270, in _handle
    resp = yield from handler(request)
  File "app.py", line 35, in logger
    return (yield from handler(request))
  File "app.py", line 73, in response
    resp = web.Response(body=app['__templating__'].get_template(template).render(**r).encode('utf-8'))
  File "/home/gyz/python3.5.2/lib/python3.5/site-packages/jinja2/environment.py", line 1008, in render
    return self.environment.handle_exception(exc_info, True)
  File "/home/gyz/python3.5.2/lib/python3.5/site-packages/jinja2/environment.py", line 780, in handle_exception
    reraise(exc_type, exc_value, tb)
  File "/home/gyz/python3.5.2/lib/python3.5/site-packages/jinja2/_compat.py", line 37, in reraise
    raise value.with_traceback(tb)
  File "/home/pycode/python3-summer-blog/www/templates/blogs.html", line 1, in top-level template code
    {% extends '__base__.html' %}
  File "/home/pycode/python3-summer-blog/www/templates/__base__.html", line 67, in top-level template code
    {% block content %}
  File "/home/pycode/python3-summer-blog/www/templates/blogs.html", line 18, in block "content"
    <p class="uk-article-meta">发表于{{ blog.created_at|datetime }}</p>
  File "app.py", line 93, in datetime_filter
    return str('%s minutes ago' (delta//60))
TypeError: 'str' object is not callable
2017-03-22 13:29:12,343 web_server.py[line:88] ERROR Error handling request
Traceback (most recent call last):
  File "/home/gyz/python3.5.2/lib/python3.5/site-packages/aiohttp/web_server.py", line 62, in handle_request
    resp = yield from self._handler(request)
  File "/home/gyz/python3.5.2/lib/python3.5/site-packages/aiohttp/web.py", line 270, in _handle
    resp = yield from handler(request)
  File "app.py", line 35, in logger
    return (yield from handler(request))
  File "app.py", line 73, in response
    resp = web.Response(body=app['__templating__'].get_template(template).render(**r).encode('utf-8'))
  File "/home/gyz/python3.5.2/lib/python3.5/site-packages/jinja2/environment.py", line 1008, in render
    return self.environment.handle_exception(exc_info, True)
  File "/home/gyz/python3.5.2/lib/python3.5/site-packages/jinja2/environment.py", line 780, in handle_exception
    reraise(exc_type, exc_value, tb)
  File "/home/gyz/python3.5.2/lib/python3.5/site-packages/jinja2/_compat.py", line 37, in reraise
    raise value.with_traceback(tb)
  File "/home/pycode/python3-summer-blog/www/templates/blogs.html", line 1, in top-level template code
    {% extends '__base__.html' %}
  File "/home/pycode/python3-summer-blog/www/templates/__base__.html", line 67, in top-level template code
    {% block content %}
  File "/home/pycode/python3-summer-blog/www/templates/blogs.html", line 18, in block "content"
    <p class="uk-article-meta">发表于{{ blog.created_at|datetime }}</p>
  File "app.py", line 93, in datetime_filter
    return str('%s minutes ago' (delta//60))
TypeError: 'str' object is not callable
2017-03-22 13:34:09,212 web_server.py[line:88] ERROR Error handling request
Traceback (most recent call last):
  File "/home/gyz/python3.5.2/lib/python3.5/site-packages/aiohttp/web_server.py", line 62, in handle_request
    resp = yield from self._handler(request)
  File "/home/gyz/python3.5.2/lib/python3.5/site-packages/aiohttp/web.py", line 270, in _handle
    resp = yield from handler(request)
  File "app.py", line 35, in logger
    return (yield from handler(request))
  File "app.py", line 73, in response
    resp = web.Response(body=app['__templating__'].get_template(template).render(**r).encode('utf-8'))
  File "/home/gyz/python3.5.2/lib/python3.5/site-packages/jinja2/environment.py", line 1008, in render
    return self.environment.handle_exception(exc_info, True)
  File "/home/gyz/python3.5.2/lib/python3.5/site-packages/jinja2/environment.py", line 780, in handle_exception
    reraise(exc_type, exc_value, tb)
  File "/home/gyz/python3.5.2/lib/python3.5/site-packages/jinja2/_compat.py", line 37, in reraise
    raise value.with_traceback(tb)
  File "/home/pycode/python3-summer-blog/www/templates/blogs.html", line 1, in top-level template code
    {% extends '__base__.html' %}
  File "/home/pycode/python3-summer-blog/www/templates/__base__.html", line 67, in top-level template code
    {% block content %}
  File "/home/pycode/python3-summer-blog/www/templates/blogs.html", line 18, in block "content"
    <p class="uk-article-meta">发表于{{ blog.created_at|datetime }}</p>
  File "app.py", line 93, in datetime_filter
    return u'%s minutes ago' (delta//60)
TypeError: 'str' object is not callable
2017-03-22 13:34:09,376 web_server.py[line:88] ERROR Error handling request
Traceback (most recent call last):
  File "/home/gyz/python3.5.2/lib/python3.5/site-packages/aiohttp/web_server.py", line 62, in handle_request
    resp = yield from self._handler(request)
  File "/home/gyz/python3.5.2/lib/python3.5/site-packages/aiohttp/web.py", line 270, in _handle
    resp = yield from handler(request)
  File "app.py", line 35, in logger
    return (yield from handler(request))
  File "app.py", line 73, in response
    resp = web.Response(body=app['__templating__'].get_template(template).render(**r).encode('utf-8'))
  File "/home/gyz/python3.5.2/lib/python3.5/site-packages/jinja2/environment.py", line 1008, in render
    return self.environment.handle_exception(exc_info, True)
  File "/home/gyz/python3.5.2/lib/python3.5/site-packages/jinja2/environment.py", line 780, in handle_exception
    reraise(exc_type, exc_value, tb)
  File "/home/gyz/python3.5.2/lib/python3.5/site-packages/jinja2/_compat.py", line 37, in reraise
    raise value.with_traceback(tb)
  File "/home/pycode/python3-summer-blog/www/templates/blogs.html", line 1, in top-level template code
    {% extends '__base__.html' %}
  File "/home/pycode/python3-summer-blog/www/templates/__base__.html", line 67, in top-level template code
    {% block content %}
  File "/home/pycode/python3-summer-blog/www/templates/blogs.html", line 18, in block "content"
    <p class="uk-article-meta">发表于{{ blog.created_at|datetime }}</p>
  File "app.py", line 93, in datetime_filter
    return u'%s minutes ago' (delta//60)
TypeError: 'str' object is not callable
2017-03-22 13:34:11,726 web_server.py[line:88] ERROR Error handling request
Traceback (most recent call last):
  File "/home/gyz/python3.5.2/lib/python3.5/site-packages/aiohttp/web_server.py", line 62, in handle_request
    resp = yield from self._handler(request)
  File "/home/gyz/python3.5.2/lib/python3.5/site-packages/aiohttp/web.py", line 270, in _handle
    resp = yield from handler(request)
  File "app.py", line 35, in logger
    return (yield from handler(request))
  File "app.py", line 73, in response
    resp = web.Response(body=app['__templating__'].get_template(template).render(**r).encode('utf-8'))
  File "/home/gyz/python3.5.2/lib/python3.5/site-packages/jinja2/environment.py", line 1008, in render
    return self.environment.handle_exception(exc_info, True)
  File "/home/gyz/python3.5.2/lib/python3.5/site-packages/jinja2/environment.py", line 780, in handle_exception
    reraise(exc_type, exc_value, tb)
  File "/home/gyz/python3.5.2/lib/python3.5/site-packages/jinja2/_compat.py", line 37, in reraise
    raise value.with_traceback(tb)
  File "/home/pycode/python3-summer-blog/www/templates/blogs.html", line 1, in top-level template code
    {% extends '__base__.html' %}
  File "/home/pycode/python3-summer-blog/www/templates/__base__.html", line 67, in top-level template code
    {% block content %}
  File "/home/pycode/python3-summer-blog/www/templates/blogs.html", line 18, in block "content"
    <p class="uk-article-meta">发表于{{ blog.created_at|datetime }}</p>
  File "app.py", line 93, in datetime_filter
    return u'%s minutes ago' (delta//60)
TypeError: 'str' object is not callable
2017-03-22 13:35:34,692 web_server.py[line:88] ERROR Error handling request
Traceback (most recent call last):
  File "/home/gyz/python3.5.2/lib/python3.5/site-packages/aiohttp/web_server.py", line 62, in handle_request
    resp = yield from self._handler(request)
  File "/home/gyz/python3.5.2/lib/python3.5/site-packages/aiohttp/web.py", line 270, in _handle
    resp = yield from handler(request)
  File "app.py", line 35, in logger
    return (yield from handler(request))
  File "app.py", line 73, in response
    resp = web.Response(body=app['__templating__'].get_template(template).render(**r).encode('utf-8'))
  File "/home/gyz/python3.5.2/lib/python3.5/site-packages/jinja2/environment.py", line 1008, in render
    return self.environment.handle_exception(exc_info, True)
  File "/home/gyz/python3.5.2/lib/python3.5/site-packages/jinja2/environment.py", line 780, in handle_exception
    reraise(exc_type, exc_value, tb)
  File "/home/gyz/python3.5.2/lib/python3.5/site-packages/jinja2/_compat.py", line 37, in reraise
    raise value.with_traceback(tb)
  File "/home/pycode/python3-summer-blog/www/templates/blogs.html", line 1, in top-level template code
    {% extends '__base__.html' %}
  File "/home/pycode/python3-summer-blog/www/templates/__base__.html", line 67, in top-level template code
    {% block content %}
  File "/home/pycode/python3-summer-blog/www/templates/blogs.html", line 18, in block "content"
    <p class="uk-article-meta">{{ blog.created_at|datetime }}</p>
  File "app.py", line 93, in datetime_filter
    return u'%s minutes ago' (delta//60)
TypeError: 'str' object is not callable
2017-03-22 13:35:34,850 web_server.py[line:88] ERROR Error handling request
Traceback (most recent call last):
  File "/home/gyz/python3.5.2/lib/python3.5/site-packages/aiohttp/web_server.py", line 62, in handle_request
    resp = yield from self._handler(request)
  File "/home/gyz/python3.5.2/lib/python3.5/site-packages/aiohttp/web.py", line 270, in _handle
    resp = yield from handler(request)
  File "app.py", line 35, in logger
    return (yield from handler(request))
  File "app.py", line 73, in response
    resp = web.Response(body=app['__templating__'].get_template(template).render(**r).encode('utf-8'))
  File "/home/gyz/python3.5.2/lib/python3.5/site-packages/jinja2/environment.py", line 1008, in render
    return self.environment.handle_exception(exc_info, True)
  File "/home/gyz/python3.5.2/lib/python3.5/site-packages/jinja2/environment.py", line 780, in handle_exception
    reraise(exc_type, exc_value, tb)
  File "/home/gyz/python3.5.2/lib/python3.5/site-packages/jinja2/_compat.py", line 37, in reraise
    raise value.with_traceback(tb)
  File "/home/pycode/python3-summer-blog/www/templates/blogs.html", line 1, in top-level template code
    {% extends '__base__.html' %}
  File "/home/pycode/python3-summer-blog/www/templates/__base__.html", line 67, in top-level template code
    {% block content %}
  File "/home/pycode/python3-summer-blog/www/templates/blogs.html", line 18, in block "content"
    <p class="uk-article-meta">{{ blog.created_at|datetime }}</p>
  File "app.py", line 93, in datetime_filter
    return u'%s minutes ago' (delta//60)
TypeError: 'str' object is not callable
2017-03-22 13:35:35,464 web_server.py[line:88] ERROR Error handling request
Traceback (most recent call last):
  File "/home/gyz/python3.5.2/lib/python3.5/site-packages/aiohttp/web_server.py", line 62, in handle_request
    resp = yield from self._handler(request)
  File "/home/gyz/python3.5.2/lib/python3.5/site-packages/aiohttp/web.py", line 270, in _handle
    resp = yield from handler(request)
  File "app.py", line 35, in logger
    return (yield from handler(request))
  File "app.py", line 73, in response
    resp = web.Response(body=app['__templating__'].get_template(template).render(**r).encode('utf-8'))
  File "/home/gyz/python3.5.2/lib/python3.5/site-packages/jinja2/environment.py", line 1008, in render
    return self.environment.handle_exception(exc_info, True)
  File "/home/gyz/python3.5.2/lib/python3.5/site-packages/jinja2/environment.py", line 780, in handle_exception
    reraise(exc_type, exc_value, tb)
  File "/home/gyz/python3.5.2/lib/python3.5/site-packages/jinja2/_compat.py", line 37, in reraise
    raise value.with_traceback(tb)
  File "/home/pycode/python3-summer-blog/www/templates/blogs.html", line 1, in top-level template code
    {% extends '__base__.html' %}
  File "/home/pycode/python3-summer-blog/www/templates/__base__.html", line 67, in top-level template code
    {% block content %}
  File "/home/pycode/python3-summer-blog/www/templates/blogs.html", line 18, in block "content"
    <p class="uk-article-meta">{{ blog.created_at|datetime }}</p>
  File "app.py", line 93, in datetime_filter
    return u'%s minutes ago' (delta//60)
TypeError: 'str' object is not callable
2017-03-22 13:43:39,990 web_server.py[line:88] ERROR Error handling request
Traceback (most recent call last):
  File "/home/gyz/python3.5.2/lib/python3.5/site-packages/aiohttp/web_server.py", line 62, in handle_request
    resp = yield from self._handler(request)
  File "/home/gyz/python3.5.2/lib/python3.5/site-packages/aiohttp/web.py", line 270, in _handle
    resp = yield from handler(request)
  File "app.py", line 35, in logger
    return (yield from handler(request))
  File "app.py", line 73, in response
    resp = web.Response(body=app['__templating__'].get_template(template).render(**r).encode('utf-8'))
  File "/home/gyz/python3.5.2/lib/python3.5/site-packages/jinja2/environment.py", line 1008, in render
    return self.environment.handle_exception(exc_info, True)
  File "/home/gyz/python3.5.2/lib/python3.5/site-packages/jinja2/environment.py", line 780, in handle_exception
    reraise(exc_type, exc_value, tb)
  File "/home/gyz/python3.5.2/lib/python3.5/site-packages/jinja2/_compat.py", line 37, in reraise
    raise value.with_traceback(tb)
  File "/home/pycode/python3-summer-blog/www/templates/blogs.html", line 1, in top-level template code
    {% extends '__base__.html' %}
  File "/home/pycode/python3-summer-blog/www/templates/__base__.html", line 67, in top-level template code
    {% block content %}
  File "/home/pycode/python3-summer-blog/www/templates/blogs.html", line 18, in block "content"
    <p class="uk-article-meta">发表于{{ blog.created_at|datetime }}</p>
  File "app.py", line 93, in datetime_filter
    return u'%d minutes ago' (delta//60)
TypeError: 'str' object is not callable
2017-03-22 13:43:40,145 web_server.py[line:88] ERROR Error handling request
Traceback (most recent call last):
  File "/home/gyz/python3.5.2/lib/python3.5/site-packages/aiohttp/web_server.py", line 62, in handle_request
    resp = yield from self._handler(request)
  File "/home/gyz/python3.5.2/lib/python3.5/site-packages/aiohttp/web.py", line 270, in _handle
    resp = yield from handler(request)
  File "app.py", line 35, in logger
    return (yield from handler(request))
  File "app.py", line 73, in response
    resp = web.Response(body=app['__templating__'].get_template(template).render(**r).encode('utf-8'))
  File "/home/gyz/python3.5.2/lib/python3.5/site-packages/jinja2/environment.py", line 1008, in render
    return self.environment.handle_exception(exc_info, True)
  File "/home/gyz/python3.5.2/lib/python3.5/site-packages/jinja2/environment.py", line 780, in handle_exception
    reraise(exc_type, exc_value, tb)
  File "/home/gyz/python3.5.2/lib/python3.5/site-packages/jinja2/_compat.py", line 37, in reraise
    raise value.with_traceback(tb)
  File "/home/pycode/python3-summer-blog/www/templates/blogs.html", line 1, in top-level template code
    {% extends '__base__.html' %}
  File "/home/pycode/python3-summer-blog/www/templates/__base__.html", line 67, in top-level template code
    {% block content %}
  File "/home/pycode/python3-summer-blog/www/templates/blogs.html", line 18, in block "content"
    <p class="uk-article-meta">发表于{{ blog.created_at|datetime }}</p>
  File "app.py", line 93, in datetime_filter
    return u'%d minutes ago' (delta//60)
TypeError: 'str' object is not callable
2017-03-22 13:43:40,525 web_server.py[line:88] ERROR Error handling request
Traceback (most recent call last):
  File "/home/gyz/python3.5.2/lib/python3.5/site-packages/aiohttp/web_server.py", line 62, in handle_request
    resp = yield from self._handler(request)
  File "/home/gyz/python3.5.2/lib/python3.5/site-packages/aiohttp/web.py", line 270, in _handle
    resp = yield from handler(request)
  File "app.py", line 35, in logger
    return (yield from handler(request))
  File "app.py", line 73, in response
    resp = web.Response(body=app['__templating__'].get_template(template).render(**r).encode('utf-8'))
  File "/home/gyz/python3.5.2/lib/python3.5/site-packages/jinja2/environment.py", line 1008, in render
    return self.environment.handle_exception(exc_info, True)
  File "/home/gyz/python3.5.2/lib/python3.5/site-packages/jinja2/environment.py", line 780, in handle_exception
    reraise(exc_type, exc_value, tb)
  File "/home/gyz/python3.5.2/lib/python3.5/site-packages/jinja2/_compat.py", line 37, in reraise
    raise value.with_traceback(tb)
  File "/home/pycode/python3-summer-blog/www/templates/blogs.html", line 1, in top-level template code
    {% extends '__base__.html' %}
  File "/home/pycode/python3-summer-blog/www/templates/__base__.html", line 67, in top-level template code
    {% block content %}
  File "/home/pycode/python3-summer-blog/www/templates/blogs.html", line 18, in block "content"
    <p class="uk-article-meta">发表于{{ blog.created_at|datetime }}</p>
  File "app.py", line 93, in datetime_filter
    return u'%d minutes ago' (delta//60)
TypeError: 'str' object is not callable
2017-03-24 15:02:36,151 web_server.py[line:88] ERROR Error handling request
Traceback (most recent call last):
  File "/home/gyz/python3.5.2/lib/python3.5/site-packages/aiohttp/web_server.py", line 62, in handle_request
    resp = yield from self._handler(request)
  File "/home/gyz/python3.5.2/lib/python3.5/site-packages/aiohttp/web.py", line 270, in _handle
    resp = yield from handler(request)
  File "app.py", line 35, in logger
    return (yield from handler(request))
  File "app.py", line 73, in response
    resp = web.Response(body=app['__templating__'].get_template(template).render(**r).encode('utf-8'))
  File "/home/gyz/python3.5.2/lib/python3.5/site-packages/jinja2/environment.py", line 830, in get_template
    return self._load_template(name, self.make_globals(globals))
  File "/home/gyz/python3.5.2/lib/python3.5/site-packages/jinja2/environment.py", line 804, in _load_template
    template = self.loader.load(self, name, globals)
  File "/home/gyz/python3.5.2/lib/python3.5/site-packages/jinja2/loaders.py", line 113, in load
    source, filename, uptodate = self.get_source(environment, name)
  File "/home/gyz/python3.5.2/lib/python3.5/site-packages/jinja2/loaders.py", line 175, in get_source
    contents = f.read().decode(self.encoding)
UnicodeDecodeError: 'utf-8' codec can't decode byte 0xb5 in position 96: invalid start byte
2017-03-24 15:02:36,385 web_server.py[line:88] ERROR Error handling request
Traceback (most recent call last):
  File "/home/gyz/python3.5.2/lib/python3.5/site-packages/aiohttp/web_server.py", line 62, in handle_request
    resp = yield from self._handler(request)
  File "/home/gyz/python3.5.2/lib/python3.5/site-packages/aiohttp/web.py", line 270, in _handle
    resp = yield from handler(request)
  File "app.py", line 35, in logger
    return (yield from handler(request))
  File "app.py", line 73, in response
    resp = web.Response(body=app['__templating__'].get_template(template).render(**r).encode('utf-8'))
  File "/home/gyz/python3.5.2/lib/python3.5/site-packages/jinja2/environment.py", line 830, in get_template
    return self._load_template(name, self.make_globals(globals))
  File "/home/gyz/python3.5.2/lib/python3.5/site-packages/jinja2/environment.py", line 804, in _load_template
    template = self.loader.load(self, name, globals)
  File "/home/gyz/python3.5.2/lib/python3.5/site-packages/jinja2/loaders.py", line 113, in load
    source, filename, uptodate = self.get_source(environment, name)
  File "/home/gyz/python3.5.2/lib/python3.5/site-packages/jinja2/loaders.py", line 175, in get_source
    contents = f.read().decode(self.encoding)
UnicodeDecodeError: 'utf-8' codec can't decode byte 0xb5 in position 96: invalid start byte
2017-03-24 15:02:40,184 web_server.py[line:88] ERROR Error handling request
Traceback (most recent call last):
  File "/home/gyz/python3.5.2/lib/python3.5/site-packages/aiohttp/web_server.py", line 62, in handle_request
    resp = yield from self._handler(request)
  File "/home/gyz/python3.5.2/lib/python3.5/site-packages/aiohttp/web.py", line 270, in _handle
    resp = yield from handler(request)
  File "app.py", line 35, in logger
    return (yield from handler(request))
  File "app.py", line 73, in response
    resp = web.Response(body=app['__templating__'].get_template(template).render(**r).encode('utf-8'))
  File "/home/gyz/python3.5.2/lib/python3.5/site-packages/jinja2/environment.py", line 830, in get_template
    return self._load_template(name, self.make_globals(globals))
  File "/home/gyz/python3.5.2/lib/python3.5/site-packages/jinja2/environment.py", line 804, in _load_template
    template = self.loader.load(self, name, globals)
  File "/home/gyz/python3.5.2/lib/python3.5/site-packages/jinja2/loaders.py", line 113, in load
    source, filename, uptodate = self.get_source(environment, name)
  File "/home/gyz/python3.5.2/lib/python3.5/site-packages/jinja2/loaders.py", line 175, in get_source
    contents = f.read().decode(self.encoding)
UnicodeDecodeError: 'utf-8' codec can't decode byte 0xb2 in position 52: invalid start byte
2017-03-24 15:02:40,335 web_server.py[line:88] ERROR Error handling request
Traceback (most recent call last):
  File "/home/gyz/python3.5.2/lib/python3.5/site-packages/aiohttp/web_server.py", line 62, in handle_request
    resp = yield from self._handler(request)
  File "/home/gyz/python3.5.2/lib/python3.5/site-packages/aiohttp/web.py", line 270, in _handle
    resp = yield from handler(request)
  File "app.py", line 35, in logger
    return (yield from handler(request))
  File "app.py", line 73, in response
    resp = web.Response(body=app['__templating__'].get_template(template).render(**r).encode('utf-8'))
  File "/home/gyz/python3.5.2/lib/python3.5/site-packages/jinja2/environment.py", line 830, in get_template
    return self._load_template(name, self.make_globals(globals))
  File "/home/gyz/python3.5.2/lib/python3.5/site-packages/jinja2/environment.py", line 804, in _load_template
    template = self.loader.load(self, name, globals)
  File "/home/gyz/python3.5.2/lib/python3.5/site-packages/jinja2/loaders.py", line 113, in load
    source, filename, uptodate = self.get_source(environment, name)
  File "/home/gyz/python3.5.2/lib/python3.5/site-packages/jinja2/loaders.py", line 175, in get_source
    contents = f.read().decode(self.encoding)
UnicodeDecodeError: 'utf-8' codec can't decode byte 0xb2 in position 52: invalid start byte
2017-03-24 15:02:44,119 web_server.py[line:88] ERROR Error handling request
Traceback (most recent call last):
  File "/home/gyz/python3.5.2/lib/python3.5/site-packages/aiohttp/web_server.py", line 62, in handle_request
    resp = yield from self._handler(request)
  File "/home/gyz/python3.5.2/lib/python3.5/site-packages/aiohttp/web.py", line 270, in _handle
    resp = yield from handler(request)
  File "app.py", line 35, in logger
    return (yield from handler(request))
  File "app.py", line 73, in response
    resp = web.Response(body=app['__templating__'].get_template(template).render(**r).encode('utf-8'))
  File "/home/gyz/python3.5.2/lib/python3.5/site-packages/jinja2/environment.py", line 830, in get_template
    return self._load_template(name, self.make_globals(globals))
  File "/home/gyz/python3.5.2/lib/python3.5/site-packages/jinja2/environment.py", line 804, in _load_template
    template = self.loader.load(self, name, globals)
  File "/home/gyz/python3.5.2/lib/python3.5/site-packages/jinja2/loaders.py", line 113, in load
    source, filename, uptodate = self.get_source(environment, name)
  File "/home/gyz/python3.5.2/lib/python3.5/site-packages/jinja2/loaders.py", line 175, in get_source
    contents = f.read().decode(self.encoding)
UnicodeDecodeError: 'utf-8' codec can't decode byte 0xb5 in position 96: invalid start byte
2017-03-24 15:02:44,312 web_server.py[line:88] ERROR Error handling request
Traceback (most recent call last):
  File "/home/gyz/python3.5.2/lib/python3.5/site-packages/aiohttp/web_server.py", line 62, in handle_request
    resp = yield from self._handler(request)
  File "/home/gyz/python3.5.2/lib/python3.5/site-packages/aiohttp/web.py", line 270, in _handle
    resp = yield from handler(request)
  File "app.py", line 35, in logger
    return (yield from handler(request))
  File "app.py", line 73, in response
    resp = web.Response(body=app['__templating__'].get_template(template).render(**r).encode('utf-8'))
  File "/home/gyz/python3.5.2/lib/python3.5/site-packages/jinja2/environment.py", line 830, in get_template
    return self._load_template(name, self.make_globals(globals))
  File "/home/gyz/python3.5.2/lib/python3.5/site-packages/jinja2/environment.py", line 804, in _load_template
    template = self.loader.load(self, name, globals)
  File "/home/gyz/python3.5.2/lib/python3.5/site-packages/jinja2/loaders.py", line 113, in load
    source, filename, uptodate = self.get_source(environment, name)
  File "/home/gyz/python3.5.2/lib/python3.5/site-packages/jinja2/loaders.py", line 175, in get_source
    contents = f.read().decode(self.encoding)
UnicodeDecodeError: 'utf-8' codec can't decode byte 0xb5 in position 96: invalid start byte
2017-03-24 15:03:07,300 web_server.py[line:88] ERROR Error handling request
Traceback (most recent call last):
  File "/home/gyz/python3.5.2/lib/python3.5/site-packages/aiohttp/web_server.py", line 62, in handle_request
    resp = yield from self._handler(request)
  File "/home/gyz/python3.5.2/lib/python3.5/site-packages/aiohttp/web.py", line 270, in _handle
    resp = yield from handler(request)
  File "app.py", line 35, in logger
    return (yield from handler(request))
  File "app.py", line 73, in response
    resp = web.Response(body=app['__templating__'].get_template(template).render(**r).encode('utf-8'))
  File "/home/gyz/python3.5.2/lib/python3.5/site-packages/jinja2/environment.py", line 830, in get_template
    return self._load_template(name, self.make_globals(globals))
  File "/home/gyz/python3.5.2/lib/python3.5/site-packages/jinja2/environment.py", line 804, in _load_template
    template = self.loader.load(self, name, globals)
  File "/home/gyz/python3.5.2/lib/python3.5/site-packages/jinja2/loaders.py", line 113, in load
    source, filename, uptodate = self.get_source(environment, name)
  File "/home/gyz/python3.5.2/lib/python3.5/site-packages/jinja2/loaders.py", line 175, in get_source
    contents = f.read().decode(self.encoding)
UnicodeDecodeError: 'utf-8' codec can't decode byte 0xb5 in position 96: invalid start byte
2017-03-24 15:03:39,318 web_server.py[line:88] ERROR Error handling request
Traceback (most recent call last):
  File "/home/gyz/python3.5.2/lib/python3.5/site-packages/aiohttp/web_server.py", line 62, in handle_request
    resp = yield from self._handler(request)
  File "/home/gyz/python3.5.2/lib/python3.5/site-packages/aiohttp/web.py", line 270, in _handle
    resp = yield from handler(request)
  File "app.py", line 35, in logger
    return (yield from handler(request))
  File "app.py", line 73, in response
    resp = web.Response(body=app['__templating__'].get_template(template).render(**r).encode('utf-8'))
  File "/home/gyz/python3.5.2/lib/python3.5/site-packages/jinja2/environment.py", line 830, in get_template
    return self._load_template(name, self.make_globals(globals))
  File "/home/gyz/python3.5.2/lib/python3.5/site-packages/jinja2/environment.py", line 804, in _load_template
    template = self.loader.load(self, name, globals)
  File "/home/gyz/python3.5.2/lib/python3.5/site-packages/jinja2/loaders.py", line 113, in load
    source, filename, uptodate = self.get_source(environment, name)
  File "/home/gyz/python3.5.2/lib/python3.5/site-packages/jinja2/loaders.py", line 175, in get_source
    contents = f.read().decode(self.encoding)
UnicodeDecodeError: 'utf-8' codec can't decode byte 0xb5 in position 96: invalid start byte
2017-03-24 15:03:39,517 web_server.py[line:88] ERROR Error handling request
Traceback (most recent call last):
  File "/home/gyz/python3.5.2/lib/python3.5/site-packages/aiohttp/web_server.py", line 62, in handle_request
    resp = yield from self._handler(request)
  File "/home/gyz/python3.5.2/lib/python3.5/site-packages/aiohttp/web.py", line 270, in _handle
    resp = yield from handler(request)
  File "app.py", line 35, in logger
    return (yield from handler(request))
  File "app.py", line 73, in response
    resp = web.Response(body=app['__templating__'].get_template(template).render(**r).encode('utf-8'))
  File "/home/gyz/python3.5.2/lib/python3.5/site-packages/jinja2/environment.py", line 830, in get_template
    return self._load_template(name, self.make_globals(globals))
  File "/home/gyz/python3.5.2/lib/python3.5/site-packages/jinja2/environment.py", line 804, in _load_template
    template = self.loader.load(self, name, globals)
  File "/home/gyz/python3.5.2/lib/python3.5/site-packages/jinja2/loaders.py", line 113, in load
    source, filename, uptodate = self.get_source(environment, name)
  File "/home/gyz/python3.5.2/lib/python3.5/site-packages/jinja2/loaders.py", line 175, in get_source
    contents = f.read().decode(self.encoding)
UnicodeDecodeError: 'utf-8' codec can't decode byte 0xb5 in position 96: invalid start byte
2017-03-24 15:04:31,348 web_server.py[line:88] ERROR Error handling request
Traceback (most recent call last):
  File "/home/gyz/python3.5.2/lib/python3.5/site-packages/aiohttp/web_server.py", line 62, in handle_request
    resp = yield from self._handler(request)
  File "/home/gyz/python3.5.2/lib/python3.5/site-packages/aiohttp/web.py", line 270, in _handle
    resp = yield from handler(request)
  File "app.py", line 35, in logger
    return (yield from handler(request))
  File "app.py", line 73, in response
    resp = web.Response(body=app['__templating__'].get_template(template).render(**r).encode('utf-8'))
  File "/home/gyz/python3.5.2/lib/python3.5/site-packages/jinja2/environment.py", line 830, in get_template
    return self._load_template(name, self.make_globals(globals))
  File "/home/gyz/python3.5.2/lib/python3.5/site-packages/jinja2/environment.py", line 804, in _load_template
    template = self.loader.load(self, name, globals)
  File "/home/gyz/python3.5.2/lib/python3.5/site-packages/jinja2/loaders.py", line 113, in load
    source, filename, uptodate = self.get_source(environment, name)
  File "/home/gyz/python3.5.2/lib/python3.5/site-packages/jinja2/loaders.py", line 175, in get_source
    contents = f.read().decode(self.encoding)
UnicodeDecodeError: 'utf-8' codec can't decode byte 0xb5 in position 96: invalid start byte
2017-03-24 16:03:27,267 web_server.py[line:88] ERROR Error handling request
Traceback (most recent call last):
  File "/home/gyz/python3.5.2/lib/python3.5/site-packages/aiohttp/web_server.py", line 62, in handle_request
    resp = yield from self._handler(request)
  File "/home/gyz/python3.5.2/lib/python3.5/site-packages/aiohttp/web.py", line 270, in _handle
    resp = yield from handler(request)
  File "app.py", line 35, in logger
    return (yield from handler(request))
  File "app.py", line 53, in response
    r = await handler(request)
  File "/home/gyz/python3.5.2/lib/python3.5/site-packages/aiohttp/web_urldispatcher.py", line 116, in handler_wrapper
    result = yield from result
  File "/home/pycode/python3-summer-blog/www/coroweb.py", line 127, in __call__
    r = await self._func(**kw)
  File "/home/gyz/python3.5.2/lib/python3.5/asyncio/coroutines.py", line 209, in coro
    res = yield from res
  File "/home/pycode/python3-summer-blog/www/handlers.py", line 124, in api_register_user
    r = web.Response()
NameError: name 'web' is not defined
2017-03-24 16:04:34,328 web_server.py[line:88] ERROR Error handling request
Traceback (most recent call last):
  File "/home/gyz/python3.5.2/lib/python3.5/site-packages/aiohttp/web_server.py", line 62, in handle_request
    resp = yield from self._handler(request)
  File "/home/gyz/python3.5.2/lib/python3.5/site-packages/aiohttp/web.py", line 270, in _handle
    resp = yield from handler(request)
  File "app.py", line 35, in logger
    return (yield from handler(request))
  File "app.py", line 53, in response
    r = await handler(request)
  File "/home/gyz/python3.5.2/lib/python3.5/site-packages/aiohttp/web_urldispatcher.py", line 116, in handler_wrapper
    result = yield from result
  File "/home/pycode/python3-summer-blog/www/coroweb.py", line 127, in __call__
    r = await self._func(**kw)
  File "/home/gyz/python3.5.2/lib/python3.5/asyncio/coroutines.py", line 209, in coro
    res = yield from res
  File "/home/pycode/python3-summer-blog/www/handlers.py", line 119, in api_register_user
    raise APIError('register:failed', 'email', 'Email is already in use.')
NameError: name 'APIError' is not defined
2017-03-24 16:17:08,927 web_server.py[line:88] ERROR Error handling request
Traceback (most recent call last):
  File "/home/gyz/python3.5.2/lib/python3.5/site-packages/aiohttp/web_server.py", line 62, in handle_request
    resp = yield from self._handler(request)
  File "/home/gyz/python3.5.2/lib/python3.5/site-packages/aiohttp/web.py", line 270, in _handle
    resp = yield from handler(request)
  File "app.py", line 35, in logger
    return (yield from handler(request))
  File "app.py", line 73, in response
    resp = web.Response(body=app['__templating__'].get_template(template).render(**r).encode('utf-8'))
  File "/home/gyz/python3.5.2/lib/python3.5/site-packages/jinja2/environment.py", line 830, in get_template
    return self._load_template(name, self.make_globals(globals))
  File "/home/gyz/python3.5.2/lib/python3.5/site-packages/jinja2/environment.py", line 804, in _load_template
    template = self.loader.load(self, name, globals)
  File "/home/gyz/python3.5.2/lib/python3.5/site-packages/jinja2/loaders.py", line 125, in load
    code = environment.compile(source, name, filename)
  File "/home/gyz/python3.5.2/lib/python3.5/site-packages/jinja2/environment.py", line 591, in compile
    self.handle_exception(exc_info, source_hint=source_hint)
  File "/home/gyz/python3.5.2/lib/python3.5/site-packages/jinja2/environment.py", line 780, in handle_exception
    reraise(exc_type, exc_value, tb)
  File "/home/gyz/python3.5.2/lib/python3.5/site-packages/jinja2/_compat.py", line 37, in reraise
    raise value.with_traceback(tb)
  File "/home/pycode/python3-summer-blog/www/templates/signin.html", line 5, in template
    {% block beforehead %}
  File "/home/gyz/python3.5.2/lib/python3.5/site-packages/jinja2/environment.py", line 497, in _parse
    return Parser(self, source, name, encode_filename(filename)).parse()
  File "/home/gyz/python3.5.2/lib/python3.5/site-packages/jinja2/parser.py", line 896, in parse
    result = nodes.Template(self.subparse(), lineno=1)
  File "/home/gyz/python3.5.2/lib/python3.5/site-packages/jinja2/parser.py", line 878, in subparse
    rv = self.parse_statement()
  File "/home/gyz/python3.5.2/lib/python3.5/site-packages/jinja2/parser.py", line 130, in parse_statement
    return getattr(self, 'parse_' + self.stream.current.value)()
  File "/home/gyz/python3.5.2/lib/python3.5/site-packages/jinja2/parser.py", line 268, in parse_block
    node.body = self.parse_statements(('name:endblock',), drop_needle=True)
  File "/home/gyz/python3.5.2/lib/python3.5/site-packages/jinja2/parser.py", line 170, in parse_statements
    self.fail_eof(end_tokens)
  File "/home/gyz/python3.5.2/lib/python3.5/site-packages/jinja2/parser.py", line 104, in fail_eof
    return self._fail_ut_eof(None, stack, lineno)
  File "/home/gyz/python3.5.2/lib/python3.5/site-packages/jinja2/parser.py", line 90, in _fail_ut_eof
    self.fail(' '.join(message), lineno)
  File "/home/gyz/python3.5.2/lib/python3.5/site-packages/jinja2/parser.py", line 59, in fail
    raise exc(msg, lineno, self.name, self.filename)
jinja2.exceptions.TemplateSyntaxError: Unexpected end of template. Jinja was looking for the following tags: 'endblock'. The innermost block that needs to be closed is 'block'.
2017-03-24 16:17:09,186 web_server.py[line:88] ERROR Error handling request
Traceback (most recent call last):
  File "/home/gyz/python3.5.2/lib/python3.5/site-packages/aiohttp/web_server.py", line 62, in handle_request
    resp = yield from self._handler(request)
  File "/home/gyz/python3.5.2/lib/python3.5/site-packages/aiohttp/web.py", line 270, in _handle
    resp = yield from handler(request)
  File "app.py", line 35, in logger
    return (yield from handler(request))
  File "app.py", line 73, in response
    resp = web.Response(body=app['__templating__'].get_template(template).render(**r).encode('utf-8'))
  File "/home/gyz/python3.5.2/lib/python3.5/site-packages/jinja2/environment.py", line 830, in get_template
    return self._load_template(name, self.make_globals(globals))
  File "/home/gyz/python3.5.2/lib/python3.5/site-packages/jinja2/environment.py", line 804, in _load_template
    template = self.loader.load(self, name, globals)
  File "/home/gyz/python3.5.2/lib/python3.5/site-packages/jinja2/loaders.py", line 125, in load
    code = environment.compile(source, name, filename)
  File "/home/gyz/python3.5.2/lib/python3.5/site-packages/jinja2/environment.py", line 591, in compile
    self.handle_exception(exc_info, source_hint=source_hint)
  File "/home/gyz/python3.5.2/lib/python3.5/site-packages/jinja2/environment.py", line 780, in handle_exception
    reraise(exc_type, exc_value, tb)
  File "/home/gyz/python3.5.2/lib/python3.5/site-packages/jinja2/_compat.py", line 37, in reraise
    raise value.with_traceback(tb)
  File "/home/pycode/python3-summer-blog/www/templates/signin.html", line 5, in template
    {% block beforehead %}
  File "/home/gyz/python3.5.2/lib/python3.5/site-packages/jinja2/environment.py", line 497, in _parse
    return Parser(self, source, name, encode_filename(filename)).parse()
  File "/home/gyz/python3.5.2/lib/python3.5/site-packages/jinja2/parser.py", line 896, in parse
    result = nodes.Template(self.subparse(), lineno=1)
  File "/home/gyz/python3.5.2/lib/python3.5/site-packages/jinja2/parser.py", line 878, in subparse
    rv = self.parse_statement()
  File "/home/gyz/python3.5.2/lib/python3.5/site-packages/jinja2/parser.py", line 130, in parse_statement
    return getattr(self, 'parse_' + self.stream.current.value)()
  File "/home/gyz/python3.5.2/lib/python3.5/site-packages/jinja2/parser.py", line 268, in parse_block
    node.body = self.parse_statements(('name:endblock',), drop_needle=True)
  File "/home/gyz/python3.5.2/lib/python3.5/site-packages/jinja2/parser.py", line 170, in parse_statements
    self.fail_eof(end_tokens)
  File "/home/gyz/python3.5.2/lib/python3.5/site-packages/jinja2/parser.py", line 104, in fail_eof
    return self._fail_ut_eof(None, stack, lineno)
  File "/home/gyz/python3.5.2/lib/python3.5/site-packages/jinja2/parser.py", line 90, in _fail_ut_eof
    self.fail(' '.join(message), lineno)
  File "/home/gyz/python3.5.2/lib/python3.5/site-packages/jinja2/parser.py", line 59, in fail
    raise exc(msg, lineno, self.name, self.filename)
jinja2.exceptions.TemplateSyntaxError: Unexpected end of template. Jinja was looking for the following tags: 'endblock'. The innermost block that needs to be closed is 'block'.
2017-03-24 16:17:10,274 web_server.py[line:88] ERROR Error handling request
Traceback (most recent call last):
  File "/home/gyz/python3.5.2/lib/python3.5/site-packages/aiohttp/web_server.py", line 62, in handle_request
    resp = yield from self._handler(request)
  File "/home/gyz/python3.5.2/lib/python3.5/site-packages/aiohttp/web.py", line 270, in _handle
    resp = yield from handler(request)
  File "app.py", line 35, in logger
    return (yield from handler(request))
  File "app.py", line 73, in response
    resp = web.Response(body=app['__templating__'].get_template(template).render(**r).encode('utf-8'))
  File "/home/gyz/python3.5.2/lib/python3.5/site-packages/jinja2/environment.py", line 830, in get_template
    return self._load_template(name, self.make_globals(globals))
  File "/home/gyz/python3.5.2/lib/python3.5/site-packages/jinja2/environment.py", line 804, in _load_template
    template = self.loader.load(self, name, globals)
  File "/home/gyz/python3.5.2/lib/python3.5/site-packages/jinja2/loaders.py", line 125, in load
    code = environment.compile(source, name, filename)
  File "/home/gyz/python3.5.2/lib/python3.5/site-packages/jinja2/environment.py", line 591, in compile
    self.handle_exception(exc_info, source_hint=source_hint)
  File "/home/gyz/python3.5.2/lib/python3.5/site-packages/jinja2/environment.py", line 780, in handle_exception
    reraise(exc_type, exc_value, tb)
  File "/home/gyz/python3.5.2/lib/python3.5/site-packages/jinja2/_compat.py", line 37, in reraise
    raise value.with_traceback(tb)
  File "/home/pycode/python3-summer-blog/www/templates/signin.html", line 5, in template
    {% block beforehead %}
  File "/home/gyz/python3.5.2/lib/python3.5/site-packages/jinja2/environment.py", line 497, in _parse
    return Parser(self, source, name, encode_filename(filename)).parse()
  File "/home/gyz/python3.5.2/lib/python3.5/site-packages/jinja2/parser.py", line 896, in parse
    result = nodes.Template(self.subparse(), lineno=1)
  File "/home/gyz/python3.5.2/lib/python3.5/site-packages/jinja2/parser.py", line 878, in subparse
    rv = self.parse_statement()
  File "/home/gyz/python3.5.2/lib/python3.5/site-packages/jinja2/parser.py", line 130, in parse_statement
    return getattr(self, 'parse_' + self.stream.current.value)()
  File "/home/gyz/python3.5.2/lib/python3.5/site-packages/jinja2/parser.py", line 268, in parse_block
    node.body = self.parse_statements(('name:endblock',), drop_needle=True)
  File "/home/gyz/python3.5.2/lib/python3.5/site-packages/jinja2/parser.py", line 170, in parse_statements
    self.fail_eof(end_tokens)
  File "/home/gyz/python3.5.2/lib/python3.5/site-packages/jinja2/parser.py", line 104, in fail_eof
    return self._fail_ut_eof(None, stack, lineno)
  File "/home/gyz/python3.5.2/lib/python3.5/site-packages/jinja2/parser.py", line 90, in _fail_ut_eof
    self.fail(' '.join(message), lineno)
  File "/home/gyz/python3.5.2/lib/python3.5/site-packages/jinja2/parser.py", line 59, in fail
    raise exc(msg, lineno, self.name, self.filename)
jinja2.exceptions.TemplateSyntaxError: Unexpected end of template. Jinja was looking for the following tags: 'endblock'. The innermost block that needs to be closed is 'block'.
2017-03-24 16:17:10,499 web_server.py[line:88] ERROR Error handling request
Traceback (most recent call last):
  File "/home/gyz/python3.5.2/lib/python3.5/site-packages/aiohttp/web_server.py", line 62, in handle_request
    resp = yield from self._handler(request)
  File "/home/gyz/python3.5.2/lib/python3.5/site-packages/aiohttp/web.py", line 270, in _handle
    resp = yield from handler(request)
  File "app.py", line 35, in logger
    return (yield from handler(request))
  File "app.py", line 73, in response
    resp = web.Response(body=app['__templating__'].get_template(template).render(**r).encode('utf-8'))
  File "/home/gyz/python3.5.2/lib/python3.5/site-packages/jinja2/environment.py", line 830, in get_template
    return self._load_template(name, self.make_globals(globals))
  File "/home/gyz/python3.5.2/lib/python3.5/site-packages/jinja2/environment.py", line 804, in _load_template
    template = self.loader.load(self, name, globals)
  File "/home/gyz/python3.5.2/lib/python3.5/site-packages/jinja2/loaders.py", line 125, in load
    code = environment.compile(source, name, filename)
  File "/home/gyz/python3.5.2/lib/python3.5/site-packages/jinja2/environment.py", line 591, in compile
    self.handle_exception(exc_info, source_hint=source_hint)
  File "/home/gyz/python3.5.2/lib/python3.5/site-packages/jinja2/environment.py", line 780, in handle_exception
    reraise(exc_type, exc_value, tb)
  File "/home/gyz/python3.5.2/lib/python3.5/site-packages/jinja2/_compat.py", line 37, in reraise
    raise value.with_traceback(tb)
  File "/home/pycode/python3-summer-blog/www/templates/signin.html", line 5, in template
    {% block beforehead %}
  File "/home/gyz/python3.5.2/lib/python3.5/site-packages/jinja2/environment.py", line 497, in _parse
    return Parser(self, source, name, encode_filename(filename)).parse()
  File "/home/gyz/python3.5.2/lib/python3.5/site-packages/jinja2/parser.py", line 896, in parse
    result = nodes.Template(self.subparse(), lineno=1)
  File "/home/gyz/python3.5.2/lib/python3.5/site-packages/jinja2/parser.py", line 878, in subparse
    rv = self.parse_statement()
  File "/home/gyz/python3.5.2/lib/python3.5/site-packages/jinja2/parser.py", line 130, in parse_statement
    return getattr(self, 'parse_' + self.stream.current.value)()
  File "/home/gyz/python3.5.2/lib/python3.5/site-packages/jinja2/parser.py", line 268, in parse_block
    node.body = self.parse_statements(('name:endblock',), drop_needle=True)
  File "/home/gyz/python3.5.2/lib/python3.5/site-packages/jinja2/parser.py", line 170, in parse_statements
    self.fail_eof(end_tokens)
  File "/home/gyz/python3.5.2/lib/python3.5/site-packages/jinja2/parser.py", line 104, in fail_eof
    return self._fail_ut_eof(None, stack, lineno)
  File "/home/gyz/python3.5.2/lib/python3.5/site-packages/jinja2/parser.py", line 90, in _fail_ut_eof
    self.fail(' '.join(message), lineno)
  File "/home/gyz/python3.5.2/lib/python3.5/site-packages/jinja2/parser.py", line 59, in fail
    raise exc(msg, lineno, self.name, self.filename)
jinja2.exceptions.TemplateSyntaxError: Unexpected end of template. Jinja was looking for the following tags: 'endblock'. The innermost block that needs to be closed is 'block'.
2017-03-24 16:17:11,019 web_server.py[line:88] ERROR Error handling request
Traceback (most recent call last):
  File "/home/gyz/python3.5.2/lib/python3.5/site-packages/aiohttp/web_server.py", line 62, in handle_request
    resp = yield from self._handler(request)
  File "/home/gyz/python3.5.2/lib/python3.5/site-packages/aiohttp/web.py", line 270, in _handle
    resp = yield from handler(request)
  File "app.py", line 35, in logger
    return (yield from handler(request))
  File "app.py", line 73, in response
    resp = web.Response(body=app['__templating__'].get_template(template).render(**r).encode('utf-8'))
  File "/home/gyz/python3.5.2/lib/python3.5/site-packages/jinja2/environment.py", line 830, in get_template
    return self._load_template(name, self.make_globals(globals))
  File "/home/gyz/python3.5.2/lib/python3.5/site-packages/jinja2/environment.py", line 804, in _load_template
    template = self.loader.load(self, name, globals)
  File "/home/gyz/python3.5.2/lib/python3.5/site-packages/jinja2/loaders.py", line 125, in load
    code = environment.compile(source, name, filename)
  File "/home/gyz/python3.5.2/lib/python3.5/site-packages/jinja2/environment.py", line 591, in compile
    self.handle_exception(exc_info, source_hint=source_hint)
  File "/home/gyz/python3.5.2/lib/python3.5/site-packages/jinja2/environment.py", line 780, in handle_exception
    reraise(exc_type, exc_value, tb)
  File "/home/gyz/python3.5.2/lib/python3.5/site-packages/jinja2/_compat.py", line 37, in reraise
    raise value.with_traceback(tb)
  File "/home/pycode/python3-summer-blog/www/templates/signin.html", line 5, in template
    {% block beforehead %}
  File "/home/gyz/python3.5.2/lib/python3.5/site-packages/jinja2/environment.py", line 497, in _parse
    return Parser(self, source, name, encode_filename(filename)).parse()
  File "/home/gyz/python3.5.2/lib/python3.5/site-packages/jinja2/parser.py", line 896, in parse
    result = nodes.Template(self.subparse(), lineno=1)
  File "/home/gyz/python3.5.2/lib/python3.5/site-packages/jinja2/parser.py", line 878, in subparse
    rv = self.parse_statement()
  File "/home/gyz/python3.5.2/lib/python3.5/site-packages/jinja2/parser.py", line 130, in parse_statement
    return getattr(self, 'parse_' + self.stream.current.value)()
  File "/home/gyz/python3.5.2/lib/python3.5/site-packages/jinja2/parser.py", line 268, in parse_block
    node.body = self.parse_statements(('name:endblock',), drop_needle=True)
  File "/home/gyz/python3.5.2/lib/python3.5/site-packages/jinja2/parser.py", line 170, in parse_statements
    self.fail_eof(end_tokens)
  File "/home/gyz/python3.5.2/lib/python3.5/site-packages/jinja2/parser.py", line 104, in fail_eof
    return self._fail_ut_eof(None, stack, lineno)
  File "/home/gyz/python3.5.2/lib/python3.5/site-packages/jinja2/parser.py", line 90, in _fail_ut_eof
    self.fail(' '.join(message), lineno)
  File "/home/gyz/python3.5.2/lib/python3.5/site-packages/jinja2/parser.py", line 59, in fail
    raise exc(msg, lineno, self.name, self.filename)
jinja2.exceptions.TemplateSyntaxError: Unexpected end of template. Jinja was looking for the following tags: 'endblock'. The innermost block that needs to be closed is 'block'.
2017-03-24 16:17:17,112 web_server.py[line:88] ERROR Error handling request
Traceback (most recent call last):
  File "/home/gyz/python3.5.2/lib/python3.5/site-packages/aiohttp/web_server.py", line 62, in handle_request
    resp = yield from self._handler(request)
  File "/home/gyz/python3.5.2/lib/python3.5/site-packages/aiohttp/web.py", line 270, in _handle
    resp = yield from handler(request)
  File "app.py", line 35, in logger
    return (yield from handler(request))
  File "app.py", line 73, in response
    resp = web.Response(body=app['__templating__'].get_template(template).render(**r).encode('utf-8'))
  File "/home/gyz/python3.5.2/lib/python3.5/site-packages/jinja2/environment.py", line 830, in get_template
    return self._load_template(name, self.make_globals(globals))
  File "/home/gyz/python3.5.2/lib/python3.5/site-packages/jinja2/environment.py", line 804, in _load_template
    template = self.loader.load(self, name, globals)
  File "/home/gyz/python3.5.2/lib/python3.5/site-packages/jinja2/loaders.py", line 125, in load
    code = environment.compile(source, name, filename)
  File "/home/gyz/python3.5.2/lib/python3.5/site-packages/jinja2/environment.py", line 591, in compile
    self.handle_exception(exc_info, source_hint=source_hint)
  File "/home/gyz/python3.5.2/lib/python3.5/site-packages/jinja2/environment.py", line 780, in handle_exception
    reraise(exc_type, exc_value, tb)
  File "/home/gyz/python3.5.2/lib/python3.5/site-packages/jinja2/_compat.py", line 37, in reraise
    raise value.with_traceback(tb)
  File "/home/pycode/python3-summer-blog/www/templates/signin.html", line 5, in template
    {% block beforehead %}
  File "/home/gyz/python3.5.2/lib/python3.5/site-packages/jinja2/environment.py", line 497, in _parse
    return Parser(self, source, name, encode_filename(filename)).parse()
  File "/home/gyz/python3.5.2/lib/python3.5/site-packages/jinja2/parser.py", line 896, in parse
    result = nodes.Template(self.subparse(), lineno=1)
  File "/home/gyz/python3.5.2/lib/python3.5/site-packages/jinja2/parser.py", line 878, in subparse
    rv = self.parse_statement()
  File "/home/gyz/python3.5.2/lib/python3.5/site-packages/jinja2/parser.py", line 130, in parse_statement
    return getattr(self, 'parse_' + self.stream.current.value)()
  File "/home/gyz/python3.5.2/lib/python3.5/site-packages/jinja2/parser.py", line 268, in parse_block
    node.body = self.parse_statements(('name:endblock',), drop_needle=True)
  File "/home/gyz/python3.5.2/lib/python3.5/site-packages/jinja2/parser.py", line 170, in parse_statements
    self.fail_eof(end_tokens)
  File "/home/gyz/python3.5.2/lib/python3.5/site-packages/jinja2/parser.py", line 104, in fail_eof
    return self._fail_ut_eof(None, stack, lineno)
  File "/home/gyz/python3.5.2/lib/python3.5/site-packages/jinja2/parser.py", line 90, in _fail_ut_eof
    self.fail(' '.join(message), lineno)
  File "/home/gyz/python3.5.2/lib/python3.5/site-packages/jinja2/parser.py", line 59, in fail
    raise exc(msg, lineno, self.name, self.filename)
jinja2.exceptions.TemplateSyntaxError: Unexpected end of template. Jinja was looking for the following tags: 'endblock'. The innermost block that needs to be closed is 'block'.
2017-03-24 16:17:17,298 web_server.py[line:88] ERROR Error handling request
Traceback (most recent call last):
  File "/home/gyz/python3.5.2/lib/python3.5/site-packages/aiohttp/web_server.py", line 62, in handle_request
    resp = yield from self._handler(request)
  File "/home/gyz/python3.5.2/lib/python3.5/site-packages/aiohttp/web.py", line 270, in _handle
    resp = yield from handler(request)
  File "app.py", line 35, in logger
    return (yield from handler(request))
  File "app.py", line 73, in response
    resp = web.Response(body=app['__templating__'].get_template(template).render(**r).encode('utf-8'))
  File "/home/gyz/python3.5.2/lib/python3.5/site-packages/jinja2/environment.py", line 830, in get_template
    return self._load_template(name, self.make_globals(globals))
  File "/home/gyz/python3.5.2/lib/python3.5/site-packages/jinja2/environment.py", line 804, in _load_template
    template = self.loader.load(self, name, globals)
  File "/home/gyz/python3.5.2/lib/python3.5/site-packages/jinja2/loaders.py", line 125, in load
    code = environment.compile(source, name, filename)
  File "/home/gyz/python3.5.2/lib/python3.5/site-packages/jinja2/environment.py", line 591, in compile
    self.handle_exception(exc_info, source_hint=source_hint)
  File "/home/gyz/python3.5.2/lib/python3.5/site-packages/jinja2/environment.py", line 780, in handle_exception
    reraise(exc_type, exc_value, tb)
  File "/home/gyz/python3.5.2/lib/python3.5/site-packages/jinja2/_compat.py", line 37, in reraise
    raise value.with_traceback(tb)
  File "/home/pycode/python3-summer-blog/www/templates/signin.html", line 5, in template
    {% block beforehead %}
  File "/home/gyz/python3.5.2/lib/python3.5/site-packages/jinja2/environment.py", line 497, in _parse
    return Parser(self, source, name, encode_filename(filename)).parse()
  File "/home/gyz/python3.5.2/lib/python3.5/site-packages/jinja2/parser.py", line 896, in parse
    result = nodes.Template(self.subparse(), lineno=1)
  File "/home/gyz/python3.5.2/lib/python3.5/site-packages/jinja2/parser.py", line 878, in subparse
    rv = self.parse_statement()
  File "/home/gyz/python3.5.2/lib/python3.5/site-packages/jinja2/parser.py", line 130, in parse_statement
    return getattr(self, 'parse_' + self.stream.current.value)()
  File "/home/gyz/python3.5.2/lib/python3.5/site-packages/jinja2/parser.py", line 268, in parse_block
    node.body = self.parse_statements(('name:endblock',), drop_needle=True)
  File "/home/gyz/python3.5.2/lib/python3.5/site-packages/jinja2/parser.py", line 170, in parse_statements
    self.fail_eof(end_tokens)
  File "/home/gyz/python3.5.2/lib/python3.5/site-packages/jinja2/parser.py", line 104, in fail_eof
    return self._fail_ut_eof(None, stack, lineno)
  File "/home/gyz/python3.5.2/lib/python3.5/site-packages/jinja2/parser.py", line 90, in _fail_ut_eof
    self.fail(' '.join(message), lineno)
  File "/home/gyz/python3.5.2/lib/python3.5/site-packages/jinja2/parser.py", line 59, in fail
    raise exc(msg, lineno, self.name, self.filename)
jinja2.exceptions.TemplateSyntaxError: Unexpected end of template. Jinja was looking for the following tags: 'endblock'. The innermost block that needs to be closed is 'block'.
2017-03-24 16:17:17,645 web_server.py[line:88] ERROR Error handling request
Traceback (most recent call last):
  File "/home/gyz/python3.5.2/lib/python3.5/site-packages/aiohttp/web_server.py", line 62, in handle_request
    resp = yield from self._handler(request)
  File "/home/gyz/python3.5.2/lib/python3.5/site-packages/aiohttp/web.py", line 270, in _handle
    resp = yield from handler(request)
  File "app.py", line 35, in logger
    return (yield from handler(request))
  File "app.py", line 73, in response
    resp = web.Response(body=app['__templating__'].get_template(template).render(**r).encode('utf-8'))
  File "/home/gyz/python3.5.2/lib/python3.5/site-packages/jinja2/environment.py", line 830, in get_template
    return self._load_template(name, self.make_globals(globals))
  File "/home/gyz/python3.5.2/lib/python3.5/site-packages/jinja2/environment.py", line 804, in _load_template
    template = self.loader.load(self, name, globals)
  File "/home/gyz/python3.5.2/lib/python3.5/site-packages/jinja2/loaders.py", line 125, in load
    code = environment.compile(source, name, filename)
  File "/home/gyz/python3.5.2/lib/python3.5/site-packages/jinja2/environment.py", line 591, in compile
    self.handle_exception(exc_info, source_hint=source_hint)
  File "/home/gyz/python3.5.2/lib/python3.5/site-packages/jinja2/environment.py", line 780, in handle_exception
    reraise(exc_type, exc_value, tb)
  File "/home/gyz/python3.5.2/lib/python3.5/site-packages/jinja2/_compat.py", line 37, in reraise
    raise value.with_traceback(tb)
  File "/home/pycode/python3-summer-blog/www/templates/signin.html", line 5, in template
    {% block beforehead %}
  File "/home/gyz/python3.5.2/lib/python3.5/site-packages/jinja2/environment.py", line 497, in _parse
    return Parser(self, source, name, encode_filename(filename)).parse()
  File "/home/gyz/python3.5.2/lib/python3.5/site-packages/jinja2/parser.py", line 896, in parse
    result = nodes.Template(self.subparse(), lineno=1)
  File "/home/gyz/python3.5.2/lib/python3.5/site-packages/jinja2/parser.py", line 878, in subparse
    rv = self.parse_statement()
  File "/home/gyz/python3.5.2/lib/python3.5/site-packages/jinja2/parser.py", line 130, in parse_statement
    return getattr(self, 'parse_' + self.stream.current.value)()
  File "/home/gyz/python3.5.2/lib/python3.5/site-packages/jinja2/parser.py", line 268, in parse_block
    node.body = self.parse_statements(('name:endblock',), drop_needle=True)
  File "/home/gyz/python3.5.2/lib/python3.5/site-packages/jinja2/parser.py", line 170, in parse_statements
    self.fail_eof(end_tokens)
  File "/home/gyz/python3.5.2/lib/python3.5/site-packages/jinja2/parser.py", line 104, in fail_eof
    return self._fail_ut_eof(None, stack, lineno)
  File "/home/gyz/python3.5.2/lib/python3.5/site-packages/jinja2/parser.py", line 90, in _fail_ut_eof
    self.fail(' '.join(message), lineno)
  File "/home/gyz/python3.5.2/lib/python3.5/site-packages/jinja2/parser.py", line 59, in fail
    raise exc(msg, lineno, self.name, self.filename)
jinja2.exceptions.TemplateSyntaxError: Unexpected end of template. Jinja was looking for the following tags: 'endblock'. The innermost block that needs to be closed is 'block'.
2017-03-24 16:20:29,586 web_server.py[line:88] ERROR Error handling request
Traceback (most recent call last):
  File "/home/gyz/python3.5.2/lib/python3.5/site-packages/aiohttp/web_server.py", line 62, in handle_request
    resp = yield from self._handler(request)
  File "/home/gyz/python3.5.2/lib/python3.5/site-packages/aiohttp/web.py", line 270, in _handle
    resp = yield from handler(request)
  File "app.py", line 35, in logger
    return (yield from handler(request))
  File "app.py", line 73, in response
    resp = web.Response(body=app['__templating__'].get_template(template).render(**r).encode('utf-8'))
  File "/home/gyz/python3.5.2/lib/python3.5/site-packages/jinja2/environment.py", line 830, in get_template
    return self._load_template(name, self.make_globals(globals))
  File "/home/gyz/python3.5.2/lib/python3.5/site-packages/jinja2/environment.py", line 804, in _load_template
    template = self.loader.load(self, name, globals)
  File "/home/gyz/python3.5.2/lib/python3.5/site-packages/jinja2/loaders.py", line 125, in load
    code = environment.compile(source, name, filename)
  File "/home/gyz/python3.5.2/lib/python3.5/site-packages/jinja2/environment.py", line 591, in compile
    self.handle_exception(exc_info, source_hint=source_hint)
  File "/home/gyz/python3.5.2/lib/python3.5/site-packages/jinja2/environment.py", line 780, in handle_exception
    reraise(exc_type, exc_value, tb)
  File "/home/gyz/python3.5.2/lib/python3.5/site-packages/jinja2/_compat.py", line 37, in reraise
    raise value.with_traceback(tb)
  File "/home/pycode/python3-summer-blog/www/templates/signin.html", line 6, in template
    {% block beforehead %}
  File "/home/gyz/python3.5.2/lib/python3.5/site-packages/jinja2/environment.py", line 497, in _parse
    return Parser(self, source, name, encode_filename(filename)).parse()
  File "/home/gyz/python3.5.2/lib/python3.5/site-packages/jinja2/parser.py", line 896, in parse
    result = nodes.Template(self.subparse(), lineno=1)
  File "/home/gyz/python3.5.2/lib/python3.5/site-packages/jinja2/parser.py", line 878, in subparse
    rv = self.parse_statement()
  File "/home/gyz/python3.5.2/lib/python3.5/site-packages/jinja2/parser.py", line 130, in parse_statement
    return getattr(self, 'parse_' + self.stream.current.value)()
  File "/home/gyz/python3.5.2/lib/python3.5/site-packages/jinja2/parser.py", line 268, in parse_block
    node.body = self.parse_statements(('name:endblock',), drop_needle=True)
  File "/home/gyz/python3.5.2/lib/python3.5/site-packages/jinja2/parser.py", line 170, in parse_statements
    self.fail_eof(end_tokens)
  File "/home/gyz/python3.5.2/lib/python3.5/site-packages/jinja2/parser.py", line 104, in fail_eof
    return self._fail_ut_eof(None, stack, lineno)
  File "/home/gyz/python3.5.2/lib/python3.5/site-packages/jinja2/parser.py", line 90, in _fail_ut_eof
    self.fail(' '.join(message), lineno)
  File "/home/gyz/python3.5.2/lib/python3.5/site-packages/jinja2/parser.py", line 59, in fail
    raise exc(msg, lineno, self.name, self.filename)
jinja2.exceptions.TemplateSyntaxError: Unexpected end of template. Jinja was looking for the following tags: 'endblock'. The innermost block that needs to be closed is 'block'.
2017-03-24 16:20:30,028 web_server.py[line:88] ERROR Error handling request
Traceback (most recent call last):
  File "/home/gyz/python3.5.2/lib/python3.5/site-packages/aiohttp/web_server.py", line 62, in handle_request
    resp = yield from self._handler(request)
  File "/home/gyz/python3.5.2/lib/python3.5/site-packages/aiohttp/web.py", line 270, in _handle
    resp = yield from handler(request)
  File "app.py", line 35, in logger
    return (yield from handler(request))
  File "app.py", line 73, in response
    resp = web.Response(body=app['__templating__'].get_template(template).render(**r).encode('utf-8'))
  File "/home/gyz/python3.5.2/lib/python3.5/site-packages/jinja2/environment.py", line 830, in get_template
    return self._load_template(name, self.make_globals(globals))
  File "/home/gyz/python3.5.2/lib/python3.5/site-packages/jinja2/environment.py", line 804, in _load_template
    template = self.loader.load(self, name, globals)
  File "/home/gyz/python3.5.2/lib/python3.5/site-packages/jinja2/loaders.py", line 125, in load
    code = environment.compile(source, name, filename)
  File "/home/gyz/python3.5.2/lib/python3.5/site-packages/jinja2/environment.py", line 591, in compile
    self.handle_exception(exc_info, source_hint=source_hint)
  File "/home/gyz/python3.5.2/lib/python3.5/site-packages/jinja2/environment.py", line 780, in handle_exception
    reraise(exc_type, exc_value, tb)
  File "/home/gyz/python3.5.2/lib/python3.5/site-packages/jinja2/_compat.py", line 37, in reraise
    raise value.with_traceback(tb)
  File "/home/pycode/python3-summer-blog/www/templates/signin.html", line 6, in template
    {% block beforehead %}
  File "/home/gyz/python3.5.2/lib/python3.5/site-packages/jinja2/environment.py", line 497, in _parse
    return Parser(self, source, name, encode_filename(filename)).parse()
  File "/home/gyz/python3.5.2/lib/python3.5/site-packages/jinja2/parser.py", line 896, in parse
    result = nodes.Template(self.subparse(), lineno=1)
  File "/home/gyz/python3.5.2/lib/python3.5/site-packages/jinja2/parser.py", line 878, in subparse
    rv = self.parse_statement()
  File "/home/gyz/python3.5.2/lib/python3.5/site-packages/jinja2/parser.py", line 130, in parse_statement
    return getattr(self, 'parse_' + self.stream.current.value)()
  File "/home/gyz/python3.5.2/lib/python3.5/site-packages/jinja2/parser.py", line 268, in parse_block
    node.body = self.parse_statements(('name:endblock',), drop_needle=True)
  File "/home/gyz/python3.5.2/lib/python3.5/site-packages/jinja2/parser.py", line 170, in parse_statements
    self.fail_eof(end_tokens)
  File "/home/gyz/python3.5.2/lib/python3.5/site-packages/jinja2/parser.py", line 104, in fail_eof
    return self._fail_ut_eof(None, stack, lineno)
  File "/home/gyz/python3.5.2/lib/python3.5/site-packages/jinja2/parser.py", line 90, in _fail_ut_eof
    self.fail(' '.join(message), lineno)
  File "/home/gyz/python3.5.2/lib/python3.5/site-packages/jinja2/parser.py", line 59, in fail
    raise exc(msg, lineno, self.name, self.filename)
jinja2.exceptions.TemplateSyntaxError: Unexpected end of template. Jinja was looking for the following tags: 'endblock'. The innermost block that needs to be closed is 'block'.
2017-03-24 16:20:30,519 web_server.py[line:88] ERROR Error handling request
Traceback (most recent call last):
  File "/home/gyz/python3.5.2/lib/python3.5/site-packages/aiohttp/web_server.py", line 62, in handle_request
    resp = yield from self._handler(request)
  File "/home/gyz/python3.5.2/lib/python3.5/site-packages/aiohttp/web.py", line 270, in _handle
    resp = yield from handler(request)
  File "app.py", line 35, in logger
    return (yield from handler(request))
  File "app.py", line 73, in response
    resp = web.Response(body=app['__templating__'].get_template(template).render(**r).encode('utf-8'))
  File "/home/gyz/python3.5.2/lib/python3.5/site-packages/jinja2/environment.py", line 830, in get_template
    return self._load_template(name, self.make_globals(globals))
  File "/home/gyz/python3.5.2/lib/python3.5/site-packages/jinja2/environment.py", line 804, in _load_template
    template = self.loader.load(self, name, globals)
  File "/home/gyz/python3.5.2/lib/python3.5/site-packages/jinja2/loaders.py", line 125, in load
    code = environment.compile(source, name, filename)
  File "/home/gyz/python3.5.2/lib/python3.5/site-packages/jinja2/environment.py", line 591, in compile
    self.handle_exception(exc_info, source_hint=source_hint)
  File "/home/gyz/python3.5.2/lib/python3.5/site-packages/jinja2/environment.py", line 780, in handle_exception
    reraise(exc_type, exc_value, tb)
  File "/home/gyz/python3.5.2/lib/python3.5/site-packages/jinja2/_compat.py", line 37, in reraise
    raise value.with_traceback(tb)
  File "/home/pycode/python3-summer-blog/www/templates/signin.html", line 6, in template
    {% block beforehead %}
  File "/home/gyz/python3.5.2/lib/python3.5/site-packages/jinja2/environment.py", line 497, in _parse
    return Parser(self, source, name, encode_filename(filename)).parse()
  File "/home/gyz/python3.5.2/lib/python3.5/site-packages/jinja2/parser.py", line 896, in parse
    result = nodes.Template(self.subparse(), lineno=1)
  File "/home/gyz/python3.5.2/lib/python3.5/site-packages/jinja2/parser.py", line 878, in subparse
    rv = self.parse_statement()
  File "/home/gyz/python3.5.2/lib/python3.5/site-packages/jinja2/parser.py", line 130, in parse_statement
    return getattr(self, 'parse_' + self.stream.current.value)()
  File "/home/gyz/python3.5.2/lib/python3.5/site-packages/jinja2/parser.py", line 268, in parse_block
    node.body = self.parse_statements(('name:endblock',), drop_needle=True)
  File "/home/gyz/python3.5.2/lib/python3.5/site-packages/jinja2/parser.py", line 170, in parse_statements
    self.fail_eof(end_tokens)
  File "/home/gyz/python3.5.2/lib/python3.5/site-packages/jinja2/parser.py", line 104, in fail_eof
    return self._fail_ut_eof(None, stack, lineno)
  File "/home/gyz/python3.5.2/lib/python3.5/site-packages/jinja2/parser.py", line 90, in _fail_ut_eof
    self.fail(' '.join(message), lineno)
  File "/home/gyz/python3.5.2/lib/python3.5/site-packages/jinja2/parser.py", line 59, in fail
    raise exc(msg, lineno, self.name, self.filename)
jinja2.exceptions.TemplateSyntaxError: Unexpected end of template. Jinja was looking for the following tags: 'endblock'. The innermost block that needs to be closed is 'block'.
2017-03-24 16:20:35,120 web_server.py[line:88] ERROR Error handling request
Traceback (most recent call last):
  File "/home/gyz/python3.5.2/lib/python3.5/site-packages/aiohttp/web_server.py", line 62, in handle_request
    resp = yield from self._handler(request)
  File "/home/gyz/python3.5.2/lib/python3.5/site-packages/aiohttp/web.py", line 270, in _handle
    resp = yield from handler(request)
  File "app.py", line 35, in logger
    return (yield from handler(request))
  File "app.py", line 73, in response
    resp = web.Response(body=app['__templating__'].get_template(template).render(**r).encode('utf-8'))
  File "/home/gyz/python3.5.2/lib/python3.5/site-packages/jinja2/environment.py", line 830, in get_template
    return self._load_template(name, self.make_globals(globals))
  File "/home/gyz/python3.5.2/lib/python3.5/site-packages/jinja2/environment.py", line 804, in _load_template
    template = self.loader.load(self, name, globals)
  File "/home/gyz/python3.5.2/lib/python3.5/site-packages/jinja2/loaders.py", line 125, in load
    code = environment.compile(source, name, filename)
  File "/home/gyz/python3.5.2/lib/python3.5/site-packages/jinja2/environment.py", line 591, in compile
    self.handle_exception(exc_info, source_hint=source_hint)
  File "/home/gyz/python3.5.2/lib/python3.5/site-packages/jinja2/environment.py", line 780, in handle_exception
    reraise(exc_type, exc_value, tb)
  File "/home/gyz/python3.5.2/lib/python3.5/site-packages/jinja2/_compat.py", line 37, in reraise
    raise value.with_traceback(tb)
  File "/home/pycode/python3-summer-blog/www/templates/signin.html", line 6, in template
    {% block beforehead %}
  File "/home/gyz/python3.5.2/lib/python3.5/site-packages/jinja2/environment.py", line 497, in _parse
    return Parser(self, source, name, encode_filename(filename)).parse()
  File "/home/gyz/python3.5.2/lib/python3.5/site-packages/jinja2/parser.py", line 896, in parse
    result = nodes.Template(self.subparse(), lineno=1)
  File "/home/gyz/python3.5.2/lib/python3.5/site-packages/jinja2/parser.py", line 878, in subparse
    rv = self.parse_statement()
  File "/home/gyz/python3.5.2/lib/python3.5/site-packages/jinja2/parser.py", line 130, in parse_statement
    return getattr(self, 'parse_' + self.stream.current.value)()
  File "/home/gyz/python3.5.2/lib/python3.5/site-packages/jinja2/parser.py", line 268, in parse_block
    node.body = self.parse_statements(('name:endblock',), drop_needle=True)
  File "/home/gyz/python3.5.2/lib/python3.5/site-packages/jinja2/parser.py", line 170, in parse_statements
    self.fail_eof(end_tokens)
  File "/home/gyz/python3.5.2/lib/python3.5/site-packages/jinja2/parser.py", line 104, in fail_eof
    return self._fail_ut_eof(None, stack, lineno)
  File "/home/gyz/python3.5.2/lib/python3.5/site-packages/jinja2/parser.py", line 90, in _fail_ut_eof
    self.fail(' '.join(message), lineno)
  File "/home/gyz/python3.5.2/lib/python3.5/site-packages/jinja2/parser.py", line 59, in fail
    raise exc(msg, lineno, self.name, self.filename)
jinja2.exceptions.TemplateSyntaxError: Unexpected end of template. Jinja was looking for the following tags: 'endblock'. The innermost block that needs to be closed is 'block'.
2017-03-24 16:20:35,341 web_server.py[line:88] ERROR Error handling request
Traceback (most recent call last):
  File "/home/gyz/python3.5.2/lib/python3.5/site-packages/aiohttp/web_server.py", line 62, in handle_request
    resp = yield from self._handler(request)
  File "/home/gyz/python3.5.2/lib/python3.5/site-packages/aiohttp/web.py", line 270, in _handle
    resp = yield from handler(request)
  File "app.py", line 35, in logger
    return (yield from handler(request))
  File "app.py", line 73, in response
    resp = web.Response(body=app['__templating__'].get_template(template).render(**r).encode('utf-8'))
  File "/home/gyz/python3.5.2/lib/python3.5/site-packages/jinja2/environment.py", line 830, in get_template
    return self._load_template(name, self.make_globals(globals))
  File "/home/gyz/python3.5.2/lib/python3.5/site-packages/jinja2/environment.py", line 804, in _load_template
    template = self.loader.load(self, name, globals)
  File "/home/gyz/python3.5.2/lib/python3.5/site-packages/jinja2/loaders.py", line 125, in load
    code = environment.compile(source, name, filename)
  File "/home/gyz/python3.5.2/lib/python3.5/site-packages/jinja2/environment.py", line 591, in compile
    self.handle_exception(exc_info, source_hint=source_hint)
  File "/home/gyz/python3.5.2/lib/python3.5/site-packages/jinja2/environment.py", line 780, in handle_exception
    reraise(exc_type, exc_value, tb)
  File "/home/gyz/python3.5.2/lib/python3.5/site-packages/jinja2/_compat.py", line 37, in reraise
    raise value.with_traceback(tb)
  File "/home/pycode/python3-summer-blog/www/templates/signin.html", line 6, in template
    {% block beforehead %}
  File "/home/gyz/python3.5.2/lib/python3.5/site-packages/jinja2/environment.py", line 497, in _parse
    return Parser(self, source, name, encode_filename(filename)).parse()
  File "/home/gyz/python3.5.2/lib/python3.5/site-packages/jinja2/parser.py", line 896, in parse
    result = nodes.Template(self.subparse(), lineno=1)
  File "/home/gyz/python3.5.2/lib/python3.5/site-packages/jinja2/parser.py", line 878, in subparse
    rv = self.parse_statement()
  File "/home/gyz/python3.5.2/lib/python3.5/site-packages/jinja2/parser.py", line 130, in parse_statement
    return getattr(self, 'parse_' + self.stream.current.value)()
  File "/home/gyz/python3.5.2/lib/python3.5/site-packages/jinja2/parser.py", line 268, in parse_block
    node.body = self.parse_statements(('name:endblock',), drop_needle=True)
  File "/home/gyz/python3.5.2/lib/python3.5/site-packages/jinja2/parser.py", line 170, in parse_statements
    self.fail_eof(end_tokens)
  File "/home/gyz/python3.5.2/lib/python3.5/site-packages/jinja2/parser.py", line 104, in fail_eof
    return self._fail_ut_eof(None, stack, lineno)
  File "/home/gyz/python3.5.2/lib/python3.5/site-packages/jinja2/parser.py", line 90, in _fail_ut_eof
    self.fail(' '.join(message), lineno)
  File "/home/gyz/python3.5.2/lib/python3.5/site-packages/jinja2/parser.py", line 59, in fail
    raise exc(msg, lineno, self.name, self.filename)
jinja2.exceptions.TemplateSyntaxError: Unexpected end of template. Jinja was looking for the following tags: 'endblock'. The innermost block that needs to be closed is 'block'.
2017-03-24 16:20:35,989 web_server.py[line:88] ERROR Error handling request
Traceback (most recent call last):
  File "/home/gyz/python3.5.2/lib/python3.5/site-packages/aiohttp/web_server.py", line 62, in handle_request
    resp = yield from self._handler(request)
  File "/home/gyz/python3.5.2/lib/python3.5/site-packages/aiohttp/web.py", line 270, in _handle
    resp = yield from handler(request)
  File "app.py", line 35, in logger
    return (yield from handler(request))
  File "app.py", line 73, in response
    resp = web.Response(body=app['__templating__'].get_template(template).render(**r).encode('utf-8'))
  File "/home/gyz/python3.5.2/lib/python3.5/site-packages/jinja2/environment.py", line 830, in get_template
    return self._load_template(name, self.make_globals(globals))
  File "/home/gyz/python3.5.2/lib/python3.5/site-packages/jinja2/environment.py", line 804, in _load_template
    template = self.loader.load(self, name, globals)
  File "/home/gyz/python3.5.2/lib/python3.5/site-packages/jinja2/loaders.py", line 125, in load
    code = environment.compile(source, name, filename)
  File "/home/gyz/python3.5.2/lib/python3.5/site-packages/jinja2/environment.py", line 591, in compile
    self.handle_exception(exc_info, source_hint=source_hint)
  File "/home/gyz/python3.5.2/lib/python3.5/site-packages/jinja2/environment.py", line 780, in handle_exception
    reraise(exc_type, exc_value, tb)
  File "/home/gyz/python3.5.2/lib/python3.5/site-packages/jinja2/_compat.py", line 37, in reraise
    raise value.with_traceback(tb)
  File "/home/pycode/python3-summer-blog/www/templates/signin.html", line 6, in template
    {% block beforehead %}
  File "/home/gyz/python3.5.2/lib/python3.5/site-packages/jinja2/environment.py", line 497, in _parse
    return Parser(self, source, name, encode_filename(filename)).parse()
  File "/home/gyz/python3.5.2/lib/python3.5/site-packages/jinja2/parser.py", line 896, in parse
    result = nodes.Template(self.subparse(), lineno=1)
  File "/home/gyz/python3.5.2/lib/python3.5/site-packages/jinja2/parser.py", line 878, in subparse
    rv = self.parse_statement()
  File "/home/gyz/python3.5.2/lib/python3.5/site-packages/jinja2/parser.py", line 130, in parse_statement
    return getattr(self, 'parse_' + self.stream.current.value)()
  File "/home/gyz/python3.5.2/lib/python3.5/site-packages/jinja2/parser.py", line 268, in parse_block
    node.body = self.parse_statements(('name:endblock',), drop_needle=True)
  File "/home/gyz/python3.5.2/lib/python3.5/site-packages/jinja2/parser.py", line 170, in parse_statements
    self.fail_eof(end_tokens)
  File "/home/gyz/python3.5.2/lib/python3.5/site-packages/jinja2/parser.py", line 104, in fail_eof
    return self._fail_ut_eof(None, stack, lineno)
  File "/home/gyz/python3.5.2/lib/python3.5/site-packages/jinja2/parser.py", line 90, in _fail_ut_eof
    self.fail(' '.join(message), lineno)
  File "/home/gyz/python3.5.2/lib/python3.5/site-packages/jinja2/parser.py", line 59, in fail
    raise exc(msg, lineno, self.name, self.filename)
jinja2.exceptions.TemplateSyntaxError: Unexpected end of template. Jinja was looking for the following tags: 'endblock'. The innermost block that needs to be closed is 'block'.
2017-03-24 16:20:39,412 web_server.py[line:88] ERROR Error handling request
Traceback (most recent call last):
  File "/home/gyz/python3.5.2/lib/python3.5/site-packages/aiohttp/web_server.py", line 62, in handle_request
    resp = yield from self._handler(request)
  File "/home/gyz/python3.5.2/lib/python3.5/site-packages/aiohttp/web.py", line 270, in _handle
    resp = yield from handler(request)
  File "app.py", line 35, in logger
    return (yield from handler(request))
  File "app.py", line 73, in response
    resp = web.Response(body=app['__templating__'].get_template(template).render(**r).encode('utf-8'))
  File "/home/gyz/python3.5.2/lib/python3.5/site-packages/jinja2/environment.py", line 830, in get_template
    return self._load_template(name, self.make_globals(globals))
  File "/home/gyz/python3.5.2/lib/python3.5/site-packages/jinja2/environment.py", line 804, in _load_template
    template = self.loader.load(self, name, globals)
  File "/home/gyz/python3.5.2/lib/python3.5/site-packages/jinja2/loaders.py", line 125, in load
    code = environment.compile(source, name, filename)
  File "/home/gyz/python3.5.2/lib/python3.5/site-packages/jinja2/environment.py", line 591, in compile
    self.handle_exception(exc_info, source_hint=source_hint)
  File "/home/gyz/python3.5.2/lib/python3.5/site-packages/jinja2/environment.py", line 780, in handle_exception
    reraise(exc_type, exc_value, tb)
  File "/home/gyz/python3.5.2/lib/python3.5/site-packages/jinja2/_compat.py", line 37, in reraise
    raise value.with_traceback(tb)
  File "/home/pycode/python3-summer-blog/www/templates/signin.html", line 6, in template
    {% block beforehead %}
  File "/home/gyz/python3.5.2/lib/python3.5/site-packages/jinja2/environment.py", line 497, in _parse
    return Parser(self, source, name, encode_filename(filename)).parse()
  File "/home/gyz/python3.5.2/lib/python3.5/site-packages/jinja2/parser.py", line 896, in parse
    result = nodes.Template(self.subparse(), lineno=1)
  File "/home/gyz/python3.5.2/lib/python3.5/site-packages/jinja2/parser.py", line 878, in subparse
    rv = self.parse_statement()
  File "/home/gyz/python3.5.2/lib/python3.5/site-packages/jinja2/parser.py", line 130, in parse_statement
    return getattr(self, 'parse_' + self.stream.current.value)()
  File "/home/gyz/python3.5.2/lib/python3.5/site-packages/jinja2/parser.py", line 268, in parse_block
    node.body = self.parse_statements(('name:endblock',), drop_needle=True)
  File "/home/gyz/python3.5.2/lib/python3.5/site-packages/jinja2/parser.py", line 170, in parse_statements
    self.fail_eof(end_tokens)
  File "/home/gyz/python3.5.2/lib/python3.5/site-packages/jinja2/parser.py", line 104, in fail_eof
    return self._fail_ut_eof(None, stack, lineno)
  File "/home/gyz/python3.5.2/lib/python3.5/site-packages/jinja2/parser.py", line 90, in _fail_ut_eof
    self.fail(' '.join(message), lineno)
  File "/home/gyz/python3.5.2/lib/python3.5/site-packages/jinja2/parser.py", line 59, in fail
    raise exc(msg, lineno, self.name, self.filename)
jinja2.exceptions.TemplateSyntaxError: Unexpected end of template. Jinja was looking for the following tags: 'endblock'. The innermost block that needs to be closed is 'block'.
2017-03-24 16:20:39,653 web_server.py[line:88] ERROR Error handling request
Traceback (most recent call last):
  File "/home/gyz/python3.5.2/lib/python3.5/site-packages/aiohttp/web_server.py", line 62, in handle_request
    resp = yield from self._handler(request)
  File "/home/gyz/python3.5.2/lib/python3.5/site-packages/aiohttp/web.py", line 270, in _handle
    resp = yield from handler(request)
  File "app.py", line 35, in logger
    return (yield from handler(request))
  File "app.py", line 73, in response
    resp = web.Response(body=app['__templating__'].get_template(template).render(**r).encode('utf-8'))
  File "/home/gyz/python3.5.2/lib/python3.5/site-packages/jinja2/environment.py", line 830, in get_template
    return self._load_template(name, self.make_globals(globals))
  File "/home/gyz/python3.5.2/lib/python3.5/site-packages/jinja2/environment.py", line 804, in _load_template
    template = self.loader.load(self, name, globals)
  File "/home/gyz/python3.5.2/lib/python3.5/site-packages/jinja2/loaders.py", line 125, in load
    code = environment.compile(source, name, filename)
  File "/home/gyz/python3.5.2/lib/python3.5/site-packages/jinja2/environment.py", line 591, in compile
    self.handle_exception(exc_info, source_hint=source_hint)
  File "/home/gyz/python3.5.2/lib/python3.5/site-packages/jinja2/environment.py", line 780, in handle_exception
    reraise(exc_type, exc_value, tb)
  File "/home/gyz/python3.5.2/lib/python3.5/site-packages/jinja2/_compat.py", line 37, in reraise
    raise value.with_traceback(tb)
  File "/home/pycode/python3-summer-blog/www/templates/signin.html", line 6, in template
    {% block beforehead %}
  File "/home/gyz/python3.5.2/lib/python3.5/site-packages/jinja2/environment.py", line 497, in _parse
    return Parser(self, source, name, encode_filename(filename)).parse()
  File "/home/gyz/python3.5.2/lib/python3.5/site-packages/jinja2/parser.py", line 896, in parse
    result = nodes.Template(self.subparse(), lineno=1)
  File "/home/gyz/python3.5.2/lib/python3.5/site-packages/jinja2/parser.py", line 878, in subparse
    rv = self.parse_statement()
  File "/home/gyz/python3.5.2/lib/python3.5/site-packages/jinja2/parser.py", line 130, in parse_statement
    return getattr(self, 'parse_' + self.stream.current.value)()
  File "/home/gyz/python3.5.2/lib/python3.5/site-packages/jinja2/parser.py", line 268, in parse_block
    node.body = self.parse_statements(('name:endblock',), drop_needle=True)
  File "/home/gyz/python3.5.2/lib/python3.5/site-packages/jinja2/parser.py", line 170, in parse_statements
    self.fail_eof(end_tokens)
  File "/home/gyz/python3.5.2/lib/python3.5/site-packages/jinja2/parser.py", line 104, in fail_eof
    return self._fail_ut_eof(None, stack, lineno)
  File "/home/gyz/python3.5.2/lib/python3.5/site-packages/jinja2/parser.py", line 90, in _fail_ut_eof
    self.fail(' '.join(message), lineno)
  File "/home/gyz/python3.5.2/lib/python3.5/site-packages/jinja2/parser.py", line 59, in fail
    raise exc(msg, lineno, self.name, self.filename)
jinja2.exceptions.TemplateSyntaxError: Unexpected end of template. Jinja was looking for the following tags: 'endblock'. The innermost block that needs to be closed is 'block'.
2017-03-24 16:20:41,634 web_server.py[line:88] ERROR Error handling request
Traceback (most recent call last):
  File "/home/gyz/python3.5.2/lib/python3.5/site-packages/aiohttp/web_server.py", line 62, in handle_request
    resp = yield from self._handler(request)
  File "/home/gyz/python3.5.2/lib/python3.5/site-packages/aiohttp/web.py", line 270, in _handle
    resp = yield from handler(request)
  File "app.py", line 35, in logger
    return (yield from handler(request))
  File "app.py", line 73, in response
    resp = web.Response(body=app['__templating__'].get_template(template).render(**r).encode('utf-8'))
  File "/home/gyz/python3.5.2/lib/python3.5/site-packages/jinja2/environment.py", line 830, in get_template
    return self._load_template(name, self.make_globals(globals))
  File "/home/gyz/python3.5.2/lib/python3.5/site-packages/jinja2/environment.py", line 804, in _load_template
    template = self.loader.load(self, name, globals)
  File "/home/gyz/python3.5.2/lib/python3.5/site-packages/jinja2/loaders.py", line 125, in load
    code = environment.compile(source, name, filename)
  File "/home/gyz/python3.5.2/lib/python3.5/site-packages/jinja2/environment.py", line 591, in compile
    self.handle_exception(exc_info, source_hint=source_hint)
  File "/home/gyz/python3.5.2/lib/python3.5/site-packages/jinja2/environment.py", line 780, in handle_exception
    reraise(exc_type, exc_value, tb)
  File "/home/gyz/python3.5.2/lib/python3.5/site-packages/jinja2/_compat.py", line 37, in reraise
    raise value.with_traceback(tb)
  File "/home/pycode/python3-summer-blog/www/templates/signin.html", line 6, in template
    {% block beforehead %}
  File "/home/gyz/python3.5.2/lib/python3.5/site-packages/jinja2/environment.py", line 497, in _parse
    return Parser(self, source, name, encode_filename(filename)).parse()
  File "/home/gyz/python3.5.2/lib/python3.5/site-packages/jinja2/parser.py", line 896, in parse
    result = nodes.Template(self.subparse(), lineno=1)
  File "/home/gyz/python3.5.2/lib/python3.5/site-packages/jinja2/parser.py", line 878, in subparse
    rv = self.parse_statement()
  File "/home/gyz/python3.5.2/lib/python3.5/site-packages/jinja2/parser.py", line 130, in parse_statement
    return getattr(self, 'parse_' + self.stream.current.value)()
  File "/home/gyz/python3.5.2/lib/python3.5/site-packages/jinja2/parser.py", line 268, in parse_block
    node.body = self.parse_statements(('name:endblock',), drop_needle=True)
  File "/home/gyz/python3.5.2/lib/python3.5/site-packages/jinja2/parser.py", line 170, in parse_statements
    self.fail_eof(end_tokens)
  File "/home/gyz/python3.5.2/lib/python3.5/site-packages/jinja2/parser.py", line 104, in fail_eof
    return self._fail_ut_eof(None, stack, lineno)
  File "/home/gyz/python3.5.2/lib/python3.5/site-packages/jinja2/parser.py", line 90, in _fail_ut_eof
    self.fail(' '.join(message), lineno)
  File "/home/gyz/python3.5.2/lib/python3.5/site-packages/jinja2/parser.py", line 59, in fail
    raise exc(msg, lineno, self.name, self.filename)
jinja2.exceptions.TemplateSyntaxError: Unexpected end of template. Jinja was looking for the following tags: 'endblock'. The innermost block that needs to be closed is 'block'.
2017-03-24 16:22:23,782 web_server.py[line:88] ERROR Error handling request
Traceback (most recent call last):
  File "/home/gyz/python3.5.2/lib/python3.5/site-packages/aiohttp/web_server.py", line 62, in handle_request
    resp = yield from self._handler(request)
  File "/home/gyz/python3.5.2/lib/python3.5/site-packages/aiohttp/web.py", line 270, in _handle
    resp = yield from handler(request)
  File "app.py", line 35, in logger
    return (yield from handler(request))
  File "app.py", line 73, in response
    resp = web.Response(body=app['__templating__'].get_template(template).render(**r).encode('utf-8'))
  File "/home/gyz/python3.5.2/lib/python3.5/site-packages/jinja2/environment.py", line 830, in get_template
    return self._load_template(name, self.make_globals(globals))
  File "/home/gyz/python3.5.2/lib/python3.5/site-packages/jinja2/environment.py", line 804, in _load_template
    template = self.loader.load(self, name, globals)
  File "/home/gyz/python3.5.2/lib/python3.5/site-packages/jinja2/loaders.py", line 125, in load
    code = environment.compile(source, name, filename)
  File "/home/gyz/python3.5.2/lib/python3.5/site-packages/jinja2/environment.py", line 591, in compile
    self.handle_exception(exc_info, source_hint=source_hint)
  File "/home/gyz/python3.5.2/lib/python3.5/site-packages/jinja2/environment.py", line 780, in handle_exception
    reraise(exc_type, exc_value, tb)
  File "/home/gyz/python3.5.2/lib/python3.5/site-packages/jinja2/_compat.py", line 37, in reraise
    raise value.with_traceback(tb)
  File "/home/pycode/python3-summer-blog/www/templates/signin.html", line 6, in template
    {% block beforehead %}
  File "/home/gyz/python3.5.2/lib/python3.5/site-packages/jinja2/environment.py", line 497, in _parse
    return Parser(self, source, name, encode_filename(filename)).parse()
  File "/home/gyz/python3.5.2/lib/python3.5/site-packages/jinja2/parser.py", line 896, in parse
    result = nodes.Template(self.subparse(), lineno=1)
  File "/home/gyz/python3.5.2/lib/python3.5/site-packages/jinja2/parser.py", line 878, in subparse
    rv = self.parse_statement()
  File "/home/gyz/python3.5.2/lib/python3.5/site-packages/jinja2/parser.py", line 130, in parse_statement
    return getattr(self, 'parse_' + self.stream.current.value)()
  File "/home/gyz/python3.5.2/lib/python3.5/site-packages/jinja2/parser.py", line 268, in parse_block
    node.body = self.parse_statements(('name:endblock',), drop_needle=True)
  File "/home/gyz/python3.5.2/lib/python3.5/site-packages/jinja2/parser.py", line 170, in parse_statements
    self.fail_eof(end_tokens)
  File "/home/gyz/python3.5.2/lib/python3.5/site-packages/jinja2/parser.py", line 104, in fail_eof
    return self._fail_ut_eof(None, stack, lineno)
  File "/home/gyz/python3.5.2/lib/python3.5/site-packages/jinja2/parser.py", line 90, in _fail_ut_eof
    self.fail(' '.join(message), lineno)
  File "/home/gyz/python3.5.2/lib/python3.5/site-packages/jinja2/parser.py", line 59, in fail
    raise exc(msg, lineno, self.name, self.filename)
jinja2.exceptions.TemplateSyntaxError: Unexpected end of template. Jinja was looking for the following tags: 'endblock'. The innermost block that needs to be closed is 'block'.
2017-03-24 16:22:24,119 web_server.py[line:88] ERROR Error handling request
Traceback (most recent call last):
  File "/home/gyz/python3.5.2/lib/python3.5/site-packages/aiohttp/web_server.py", line 62, in handle_request
    resp = yield from self._handler(request)
  File "/home/gyz/python3.5.2/lib/python3.5/site-packages/aiohttp/web.py", line 270, in _handle
    resp = yield from handler(request)
  File "app.py", line 35, in logger
    return (yield from handler(request))
  File "app.py", line 73, in response
    resp = web.Response(body=app['__templating__'].get_template(template).render(**r).encode('utf-8'))
  File "/home/gyz/python3.5.2/lib/python3.5/site-packages/jinja2/environment.py", line 830, in get_template
    return self._load_template(name, self.make_globals(globals))
  File "/home/gyz/python3.5.2/lib/python3.5/site-packages/jinja2/environment.py", line 804, in _load_template
    template = self.loader.load(self, name, globals)
  File "/home/gyz/python3.5.2/lib/python3.5/site-packages/jinja2/loaders.py", line 125, in load
    code = environment.compile(source, name, filename)
  File "/home/gyz/python3.5.2/lib/python3.5/site-packages/jinja2/environment.py", line 591, in compile
    self.handle_exception(exc_info, source_hint=source_hint)
  File "/home/gyz/python3.5.2/lib/python3.5/site-packages/jinja2/environment.py", line 780, in handle_exception
    reraise(exc_type, exc_value, tb)
  File "/home/gyz/python3.5.2/lib/python3.5/site-packages/jinja2/_compat.py", line 37, in reraise
    raise value.with_traceback(tb)
  File "/home/pycode/python3-summer-blog/www/templates/signin.html", line 6, in template
    {% block beforehead %}
  File "/home/gyz/python3.5.2/lib/python3.5/site-packages/jinja2/environment.py", line 497, in _parse
    return Parser(self, source, name, encode_filename(filename)).parse()
  File "/home/gyz/python3.5.2/lib/python3.5/site-packages/jinja2/parser.py", line 896, in parse
    result = nodes.Template(self.subparse(), lineno=1)
  File "/home/gyz/python3.5.2/lib/python3.5/site-packages/jinja2/parser.py", line 878, in subparse
    rv = self.parse_statement()
  File "/home/gyz/python3.5.2/lib/python3.5/site-packages/jinja2/parser.py", line 130, in parse_statement
    return getattr(self, 'parse_' + self.stream.current.value)()
  File "/home/gyz/python3.5.2/lib/python3.5/site-packages/jinja2/parser.py", line 268, in parse_block
    node.body = self.parse_statements(('name:endblock',), drop_needle=True)
  File "/home/gyz/python3.5.2/lib/python3.5/site-packages/jinja2/parser.py", line 170, in parse_statements
    self.fail_eof(end_tokens)
  File "/home/gyz/python3.5.2/lib/python3.5/site-packages/jinja2/parser.py", line 104, in fail_eof
    return self._fail_ut_eof(None, stack, lineno)
  File "/home/gyz/python3.5.2/lib/python3.5/site-packages/jinja2/parser.py", line 90, in _fail_ut_eof
    self.fail(' '.join(message), lineno)
  File "/home/gyz/python3.5.2/lib/python3.5/site-packages/jinja2/parser.py", line 59, in fail
    raise exc(msg, lineno, self.name, self.filename)
jinja2.exceptions.TemplateSyntaxError: Unexpected end of template. Jinja was looking for the following tags: 'endblock'. The innermost block that needs to be closed is 'block'.
2017-03-24 16:22:47,814 web_server.py[line:88] ERROR Error handling request
Traceback (most recent call last):
  File "/home/gyz/python3.5.2/lib/python3.5/site-packages/aiohttp/web_server.py", line 62, in handle_request
    resp = yield from self._handler(request)
  File "/home/gyz/python3.5.2/lib/python3.5/site-packages/aiohttp/web.py", line 270, in _handle
    resp = yield from handler(request)
  File "app.py", line 35, in logger
    return (yield from handler(request))
  File "app.py", line 73, in response
    resp = web.Response(body=app['__templating__'].get_template(template).render(**r).encode('utf-8'))
  File "/home/gyz/python3.5.2/lib/python3.5/site-packages/jinja2/environment.py", line 830, in get_template
    return self._load_template(name, self.make_globals(globals))
  File "/home/gyz/python3.5.2/lib/python3.5/site-packages/jinja2/environment.py", line 804, in _load_template
    template = self.loader.load(self, name, globals)
  File "/home/gyz/python3.5.2/lib/python3.5/site-packages/jinja2/loaders.py", line 125, in load
    code = environment.compile(source, name, filename)
  File "/home/gyz/python3.5.2/lib/python3.5/site-packages/jinja2/environment.py", line 591, in compile
    self.handle_exception(exc_info, source_hint=source_hint)
  File "/home/gyz/python3.5.2/lib/python3.5/site-packages/jinja2/environment.py", line 780, in handle_exception
    reraise(exc_type, exc_value, tb)
  File "/home/gyz/python3.5.2/lib/python3.5/site-packages/jinja2/_compat.py", line 37, in reraise
    raise value.with_traceback(tb)
  File "/home/pycode/python3-summer-blog/www/templates/signin.html", line 6, in template
    {% block beforehead %}
  File "/home/gyz/python3.5.2/lib/python3.5/site-packages/jinja2/environment.py", line 497, in _parse
    return Parser(self, source, name, encode_filename(filename)).parse()
  File "/home/gyz/python3.5.2/lib/python3.5/site-packages/jinja2/parser.py", line 896, in parse
    result = nodes.Template(self.subparse(), lineno=1)
  File "/home/gyz/python3.5.2/lib/python3.5/site-packages/jinja2/parser.py", line 878, in subparse
    rv = self.parse_statement()
  File "/home/gyz/python3.5.2/lib/python3.5/site-packages/jinja2/parser.py", line 130, in parse_statement
    return getattr(self, 'parse_' + self.stream.current.value)()
  File "/home/gyz/python3.5.2/lib/python3.5/site-packages/jinja2/parser.py", line 268, in parse_block
    node.body = self.parse_statements(('name:endblock',), drop_needle=True)
  File "/home/gyz/python3.5.2/lib/python3.5/site-packages/jinja2/parser.py", line 170, in parse_statements
    self.fail_eof(end_tokens)
  File "/home/gyz/python3.5.2/lib/python3.5/site-packages/jinja2/parser.py", line 104, in fail_eof
    return self._fail_ut_eof(None, stack, lineno)
  File "/home/gyz/python3.5.2/lib/python3.5/site-packages/jinja2/parser.py", line 90, in _fail_ut_eof
    self.fail(' '.join(message), lineno)
  File "/home/gyz/python3.5.2/lib/python3.5/site-packages/jinja2/parser.py", line 59, in fail
    raise exc(msg, lineno, self.name, self.filename)
jinja2.exceptions.TemplateSyntaxError: Unexpected end of template. Jinja was looking for the following tags: 'endblock'. The innermost block that needs to be closed is 'block'.
2017-03-24 16:26:22,912 web_server.py[line:88] ERROR Error handling request
Traceback (most recent call last):
  File "/home/gyz/python3.5.2/lib/python3.5/site-packages/aiohttp/web_server.py", line 62, in handle_request
    resp = yield from self._handler(request)
  File "/home/gyz/python3.5.2/lib/python3.5/site-packages/aiohttp/web.py", line 270, in _handle
    resp = yield from handler(request)
  File "app.py", line 35, in logger
    return (yield from handler(request))
  File "app.py", line 73, in response
    resp = web.Response(body=app['__templating__'].get_template(template).render(**r).encode('utf-8'))
  File "/home/gyz/python3.5.2/lib/python3.5/site-packages/jinja2/environment.py", line 830, in get_template
    return self._load_template(name, self.make_globals(globals))
  File "/home/gyz/python3.5.2/lib/python3.5/site-packages/jinja2/environment.py", line 804, in _load_template
    template = self.loader.load(self, name, globals)
  File "/home/gyz/python3.5.2/lib/python3.5/site-packages/jinja2/loaders.py", line 125, in load
    code = environment.compile(source, name, filename)
  File "/home/gyz/python3.5.2/lib/python3.5/site-packages/jinja2/environment.py", line 591, in compile
    self.handle_exception(exc_info, source_hint=source_hint)
  File "/home/gyz/python3.5.2/lib/python3.5/site-packages/jinja2/environment.py", line 780, in handle_exception
    reraise(exc_type, exc_value, tb)
  File "/home/gyz/python3.5.2/lib/python3.5/site-packages/jinja2/_compat.py", line 37, in reraise
    raise value.with_traceback(tb)
  File "/home/pycode/python3-summer-blog/www/templates/signin.html", line 5, in template
    {% block beforehead %}
  File "/home/gyz/python3.5.2/lib/python3.5/site-packages/jinja2/environment.py", line 497, in _parse
    return Parser(self, source, name, encode_filename(filename)).parse()
  File "/home/gyz/python3.5.2/lib/python3.5/site-packages/jinja2/parser.py", line 896, in parse
    result = nodes.Template(self.subparse(), lineno=1)
  File "/home/gyz/python3.5.2/lib/python3.5/site-packages/jinja2/parser.py", line 878, in subparse
    rv = self.parse_statement()
  File "/home/gyz/python3.5.2/lib/python3.5/site-packages/jinja2/parser.py", line 130, in parse_statement
    return getattr(self, 'parse_' + self.stream.current.value)()
  File "/home/gyz/python3.5.2/lib/python3.5/site-packages/jinja2/parser.py", line 268, in parse_block
    node.body = self.parse_statements(('name:endblock',), drop_needle=True)
  File "/home/gyz/python3.5.2/lib/python3.5/site-packages/jinja2/parser.py", line 170, in parse_statements
    self.fail_eof(end_tokens)
  File "/home/gyz/python3.5.2/lib/python3.5/site-packages/jinja2/parser.py", line 104, in fail_eof
    return self._fail_ut_eof(None, stack, lineno)
  File "/home/gyz/python3.5.2/lib/python3.5/site-packages/jinja2/parser.py", line 90, in _fail_ut_eof
    self.fail(' '.join(message), lineno)
  File "/home/gyz/python3.5.2/lib/python3.5/site-packages/jinja2/parser.py", line 59, in fail
    raise exc(msg, lineno, self.name, self.filename)
jinja2.exceptions.TemplateSyntaxError: Unexpected end of template. Jinja was looking for the following tags: 'endblock'. The innermost block that needs to be closed is 'block'.
2017-03-24 16:26:23,191 web_server.py[line:88] ERROR Error handling request
Traceback (most recent call last):
  File "/home/gyz/python3.5.2/lib/python3.5/site-packages/aiohttp/web_server.py", line 62, in handle_request
    resp = yield from self._handler(request)
  File "/home/gyz/python3.5.2/lib/python3.5/site-packages/aiohttp/web.py", line 270, in _handle
    resp = yield from handler(request)
  File "app.py", line 35, in logger
    return (yield from handler(request))
  File "app.py", line 73, in response
    resp = web.Response(body=app['__templating__'].get_template(template).render(**r).encode('utf-8'))
  File "/home/gyz/python3.5.2/lib/python3.5/site-packages/jinja2/environment.py", line 830, in get_template
    return self._load_template(name, self.make_globals(globals))
  File "/home/gyz/python3.5.2/lib/python3.5/site-packages/jinja2/environment.py", line 804, in _load_template
    template = self.loader.load(self, name, globals)
  File "/home/gyz/python3.5.2/lib/python3.5/site-packages/jinja2/loaders.py", line 125, in load
    code = environment.compile(source, name, filename)
  File "/home/gyz/python3.5.2/lib/python3.5/site-packages/jinja2/environment.py", line 591, in compile
    self.handle_exception(exc_info, source_hint=source_hint)
  File "/home/gyz/python3.5.2/lib/python3.5/site-packages/jinja2/environment.py", line 780, in handle_exception
    reraise(exc_type, exc_value, tb)
  File "/home/gyz/python3.5.2/lib/python3.5/site-packages/jinja2/_compat.py", line 37, in reraise
    raise value.with_traceback(tb)
  File "/home/pycode/python3-summer-blog/www/templates/signin.html", line 5, in template
    {% block beforehead %}
  File "/home/gyz/python3.5.2/lib/python3.5/site-packages/jinja2/environment.py", line 497, in _parse
    return Parser(self, source, name, encode_filename(filename)).parse()
  File "/home/gyz/python3.5.2/lib/python3.5/site-packages/jinja2/parser.py", line 896, in parse
    result = nodes.Template(self.subparse(), lineno=1)
  File "/home/gyz/python3.5.2/lib/python3.5/site-packages/jinja2/parser.py", line 878, in subparse
    rv = self.parse_statement()
  File "/home/gyz/python3.5.2/lib/python3.5/site-packages/jinja2/parser.py", line 130, in parse_statement
    return getattr(self, 'parse_' + self.stream.current.value)()
  File "/home/gyz/python3.5.2/lib/python3.5/site-packages/jinja2/parser.py", line 268, in parse_block
    node.body = self.parse_statements(('name:endblock',), drop_needle=True)
  File "/home/gyz/python3.5.2/lib/python3.5/site-packages/jinja2/parser.py", line 170, in parse_statements
    self.fail_eof(end_tokens)
  File "/home/gyz/python3.5.2/lib/python3.5/site-packages/jinja2/parser.py", line 104, in fail_eof
    return self._fail_ut_eof(None, stack, lineno)
  File "/home/gyz/python3.5.2/lib/python3.5/site-packages/jinja2/parser.py", line 90, in _fail_ut_eof
    self.fail(' '.join(message), lineno)
  File "/home/gyz/python3.5.2/lib/python3.5/site-packages/jinja2/parser.py", line 59, in fail
    raise exc(msg, lineno, self.name, self.filename)
jinja2.exceptions.TemplateSyntaxError: Unexpected end of template. Jinja was looking for the following tags: 'endblock'. The innermost block that needs to be closed is 'block'.
2017-03-24 16:26:28,379 web_server.py[line:88] ERROR Error handling request
Traceback (most recent call last):
  File "/home/gyz/python3.5.2/lib/python3.5/site-packages/aiohttp/web_server.py", line 62, in handle_request
    resp = yield from self._handler(request)
  File "/home/gyz/python3.5.2/lib/python3.5/site-packages/aiohttp/web.py", line 270, in _handle
    resp = yield from handler(request)
  File "app.py", line 35, in logger
    return (yield from handler(request))
  File "app.py", line 73, in response
    resp = web.Response(body=app['__templating__'].get_template(template).render(**r).encode('utf-8'))
  File "/home/gyz/python3.5.2/lib/python3.5/site-packages/jinja2/environment.py", line 830, in get_template
    return self._load_template(name, self.make_globals(globals))
  File "/home/gyz/python3.5.2/lib/python3.5/site-packages/jinja2/environment.py", line 804, in _load_template
    template = self.loader.load(self, name, globals)
  File "/home/gyz/python3.5.2/lib/python3.5/site-packages/jinja2/loaders.py", line 125, in load
    code = environment.compile(source, name, filename)
  File "/home/gyz/python3.5.2/lib/python3.5/site-packages/jinja2/environment.py", line 591, in compile
    self.handle_exception(exc_info, source_hint=source_hint)
  File "/home/gyz/python3.5.2/lib/python3.5/site-packages/jinja2/environment.py", line 780, in handle_exception
    reraise(exc_type, exc_value, tb)
  File "/home/gyz/python3.5.2/lib/python3.5/site-packages/jinja2/_compat.py", line 37, in reraise
    raise value.with_traceback(tb)
  File "/home/pycode/python3-summer-blog/www/templates/signin.html", line 5, in template
    {% block beforehead %}
  File "/home/gyz/python3.5.2/lib/python3.5/site-packages/jinja2/environment.py", line 497, in _parse
    return Parser(self, source, name, encode_filename(filename)).parse()
  File "/home/gyz/python3.5.2/lib/python3.5/site-packages/jinja2/parser.py", line 896, in parse
    result = nodes.Template(self.subparse(), lineno=1)
  File "/home/gyz/python3.5.2/lib/python3.5/site-packages/jinja2/parser.py", line 878, in subparse
    rv = self.parse_statement()
  File "/home/gyz/python3.5.2/lib/python3.5/site-packages/jinja2/parser.py", line 130, in parse_statement
    return getattr(self, 'parse_' + self.stream.current.value)()
  File "/home/gyz/python3.5.2/lib/python3.5/site-packages/jinja2/parser.py", line 268, in parse_block
    node.body = self.parse_statements(('name:endblock',), drop_needle=True)
  File "/home/gyz/python3.5.2/lib/python3.5/site-packages/jinja2/parser.py", line 170, in parse_statements
    self.fail_eof(end_tokens)
  File "/home/gyz/python3.5.2/lib/python3.5/site-packages/jinja2/parser.py", line 104, in fail_eof
    return self._fail_ut_eof(None, stack, lineno)
  File "/home/gyz/python3.5.2/lib/python3.5/site-packages/jinja2/parser.py", line 90, in _fail_ut_eof
    self.fail(' '.join(message), lineno)
  File "/home/gyz/python3.5.2/lib/python3.5/site-packages/jinja2/parser.py", line 59, in fail
    raise exc(msg, lineno, self.name, self.filename)
jinja2.exceptions.TemplateSyntaxError: Unexpected end of template. Jinja was looking for the following tags: 'endblock'. The innermost block that needs to be closed is 'block'.
2017-03-24 17:36:31,802 web_server.py[line:88] ERROR Error handling request
Traceback (most recent call last):
  File "/home/gyz/python3.5.2/lib/python3.5/site-packages/aiohttp/web_server.py", line 62, in handle_request
    resp = yield from self._handler(request)
  File "/home/gyz/python3.5.2/lib/python3.5/site-packages/aiohttp/web.py", line 270, in _handle
    resp = yield from handler(request)
  File "app.py", line 35, in logger
    return (yield from handler(request))
  File "app.py", line 73, in response
    resp = web.Response(body=app['__templating__'].get_template(template).render(**r).encode('utf-8'))
  File "/home/gyz/python3.5.2/lib/python3.5/site-packages/jinja2/environment.py", line 1008, in render
    return self.environment.handle_exception(exc_info, True)
  File "/home/gyz/python3.5.2/lib/python3.5/site-packages/jinja2/environment.py", line 780, in handle_exception
    reraise(exc_type, exc_value, tb)
  File "/home/gyz/python3.5.2/lib/python3.5/site-packages/jinja2/_compat.py", line 37, in reraise
    raise value.with_traceback(tb)
  File "/home/pycode/python3-summer-blog/www/templates/login.html", line 1, in top-level template code
    {% extends '__base__.html' %}
  File "/home/pycode/python3-summer-blog/www/templates/__base__.html", line 67, in top-level template code
    {% block content %}
  File "/home/pycode/python3-summer-blog/www/templates/login.html", line 15, in block "content"
    {% for blog in blogs %}
TypeError: 'function' object is not iterable
2017-03-24 17:36:32,014 web_server.py[line:88] ERROR Error handling request
Traceback (most recent call last):
  File "/home/gyz/python3.5.2/lib/python3.5/site-packages/aiohttp/web_server.py", line 62, in handle_request
    resp = yield from self._handler(request)
  File "/home/gyz/python3.5.2/lib/python3.5/site-packages/aiohttp/web.py", line 270, in _handle
    resp = yield from handler(request)
  File "app.py", line 35, in logger
    return (yield from handler(request))
  File "app.py", line 73, in response
    resp = web.Response(body=app['__templating__'].get_template(template).render(**r).encode('utf-8'))
  File "/home/gyz/python3.5.2/lib/python3.5/site-packages/jinja2/environment.py", line 1008, in render
    return self.environment.handle_exception(exc_info, True)
  File "/home/gyz/python3.5.2/lib/python3.5/site-packages/jinja2/environment.py", line 780, in handle_exception
    reraise(exc_type, exc_value, tb)
  File "/home/gyz/python3.5.2/lib/python3.5/site-packages/jinja2/_compat.py", line 37, in reraise
    raise value.with_traceback(tb)
  File "/home/pycode/python3-summer-blog/www/templates/login.html", line 1, in top-level template code
    {% extends '__base__.html' %}
  File "/home/pycode/python3-summer-blog/www/templates/__base__.html", line 67, in top-level template code
    {% block content %}
  File "/home/pycode/python3-summer-blog/www/templates/login.html", line 15, in block "content"
    {% for blog in blogs %}
TypeError: 'function' object is not iterable
2017-03-24 17:36:37,948 web_server.py[line:88] ERROR Error handling request
Traceback (most recent call last):
  File "/home/gyz/python3.5.2/lib/python3.5/site-packages/aiohttp/web_server.py", line 62, in handle_request
    resp = yield from self._handler(request)
  File "/home/gyz/python3.5.2/lib/python3.5/site-packages/aiohttp/web.py", line 270, in _handle
    resp = yield from handler(request)
  File "app.py", line 35, in logger
    return (yield from handler(request))
  File "app.py", line 73, in response
    resp = web.Response(body=app['__templating__'].get_template(template).render(**r).encode('utf-8'))
  File "/home/gyz/python3.5.2/lib/python3.5/site-packages/jinja2/environment.py", line 1008, in render
    return self.environment.handle_exception(exc_info, True)
  File "/home/gyz/python3.5.2/lib/python3.5/site-packages/jinja2/environment.py", line 780, in handle_exception
    reraise(exc_type, exc_value, tb)
  File "/home/gyz/python3.5.2/lib/python3.5/site-packages/jinja2/_compat.py", line 37, in reraise
    raise value.with_traceback(tb)
  File "/home/pycode/python3-summer-blog/www/templates/login.html", line 1, in top-level template code
    {% extends '__base__.html' %}
  File "/home/pycode/python3-summer-blog/www/templates/__base__.html", line 67, in top-level template code
    {% block content %}
  File "/home/pycode/python3-summer-blog/www/templates/login.html", line 15, in block "content"
    {% for blog in blogs %}
TypeError: 'function' object is not iterable
2017-03-24 17:51:41,142 web_server.py[line:88] ERROR Error handling request
Traceback (most recent call last):
  File "/home/gyz/python3.5.2/lib/python3.5/site-packages/aiohttp/web_server.py", line 62, in handle_request
    resp = yield from self._handler(request)
  File "/home/gyz/python3.5.2/lib/python3.5/site-packages/aiohttp/web.py", line 270, in _handle
    resp = yield from handler(request)
  File "app.py", line 35, in logger
    return (yield from handler(request))
  File "app.py", line 53, in response
    r = await handler(request)
  File "/home/gyz/python3.5.2/lib/python3.5/site-packages/aiohttp/web_urldispatcher.py", line 116, in handler_wrapper
    result = yield from result
  File "/home/pycode/python3-summer-blog/www/coroweb.py", line 127, in __call__
    r = await self._func(**kw)
  File "/home/gyz/python3.5.2/lib/python3.5/asyncio/coroutines.py", line 206, in coro
    res = func(*args, **kw)
  File "/home/pycode/python3-summer-blog/www/coroweb.py", line 14, in wrapper
    return func(*args, **kw)
  File "/home/pycode/python3-summer-blog/www/handlers.py", line 86, in login
    '__user__':request.__user__
AttributeError: 'Request' object has no attribute '__user__'
2017-03-24 17:51:41,346 web_server.py[line:88] ERROR Error handling request
Traceback (most recent call last):
  File "/home/gyz/python3.5.2/lib/python3.5/site-packages/aiohttp/web_server.py", line 62, in handle_request
    resp = yield from self._handler(request)
  File "/home/gyz/python3.5.2/lib/python3.5/site-packages/aiohttp/web.py", line 270, in _handle
    resp = yield from handler(request)
  File "app.py", line 35, in logger
    return (yield from handler(request))
  File "app.py", line 53, in response
    r = await handler(request)
  File "/home/gyz/python3.5.2/lib/python3.5/site-packages/aiohttp/web_urldispatcher.py", line 116, in handler_wrapper
    result = yield from result
  File "/home/pycode/python3-summer-blog/www/coroweb.py", line 127, in __call__
    r = await self._func(**kw)
  File "/home/gyz/python3.5.2/lib/python3.5/asyncio/coroutines.py", line 206, in coro
    res = func(*args, **kw)
  File "/home/pycode/python3-summer-blog/www/coroweb.py", line 14, in wrapper
    return func(*args, **kw)
  File "/home/pycode/python3-summer-blog/www/handlers.py", line 86, in login
    '__user__':request.__user__
AttributeError: 'Request' object has no attribute '__user__'
2017-03-24 17:51:45,263 web_server.py[line:88] ERROR Error handling request
Traceback (most recent call last):
  File "/home/gyz/python3.5.2/lib/python3.5/site-packages/aiohttp/web_server.py", line 62, in handle_request
    resp = yield from self._handler(request)
  File "/home/gyz/python3.5.2/lib/python3.5/site-packages/aiohttp/web.py", line 270, in _handle
    resp = yield from handler(request)
  File "app.py", line 35, in logger
    return (yield from handler(request))
  File "app.py", line 53, in response
    r = await handler(request)
  File "/home/gyz/python3.5.2/lib/python3.5/site-packages/aiohttp/web_urldispatcher.py", line 116, in handler_wrapper
    result = yield from result
  File "/home/pycode/python3-summer-blog/www/coroweb.py", line 127, in __call__
    r = await self._func(**kw)
  File "/home/gyz/python3.5.2/lib/python3.5/asyncio/coroutines.py", line 206, in coro
    res = func(*args, **kw)
  File "/home/pycode/python3-summer-blog/www/coroweb.py", line 14, in wrapper
    return func(*args, **kw)
  File "/home/pycode/python3-summer-blog/www/handlers.py", line 86, in login
    '__user__':request.__user__
AttributeError: 'Request' object has no attribute '__user__'
